Workbook

Sheet TW NOV-25
C2: 0.05 | E2: Please refer the terms below | AB2: 0.025
A3: TW Make Grid for the month of Nov 25 | AO3: TW Electric
B4: State (RTO) | C4: Type | D4: Hero OEM | I4: TVS OEM | N4: Suzuki OEM | S4: Yamaha OEM | X4: RE OEM | AA4: Honda | AF4: Bajaj | AK4: Others | AP4: State | AQ4: Type | AR4: All Electric Make | AX4: Hero vs Bajaj | BB4: Bajaj
C5: Type | D5: 150cc | E5: SCOOTER | F5: 150_350cc | G5: 350cc | I5: 150cc | J5: SCOOTER | K5: 150_350cc | L5: 350cc | N5: 150cc | O5: SCOOTER | P5: 150_350cc | Q5: 350cc | S5: 150cc | T5: SCOOTER | U5: 150_350cc | V5: 350cc | X5: 150_350cc | Y5: 350cc | AA5: 150cc | AB5: SCOOTER | AC5: 150_350cc | AD5: 350cc | AF5: 150cc | AG5: SCOOTER | AH5: 150_350cc | AI5: 350cc | AK5: 150cc | AL5: SCOOTER | AM5: 150_350cc | AN5: 350cc | AQ5: Type | AR5: 7 KW Bike | AS5: 7 KW SCOOTER | AT5: 7 KW - 16 KW | AU5: > 16 KW | AX5: 150cc | AY5: SCOOTER | AZ5: 150_350cc | BB5: 150cc | BC5: SCOOTER | BD5: 150_350cc | BE5: 350cc
B6: AP | C6: NEW(100-500 NOP) | D6: 0.425 | E6: 0.425 | F6: 0.425 | G6: 0 | I6: 0.35 | J6: 0.5 | K6: 0.3 | L6: 0 | N6: 0.45 | O6: 0.45 | P6: 0.45 | Q6: 0 | S6: 0.35 | T6: 0.4 | U6: 0.35 | V6: 0 | X6: 0.15 | Y6: 0.15 | AA6: 0.35 | AB6: 0.475 | AC6: 0.35 | AD6: 0 | AF6: 0.17 | AG6: 0.345 | AH6: 0.17 | AI6: 0 | AK6: 0.17 | AL6: 0.395 | AM6: 0 | AN6: 0 | AP6: AP | AQ6: NEW(100-500 NOP) | AR6: 0.17 | AS6: 0.32 | AT6: 0 | AU6: 0 | AX6: -0.205 | AY6: -0.055 | AZ6: -0.205 | BB6: 0.22 | BC6: 0.37 | BD6: 0.22 | BE6: 0
C7: NEW(30-100 NOP) | D7: 0.405 | E7: 0.405 | F7: 0.405 | G7: 0 | I7: 0.3 | J7: 0.4 | K7: 0.3 | L7: 0 | N7: 0.45 | O7: 0.45 | P7: 0.45 | Q7: 0 | S7: 0.33 | T7: 0.38 | U7: 0.33 | V7: 0 | X7: 0.13 | Y7: 0.13 | AA7: 0.3 | AB7: 0.375 | AC7: 0.3 | AD7: 0 | AF7: 0.15 | AG7: 0.325 | AH7: 0.15 | AI7: 0 | AK7: 0.17 | AL7: 0.395 | AM7: 0 | AN7: 0 | AQ7: NEW(30-100 NOP) | AR7: 0.17 | AS7: 0.32 | AT7: 0 | AU7: 0
C8: NEW(UPTO 30 NOP) | D8: 0.385 | E8: 0.385 | F8: 0.385 | G8: 0 | I8: 0.27 | J8: 0.37 | K8: 0.27 | L8: 0 | N8: 0.4 | O8: 0.4 | P8: 0.4 | Q8: 0 | S8: 0.31 | T8: 0.36 | U8: 0.31 | V8: 0 | X8: 0.11 | Y8: 0.11 | AA8: 0.17 | AB8: 0.345 | AC8: 0.17 | AD8: 0 | AF8: 0.13 | AG8: 0.305 | AH8: 0.13 | AI8: 0 | AK8: 0.17 | AL8: 0.395 | AM8: 0 | AN8: 0 | AQ8: NEW(UPTO 30 NOP) | AR8: 0.17 | AS8: 0.32 | AT8: 0 | AU8: 0
C9: ANNUAL | D9: 0.1 | E9: 0.4 | F9: 0.1 | G9: 0 | I9: 0.1 | J9: 0.4 | K9: 0.1 | L9: 0 | N9: 0.1 | O9: 0.4 | P9: 0.1 | Q9: 0 | S9: 0.06 | T9: 0.4 | U9: 0.06 | V9: 0 | X9: 0 | Y9: 0 | AA9: 0.05 | AB9: 0.375 | AC9: 0.05 | AD9: 0 | AF9: 0 | AG9: 0.375 | AH9: 0 | AI9: 0 | AK9: 0.05 | AL9: 0.375 | AM9: 0 | AN9: 0 | AQ9: ANNUAL | AR9: 0 | AS9: 0 | AT9: 0 | AU9: 0 | AX9: -0.3 | AY9: 0 | AZ9: -0.3 | BB9: 0.22 | BC9: 0.37 | BD9: 0.22 | BE9: 0
C10: ACT | D10: 0 | E10: 0.3 | F10: 0 | G10: 0 | I10: 0 | J10: 0.3 | K10: 0 | L10: 0 | N10: 0 | O10: 0.3 | P10: 0 | Q10: 0 | S10: 0 | T10: 0.3 | U10: 0 | V10: 0 | X10: 0 | Y10: 0 | AA10: 0 | AB10: 0.275 | AC10: 0 | AD10: 0 | AF10: 0 | AG10: 0.275 | AH10: 0 | AI10: 0 | AK10: 0 | AL10: 0.275 | AM10: 0 | AN10: 0 | AQ10: ACT | AR10: 0 | AS10: 0 | AT10: 0 | AU10: 0 | AY10: 0 | BB10: 0 | BC10: 0.3 | BD10: 0 | BE10: 0
B12: TS | C12: NEW(100-500 NOP) | D12: 0.42 | E12: 0.42 | F12: 0.42 | G12: 0 | I12: 0.35 | J12: 0.5 | K12: 0.3 | L12: 0 | N12: 0.45 | O12: 0.45 | P12: 0.45 | Q12: 0 | S12: 0.43 | T12: 0.43 | U12: 0.43 | V12: 0 | X12: 0.225 | Y12: 0.225 | AA12: 0.35 | AB12: 0.475 | AC12: 0.35 | AD12: 0 | AF12: 0.17 | AG12: 0.345 | AH12: 0.17 | AI12: 0 | AK12: 0.17 | AL12: 0.395 | AM12: 0 | AN12: 0 | AP12: TS | AQ12: NEW(100-500 NOP) | AR12: 0.17 | AS12: 0.32 | AT12: 0 | AU12: 0 | AX12: -0.2 | AY12: -0.05 | AZ12: -0.2 | BB12: 0.22 | BC12: 0.37 | BD12: 0.22 | BE12: 0
C13: NEW(30-100 NOP) | D13: 0.4 | E13: 0.4 | F13: 0.4 | G13: 0 | I13: 0.3 | J13: 0.4 | K13: 0.3 | L13: 0 | N13: 0.45 | O13: 0.45 | P13: 0.45 | Q13: 0 | S13: 0.41 | T13: 0.41 | U13: 0.41 | V13: 0 | X13: 0.205 | Y13: 0.205 | AA13: 0.3 | AB13: 0.375 | AC13: 0.3 | AD13: 0 | AF13: 0.15 | AG13: 0.325 | AH13: 0.15 | AI13: 0 | AK13: 0.17 | AL13: 0.395 | AM13: 0 | AN13: 0 | AQ13: NEW(30-100 NOP) | AR13: 0.17 | AS13: 0.32 | AT13: 0 | AU13: 0
C14: NEW(UPTO 30 NOP) | D14: 0.38 | E14: 0.38 | F14: 0.38 | G14: 0 | I14: 0.27 | J14: 0.37 | K14: 0.27 | L14: 0 | N14: 0.4 | O14: 0.4 | P14: 0.4 | Q14: 0 | S14: 0.39 | T14: 0.39 | U14: 0.39 | V14: 0 | X14: 0.185 | Y14: 0.185 | AA14: 0.17 | AB14: 0.345 | AC14: 0.17 | AD14: 0 | AF14: 0.13 | AG14: 0.305 | AH14: 0.13 | AI14: 0 | AK14: 0.17 | AL14: 0.395 | AM14: 0 | AN14: 0 | AQ14: NEW(UPTO 30 NOP) | AR14: 0.17 | AS14: 0.32 | AT14: 0 | AU14: 0
C15: ANNUAL | D15: 0.1 | E15: 0.4 | F15: 0.3 | G15: 0 | I15: 0.1 | J15: 0.4 | K15: 0.1 | L15: 0 | N15: 0.1 | O15: 0.4 | P15: 0.1 | Q15: 0 | S15: 0.06 | T15: 0.4 | U15: 0.06 | V15: 0 | X15: 0 | Y15: 0 | AA15: 0.05 | AB15: 0.375 | AC15: 0.05 | AD15: 0 | AF15: 0 | AG15: 0.375 | AH15: 0 | AI15: 0 | AK15: 0.05 | AL15: 0.375 | AM15: 0 | AN15: 0 | AQ15: ANNUAL | AR15: 0 | AS15: 0 | AT15: 0 | AU15: 0 | AX15: -0.3 | AY15: 0 | AZ15: -0.3 | BB15: 0.22 | BC15: 0.37 | BD15: 0.22 | BE15: 0
C16: ACT | D16: 0 | E16: 0.3 | F16: 0 | G16: 0 | I16: 0 | J16: 0.3 | K16: 0 | L16: 0 | N16: 0 | O16: 0.3 | P16: 0 | Q16: 0 | S16: 0 | T16: 0.3 | U16: 0 | V16: 0 | X16: 0 | Y16: 0 | AA16: 0 | AB16: 0.275 | AC16: 0 | AD16: 0 | AF16: 0 | AG16: 0.275 | AH16: 0 | AI16: 0 | AK16: 0 | AL16: 0.275 | AM16: 0 | AN16: 0 | AQ16: ACT | AR16: 0 | AS16: 0 | AT16: 0 | AU16: 0 | AY16: 0 | BB16: 0 | BC16: 0.3 | BD16: 0 | BE16: 0
B18: TN/ROK | C18: NEW(100-500 NOP) | D18: 0.1 | E18: 0.1 | F18: 0.1 | G18: 0 | I18: 0.15 | J18: 0.42 | K18: 0.08 | L18: 0 | N18: 0.45 | O18: 0.45 | P18: 0.45 | Q18: 0 | S18: 0.1 | T18: 0.1 | U18: 0.1 | V18: 0 | X18: 0.075 | Y18: 0.075 | AA18: 0.1 | AB18: 0.395 | AC18: 0.1 | AD18: 0 | AF18: 0.025 | AG18: 0.295 | AH18: 0.025 | AI18: 0 | AK18: 0.025 | AL18: 0.395 | AM18: 0 | AN18: 0 | AP18: TN | AQ18: NEW(100-500 NOP) | AR18: 0.025 | AS18: 0.27 | AT18: 0 | AU18: 0 | AX18: -0.025 | AY18: 0.22 | AZ18: -0.025 | BB18: 0.075 | BC18: 0.32 | BD18: 0.075 | BE18: 0
C19: NEW(30-100 NOP) | D19: 0.08 | E19: 0.08 | F19: 0.08 | G19: 0 | I19: 0.1 | J19: 0.375 | K19: 0.08 | L19: 0 | N19: 0.45 | O19: 0.45 | P19: 0.45 | Q19: 0 | S19: 0.08 | T19: 0.08 | U19: 0.08 | V19: 0 | X19: 0.075 | Y19: 0.075 | AA19: 0.05 | AB19: 0.345 | AC19: 0.05 | AD19: 0 | AF19: 0 | AG19: 0.275 | AH19: 0.01 | AI19: 0 | AK19: 0.025 | AL19: 0.395 | AM19: 0 | AN19: 0 | AQ19: NEW(30-100 NOP) | AR19: 0.025 | AS19: 0.27 | AT19: 0 | AU19: 0
C20: NEW(UPTO 30 NOP) | D20: 0.06 | E20: 0.06 | F20: 0.06 | G20: 0 | I20: 0.08 | J20: 0.325 | K20: 0.08 | L20: 0 | N20: 0.4 | O20: 0.4 | P20: 0.4 | Q20: 0 | S20: 0.06 | T20: 0.06 | U20: 0.06 | V20: 0 | X20: 0.075 | Y20: 0.075 | AA20: 0.03 | AB20: 0.295 | AC20: 0.03 | AD20: 0 | AF20: 0 | AG20: 0.255 | AH20: 0.01 | AI20: 0 | AK20: 0.025 | AL20: 0.395 | AM20: 0 | AN20: 0 | AQ20: NEW(UPTO 30 NOP) | AR20: 0.025 | AS20: 0.27 | AT20: 0 | AU20: 0
C21: ANNUAL | D21: 0.075 | E21: 0.4 | F21: 0.075 | G21: 0 | I21: 0.075 | J21: 0.4 | K21: 0.075 | L21: 0 | N21: 0.1 | O21: 0.4 | P21: 0.1 | Q21: 0 | S21: 0.075 | T21: 0.4 | U21: 0.075 | V21: 0 | X21: 0.075 | Y21: 0.075 | AA21: 0.03 | AB21: 0.375 | AC21: 0.03 | AD21: 0 | AF21: 0.025 | AG21: 0.375 | AH21: 0.025 | AI21: 0 | AK21: 0.025 | AL21: 0.375 | AM21: 0 | AN21: 0 | AQ21: ANNUAL | AR21: 0 | AS21: 0 | AT21: 0 | AU21: 0 | AX21: 0 | AY21: 0 | AZ21: 0 | BB21: 0.075 | BC21: 0.32 | BD21: 0.075 | BE21: 0
C22: ACT | D22: 0 | E22: 0.3 | F22: 0 | G22: 0 | I22: 0 | J22: 0.3 | K22: 0 | L22: 0 | N22: 0 | O22: 0.3 | P22: 0 | Q22: 0 | S22: 0 | T22: 0.3 | U22: 0 | V22: 0 | X22: 0 | Y22: 0 | AA22: 0 | AB22: 0.275 | AC22: 0 | AD22: 0 | AF22: 0 | AG22: 0.275 | AH22: 0 | AI22: 0 | AK22: 0 | AL22: 0.275 | AM22: 0 | AN22: 0 | AQ22: ACT | AR22: 0 | AS22: 0 | AT22: 0 | AU22: 0 | AY22: 0 | BB22: 0 | BC22: 0.3 | BD22: 0 | BE22: 0
B24: KA (Bangalore) | C24: NEW(100-500 NOP) | D24: 0.125 | E24: 0.125 | F24: 0.125 | G24: 0 | I24: 0.15 | J24: 0.42 | K24: 0.08 | L24: 0 | N24: 0.45 | O24: 0.45 | P24: 0.45 | Q24: 0 | S24: 0.1 | T24: 0.32 | U24: 0.1 | V24: 0 | X24: 0.075 | Y24: 0.075 | AA24: 0.1 | AB24: 0.395 | AC24: 0.1 | AD24: 0 | AF24: 0.05 | AG24: 0.295 | AH24: 0.05 | AI24: 0 | AK24: 0.05 | AL24: 0.395 | AM24: 0 | AN24: 0 | AP24: KA | AQ24: NEW(100-500 NOP) | AR24: 0.05 | AS24: 0.27 | AT24: 0 | AU24: 0 | AX24: -0.025 | AY24: 0.195 | AZ24: -0.025 | BB24: 0.1 | BC24: 0.32 | BD24: 0.1 | BE24: 0
C25: NEW(30-100 NOP) | D25: 0.105 | E25: 0.105 | F25: 0.105 | G25: 0 | I25: 0.1 | J25: 0.375 | K25: 0.08 | L25: 0 | N25: 0.45 | O25: 0.45 | P25: 0.45 | Q25: 0 | S25: 0.08 | T25: 0.3 | U25: 0.08 | V25: 0 | X25: 0.075 | Y25: 0.075 | AA25: 0.05 | AB25: 0.345 | AC25: 0.05 | AD25: 0 | AF25: 0.03 | AG25: 0.275 | AH25: 0.03 | AI25: 0 | AK25: 0.05 | AL25: 0.395 | AM25: 0 | AN25: 0 | AQ25: NEW(30-100 NOP) | AR25: 0.05 | AS25: 0.27 | AT25: 0 | AU25: 0
C26: NEW(UPTO 30 NOP) | D26: 0.085 | E26: 0.085 | F26: 0.085 | G26: 0 | I26: 0.08 | J26: 0.325 | K26: 0.08 | L26: 0 | N26: 0.4 | O26: 0.4 | P26: 0.4 | Q26: 0 | S26: 0.06 | T26: 0.28 | U26: 0.06 | V26: 0 | X26: 0.075 | Y26: 0.075 | AA26: 0.03 | AB26: 0.295 | AC26: 0.03 | AD26: 0 | AF26: 0.01 | AG26: 0.255 | AH26: 0.01 | AI26: 0 | AK26: 0.05 | AL26: 0.395 | AM26: 0 | AN26: 0 | AQ26: NEW(UPTO 30 NOP) | AR26: 0.05 | AS26: 0.27 | AT26: 0 | AU26: 0
C27: ANNUAL | D27: 0.075 | E27: 0.4 | F27: 0.075 | G27: 0 | I27: 0.075 | J27: 0.4 | K27: 0.075 | L27: 0 | N27: 0.1 | O27: 0.4 | P27: 0.1 | Q27: 0 | S27: 0.075 | T27: 0.4 | U27: 0.075 | V27: 0 | X27: 0.075 | Y27: 0.075 | AA27: 0.03 | AB27: 0.375 | AC27: 0.03 | AD27: 0 | AF27: 0.025 | AG27: 0.375 | AH27: 0.025 | AI27: 0 | AK27: 0.05 | AL27: 0.375 | AM27: 0 | AN27: 0 | AQ27: ANNUAL | AR27: 0 | AS27: 0 | AT27: 0 | AU27: 0 | AX27: 0 | AY27: 0 | AZ27: 0 | BB27: 0.1 | BC27: 0.32 | BD27: 0.1 | BE27: 0
C28: ACT | D28: 0 | E28: 0.075 | F28: 0 | G28: 0 | I28: 0 | J28: 0.075 | K28: 0 | L28: 0 | N28: 0 | O28: 0.075 | P28: 0 | Q28: 0 | S28: 0 | T28: 0.075 | U28: 0 | V28: 0 | X28: 0 | Y28: 0 | AA28: 0 | AB28: 0.05 | AC28: 0 | AD28: 0 | AF28: 0 | AG28: 0.05 | AH28: 0 | AI28: 0 | AK28: 0 | AL28: 0.05 | AM28: 0 | AN28: 0 | AQ28: ACT | AR28: 0 | AS28: 0 | AT28: 0 | AU28: 0 | AY28: 0 | BB28: 0 | BC28: 0.075 | BD28: 0 | BE28: 0
B30: KL/LD | C30: NEW(100-500 NOP) | D30: 0 | E30: 0 | F30: 0 | G30: 0 | I30: 0.05 | J30: 0.1 | K30: 0.05 | L30: 0 | N30: 0.075 | O30: 0.075 | P30: 0.075 | Q30: 0 | S30: 0 | T30: 0 | U30: 0 | V30: 0 | X30: 0 | Y30: 0 | AA30: 0 | AB30: 0 | AC30: 0 | AD30: 0 | AF30: 0 | AG30: 0 | AH30: 0 | AI30: 0 | AK30: 0 | AL30: 0.05 | AM30: 0 | AN30: 0 | AP30: KL | AQ30: NEW(100-500 NOP) | AR30: 0 | AS30: 0 | AT30: 0 | AU30: 0 | AX30: 0 | AY30: 0 | AZ30: 0 | BB30: 0 | BC30: 0 | BD30: 0 | BE30: 0
C31: NEW(30-100 NOP) | D31: 0 | E31: 0 | F31: 0 | G31: 0 | I31: 0.05 | J31: 0.1 | K31: 0.05 | L31: 0 | N31: 0.075 | O31: 0.075 | P31: 0.075 | Q31: 0 | S31: 0 | T31: 0 | U31: 0 | V31: 0 | X31: 0 | Y31: 0 | AA31: 0 | AB31: 0 | AC31: 0 | AD31: 0 | AF31: 0 | AG31: 0 | AH31: 0 | AI31: 0 | AK31: 0 | AL31: 0.05 | AM31: 0 | AN31: 0 | AQ31: NEW(30-100 NOP) | AR31: 0 | AS31: 0 | AT31: 0 | AU31: 0
C32: NEW(UPTO 30 NOP) | D32: 0 | E32: 0 | F32: 0 | G32: 0 | I32: 0.05 | J32: 0.1 | K32: 0.05 | L32: 0 | N32: 0.075 | O32: 0.075 | P32: 0.075 | Q32: 0 | S32: 0 | T32: 0 | U32: 0 | V32: 0 | X32: 0 | Y32: 0 | AA32: 0 | AB32: 0 | AC32: 0 | AD32: 0 | AF32: 0 | AG32: 0 | AH32: 0 | AI32: 0 | AK32: 0 | AL32: 0.05 | AM32: 0 | AN32: 0 | AQ32: NEW(UPTO 30 NOP) | AR32: 0 | AS32: 0 | AT32: 0 | AU32: 0
C33: ANNUAL | D33: 0 | E33: 0 | F33: 0 | G33: 0 | I33: 0.05 | J33: 0 | K33: 0.05 | L33: 0 | N33: 0.05 | O33: 0 | P33: 0.05 | Q33: 0 | S33: 0 | T33: 0 | U33: 0 | V33: 0 | X33: 0 | Y33: 0 | AA33: 0 | AB33: 0 | AC33: 0 | AD33: 0 | AF33: 0 | AG33: 0 | AH33: 0 | AI33: 0 | AK33: 0 | AL33: 0 | AM33: 0 | AN33: 0 | AQ33: ANNUAL | AR33: 0 | AS33: 0 | AT33: 0 | AU33: 0 | AX33: 0 | AY33: 0 | AZ33: 0 | BB33: 0 | BC33: 0 | BD33: 0 | BE33: 0
C34: ACT | D34: 0 | E34: 0 | F34: 0 | G34: 0 | I34: 0 | J34: 0 | K34: 0 | L34: 0 | N34: 0 | O34: 0 | P34: 0 | Q34: 0 | S34: 0 | T34: 0 | U34: 0 | V34: 0 | X34: 0 | Y34: 0 | AA34: 0 | AB34: 0 | AC34: 0 | AD34: 0 | AF34: 0 | AG34: 0 | AH34: 0 | AI34: 0 | AK34: 0 | AL34: 0 | AM34: 0 | AN34: 0 | AQ34: ACT | AR34: 0 | AS34: 0 | AT34: 0 | AU34: 0 | AY34: 0 | BB34: 0 | BC34: 0 | BD34: 0 | BE34: 0
B36: PY | C36: NEW(100-500 NOP) | D36: 0 | E36: 0 | F36: 0 | G36: 0 | I36: 0 | J36: 0 | K36: 0 | L36: 0 | N36: 0 | O36: 0 | P36: 0 | Q36: 0 | S36: 0 | T36: 0 | U36: 0 | V36: 0 | X36: 0 | Y36: 0 | AA36: 0 | AB36: 0 | AC36: 0 | AD36: 0 | AF36: 0 | AG36: 0 | AH36: 0 | AI36: 0 | AK36: 0 | AL36: 0 | AM36: 0 | AN36: 0 | AP36: PY | AQ36: NEW(100-500 NOP) | AR36: 0 | AS36: 0 | AT36: 0 | AU36: 0 | AX36: 0 | AY36: 0 | AZ36: 0 | BB36: 0 | BC36: 0 | BD36: 0 | BE36: 0
C37: NEW(30-100 NOP) | D37: 0 | E37: 0 | F37: 0 | G37: 0 | I37: 0 | J37: 0 | K37: 0 | L37: 0 | N37: 0 | O37: 0 | P37: 0 | Q37: 0 | S37: 0 | T37: 0 | U37: 0 | V37: 0 | X37: 0 | Y37: 0 | AA37: 0 | AB37: 0 | AC37: 0 | AD37: 0 | AF37: 0 | AG37: 0 | AH37: 0 | AI37: 0 | AK37: 0 | AL37: 0 | AM37: 0 | AN37: 0 | AQ37: NEW(30-100 NOP) | AR37: 0 | AS37: 0 | AT37: 0 | AU37: 0
C38: NEW(UPTO 30 NOP) | D38: 0 | E38: 0 | F38: 0 | G38: 0 | I38: 0 | J38: 0 | K38: 0 | L38: 0 | N38: 0 | O38: 0 | P38: 0 | Q38: 0 | S38: 0 | T38: 0 | U38: 0 | V38: 0 | X38: 0 | Y38: 0 | AA38: 0 | AB38: 0 | AC38: 0 | AD38: 0 | AF38: 0 | AG38: 0 | AH38: 0 | AI38: 0 | AK38: 0 | AL38: 0 | AM38: 0 | AN38: 0 | AQ38: NEW(UPTO 30 NOP) | AR38: 0 | AS38: 0 | AT38: 0 | AU38: 0
C39: ANNUAL | D39: 0 | E39: 0 | F39: 0 | G39: 0 | I39: 0 | J39: 0 | K39: 0 | L39: 0 | N39: 0 | O39: 0 | P39: 0 | Q39: 0 | S39: 0 | T39: 0 | U39: 0 | V39: 0 | X39: 0 | Y39: 0 | AA39: 0 | AB39: 0 | AC39: 0 | AD39: 0 | AF39: 0 | AG39: 0 | AH39: 0 | AI39: 0 | AK39: 0 | AL39: 0 | AM39: 0 | AN39: 0 | AQ39: ANNUAL | AR39: 0 | AS39: 0 | AT39: 0 | AU39: 0 | AX39: 0 | AY39: 0 | AZ39: 0 | BB39: 0 | BC39: 0 | BD39: 0 | BE39: 0
C40: ACT | D40: 0 | E40: 0 | F40: 0 | G40: 0 | I40: 0 | J40: 0 | K40: 0 | L40: 0 | N40: 0 | O40: 0 | P40: 0 | Q40: 0 | S40: 0 | T40: 0 | U40: 0 | V40: 0 | X40: 0 | Y40: 0 | AA40: 0 | AB40: 0 | AC40: 0 | AD40: 0 | AF40: 0 | AG40: 0 | AH40: 0 | AI40: 0 | AK40: 0 | AL40: 0 | AM40: 0 | AN40: 0 | AQ40: ACT | AR40: 0 | AS40: 0 | AT40: 0 | AU40: 0 | AY40: 0 | BB40: 0 | BC40: 0 | BD40: 0 | BE40: 0
B42: MH | C42: NEW(100-500 NOP) | D42: 0.35 | E42: 0.4 | F42: 0.4 | G42: 0 | I42: 0.25 | J42: 0.45 | K42: 0.25 | L42: 0 | N42: 0.45 | O42: 0.45 | P42: 0.45 | Q42: 0 | S42: 0.35 | T42: 0.4 | U42: 0.35 | V42: 0 | X42: 0.225 | Y42: 0.225 | AA42: 0.35 | AB42: 0.525 | AC42: 0.35 | AD42: 0 | AF42: 0 | AG42: 0.325 | AH42: 0 | AI42: 0 | AK42: 0 | AL42: 0.395 | AM42: 0 | AN42: 0 | AP42: MH | AQ42: NEW(100-500 NOP) | AR42: 0.17 | AS42: 0.3 | AT42: 0 | AU42: 0 | AX42: -0.18 | AY42: -0.05 | AZ42: -0.18 | BB42: 0.22 | BC42: 0.35 | BD42: 0.22 | BE42: 0
C43: NEW(30-100 NOP) | D43: 0.3 | E43: 0.35 | F43: 0.35 | G43: 0 | I43: 0.2 | J43: 0.4 | K43: 0.2 | L43: 0 | N43: 0.45 | O43: 0.45 | P43: 0.45 | Q43: 0 | S43: 0.33 | T43: 0.38 | U43: 0.33 | V43: 0 | X43: 0.205 | Y43: 0.205 | AA43: 0.2 | AB43: 0.375 | AC43: 0.2 | AD43: 0 | AF43: 0 | AG43: 0.305 | AH43: 0 | AI43: 0 | AK43: 0 | AL43: 0.395 | AM43: 0 | AN43: 0 | AQ43: NEW(30-100 NOP) | AR43: 0.17 | AS43: 0.3 | AT43: 0 | AU43: 0
C44: NEW(UPTO 30 NOP) | D44: 0.25 | E44: 0.3 | F44: 0.3 | G44: 0 | I44: 0.15 | J44: 0.375 | K44: 0.17 | L44: 0 | N44: 0.4 | O44: 0.4 | P44: 0.4 | Q44: 0 | S44: 0.3 | T44: 0.36 | U44: 0.3 | V44: 0 | X44: 0.185 | Y44: 0.185 | AA44: 0.15 | AB44: 0.345 | AC44: 0.15 | AD44: 0 | AF44: 0 | AG44: 0.285 | AH44: 0 | AI44: 0 | AK44: 0 | AL44: 0.395 | AM44: 0 | AN44: 0 | AQ44: NEW(UPTO 30 NOP) | AR44: 0.17 | AS44: 0.3 | AT44: 0 | AU44: 0
C45: ANNUAL | D45: 0.1 | E45: 0.45 | F45: 0.1 | G45: 0 | I45: 0.1 | J45: 0.45 | K45: 0.1 | L45: 0 | N45: 0.1 | O45: 0.45 | P45: 0.1 | Q45: 0 | S45: 0.1 | T45: 0.45 | U45: 0.1 | V45: 0 | X45: 0 | Y45: 0 | AA45: 0.05 | AB45: 0.425 | AC45: 0.05 | AD45: 0 | AF45: 0.05 | AG45: 0.425 | AH45: 0.05 | AI45: 0 | AK45: 0.05 | AL45: 0.425 | AM45: 0 | AN45: 0 | AQ45: ANNUAL | AR45: 0 | AS45: 0 | AT45: 0 | AU45: 0 | AX45: 0.07 | AY45: 0 | AZ45: 0.07 | BB45: 0.22 | BC45: 0.35 | BD45: 0.22 | BE45: 0
C46: ACT | D46: 0 | E46: 0.25 | F46: 0 | G46: 0 | I46: 0 | J46: 0.25 | K46: 0 | L46: 0 | N46: 0 | O46: 0.25 | P46: 0 | Q46: 0 | S46: 0 | T46: 0.25 | U46: 0 | V46: 0 | X46: 0 | Y46: 0 | AA46: 0 | AB46: 0.225 | AC46: 0 | AD46: 0 | AF46: 0 | AG46: 0.225 | AH46: 0 | AI46: 0 | AK46: 0 | AL46: 0.225 | AM46: 0 | AN46: 0 | AQ46: ACT | AR46: 0 | AS46: 0 | AT46: 0 | AU46: 0 | AY46: 0 | BB46: 0 | BC46: 0.25 | BD46: 0 | BE46: 0
B48: GJ/DN/DD | C48: NEW(100-500 NOP) | D48: 0.4 | E48: 0.4 | F48: 0.4 | G48: 0 | I48: 0.1 | J48: 0.5 | K48: 0.1 | L48: 0 | N48: 0.45 | O48: 0.45 | P48: 0.45 | Q48: 0 | S48: 0.075 | T48: 0.3 | U48: 0.075 | V48: 0 | X48: 0.15 | Y48: 0.15 | AA48: 0.17 | AB48: 0.475 | AC48: 0.17 | AD48: 0 | AF48: 0.025 | AG48: 0.275 | AH48: 0.025 | AI48: 0 | AK48: 0.17 | AL48: 0.395 | AM48: 0 | AN48: 0 | AP48: GJ | AQ48: NEW(100-500 NOP) | AR48: 0.17 | AS48: 0.3 | AT48: 0 | AU48: 0 | AX48: -0.325 | AY48: -0.1 | AZ48: -0.325 | BB48: 0.22 | BC48: 0.35 | BD48: 0.22 | BE48: 0
...

Sheet Private car Nov-25 
B2: Private Car Grid for the month of Nov 25
C4: PROD | D4: SUBCLASS | F4: AP/TS | I4: TN | L4: KA | O4: MH/GA | R4: GJ | U4: BH | X4: JH | AA4: OD | AD4: WB | AG4: CG | AJ4: AS/ML/TR/AR/NL | AM4: DL | AP4: PB | AS4: HP | AV4: JK | AY4: UP- East | BB4: UP | BE4: UK | BH4: AN | BK4: RJ | BM4: MP
F6: ACT | G6: PACK | I6: ACT | J6: PACK | L6: ACT | M6: PACK | O6: ACT | P6: PACK | R6: ACT | S6: PACK | U6: ACT | V6: PACK | X6: ACT | Y6: PACK | AA6: ACT | AB6: PACK | AD6: ACT | AE6: PACK | AG6: ACT | AH6: PACK | AJ6: ACT | AK6: PACK | AM6: ACT | AN6: PACK | AP6: ACT | AQ6: PACK | AS6: ACT | AT6: PACK | AV6: ACT | AW6: PACK | AY6: ACT | AZ6: PACK | BB6: ACT | BC6: PACK | BE6: ACT | BF6: PACK | BH6: ACT | BI6: PACK | BK6: ACT | BL6: PACK | BM6: ACT | BN6: PACK
C7: PC [PACK] | D7: UPTO 1000 CC | G7: 0.3 | J7: 0.25 | M7: 0.3 | O7: 0.25 | P7: 0.3 | S7: 0.3 | U7: 0.3 | V7: 0.3 | X7: 0.3 | Y7: 0.3 | AB7: 0.25 | AE7: 0.2 | AH7: 0.15 | AK7: 0.25 | AN7: 0.25 | AQ7: 0.25 | AT7: 0.25 | AW7: 0.25 | AZ7: 0.25 | BC7: 0.15 | BF7: 0.3 | BI7: 0.3 | BL7: 0.15 | BN7: 0.15
D8: 1000 TO 1500 CC | F8: 0.2 | G8: 0.3 | J8: 0.25 | M8: 0.3 | O8: 0.25 | P8: 0.3 | R8: 0.25 | S8: 0.3 | U8: 0.3 | V8: 0.3 | X8: 0.3 | Y8: 0.3 | AA8: 0.25 | AB8: 0.25 | AD8: 0.25 | AE8: 0.275 | AG8: 0 | AH8: 0.24 | AJ8: 0.25 | AK8: 0.25 | AM8: 0.3 | AN8: 0.25 | AQ8: 0.25 | AT8: 0.25 | AW8: 0.25 | AZ8: 0.25 | BC8: 0.2 | BF8: 0.3 | BH8: 0.25 | BI8: 0.3 | BL8: 0.2 | BN8: 0.2
D9: ABOVE 1500 CC | F9: 0.2 | G9: 0.3 | J9: 0.3 | L9: 0.1 | M9: 0.3 | O9: 0.25 | P9: 0.3 | R9: 0.2 | S9: 0.3 | U9: 0.3 | V9: 0.3 | X9: 0.3 | Y9: 0.3 | AA9: 0.3 | AB9: 0.3 | AD9: 0.25 | AE9: 0.3 | AG9: 0 | AH9: 0.3 | AJ9: 0.2 | AK9: 0.3 | AM9: 0.3 | AN9: 0.3 | AQ9: 0.3 | AT9: 0.3 | AW9: 0.3 | AZ9: 0.3 | BC9: 0.3 | BF9: 0.3 | BH9: 0.25 | BI9: 0.3 | BL9: 0.25 | BN9: 0.25
C12: PC [SOD] | D12: UPTO 1000 CC[P] | G12: 0.1 | J12: 0.1 | M12: 0.19 | P12: 0.19 | S12: 0.1 | V12: 0.1 | Y12: 0.19 | AB12: 0.1 | AE12: 0.1 | AH12: 0.1 | AK12: 0.19 | AN12: 0.1 | AQ12: 0.1 | AT12: 0.1 | AW12: 0.1 | AZ12: 0.15 | BC12: 0.1 | BF12: 0.15 | BI12: 0.1
D13: 1000 TO 1500 CC[P] | G13: 0.19 | J13: 0.16 | M13: 0.19 | P13: 0.19 | S13: 0.16 | V13: 0.15 | Y13: 0.19 | AB13: 0.16 | AE13: 0.19 | AH13: 0.15 | AK13: 0.19 | AN13: 0.15 | AQ13: 0.15 | AT13: 0.15 | AW13: 0.15 | AZ13: 0.2 | BC13: 0.15 | BF13: 0.2 | BI13: 0.15
D14: ABOVE 1500 CC[P] | G14: 0.2 | J14: 0.2 | M14: 0.2 | P14: 0.2 | S14: 0.2 | V14: 0.2 | Y14: 0.2 | AB14: 0.2 | AE14: 0.2 | AH14: 0.2 | AK14: 0.2 | AN14: 0.2 | AQ14: 0.2 | AT14: 0.2 | AW14: 0.2 | AZ14: 0.25 | BC14: 0.25 | BF14: 0.25 | BI14: 0.2
D16: UPTO 1000 CC[D] | G16: 0.1 | J16: 0.1 | M16: 0.1 | P16: 0.1 | S16: 0.1 | V16: 0.1 | Y16: 0.1 | AB16: 0.1 | AE16: 0.1 | AH16: 0.1 | AK16: 0.1 | AN16: 0.1 | AQ16: 0.1 | AT16: 0.1 | AW16: 0.1 | AZ16: 0.1 | BC16: 0.1 | BF16: 0.1 | BI16: 0.1
D17: 1000 TO 1500 CC[D] | G17: 0.1 | J17: 0.1 | M17: 0.1 | P17: 0.1 | S17: 0.1 | V17: 0.1 | Y17: 0.1 | AB17: 0.1 | AE17: 0.1 | AH17: 0.1 | AK17: 0.1 | AN17: 0.1 | AQ17: 0.1 | AT17: 0.1 | AW17: 0.1 | AZ17: 0.15 | BC17: 0.1 | BF17: 0.15 | BI17: 0.1
D18: ABOVE 1500 CC[D] | G18: 0.15 | J18: 0.15 | M18: 0.15 | P18: 0.15 | S18: 0.15 | V18: 0.15 | Y18: 0.15 | AB18: 0.15 | AE18: 0.15 | AH18: 0.15 | AK18: 0.15 | AN18: 0.15 | AQ18: 0.15 | AT18: 0.15 | AW18: 0.15 | AZ18: 0.2 | BC18: 0.2 | BF18: 0.2 | BI18: 0.15
C21: PC [PACK] | D21: UPTO 1000 CC[ NCB GT 25%] | G21: =G7+2.5% -> 0.325 | J21: =J7+2.5% -> 0.275 | M21: =M7+2.5% -> 0.325 | O21: 0.25 | P21: =P7+2.5% -> 0.325 | S21: =S7+2.5% -> 0.325 | U21: 0.3 | V21: 0.3 | X21: 0.3 | Y21: =Y7+2.5% -> 0.325 | AB21: =AB7+2.5% -> 0.275 | AE21: =AE7+2.5% -> 0.225 | AH21: 0.15 | AK21: =AK7+2.5% -> 0.275 | AN21: =AN7+2.5% -> 0.275 | AQ21: 0.25 | AT21: =AT7+2.5% -> 0.275 | AW21: 0.25 | AZ21: =AZ7+2.5% -> 0.275 | BC21: =BC7+2.5% -> 0.175 | BF21: =BF7+2.5% -> 0.325 | BI21: =BI7+2.5% -> 0.325 | BL21: 0.15 | BN21: 0.15
D22: 1000 TO 1500 CC[ NCB GT 25%] | F22: 0.2 | G22: =G8+2.5% -> 0.325 | J22: =J8+2.5% -> 0.275 | M22: =M8+2.5% -> 0.325 | O22: 0.25 | P22: =P8+2.5% -> 0.325 | R22: 0.25 | S22: =S8+2.5% -> 0.325 | U22: 0.3 | V22: 0.3 | X22: 0.3 | Y22: =Y8+2.5% -> 0.325 | AA22: 0.25 | AB22: =AB8+2.5% -> 0.275 | AD22: 0.25 | AE22: =AE8+2.5% -> 0.3 | AG22: 0 | AH22: 0.24 | AJ22: 0.25 | AK22: =AK8+2.5% -> 0.275 | AM22: 0.3 | AN22: =AN8+2.5% -> 0.275 | AQ22: 0.25 | AT22: =AT8+2.5% -> 0.275 | AW22: 0.25 | AZ22: =AZ8+2.5% -> 0.275 | BC22: =BC8+2.5% -> 0.225 | BF22: =BF8+2.5% -> 0.325 | BH22: 0.25 | BI22: =BI8+2.5% -> 0.325 | BL22: 0.2 | BN22: 0.2
D23: ABOVE 1500 CC[ NCB GT 25%] | F23: 0.2 | G23: =G9+2.5% -> 0.325 | J23: =J9+2.5% -> 0.325 | L23: 0.1 | M23: =M9+2.5% -> 0.325 | O23: 0.25 | P23: =P9+2.5% -> 0.325 | R23: 0.2 | S23: =S9+2.5% -> 0.325 | U23: 0.3 | V23: 0.3 | X23: 0.3 | Y23: =Y9+2.5% -> 0.325 | AA23: 0.3 | AB23: =AB9+2.5% -> 0.325 | AD23: 0.25 | AE23: =AE9+2.5% -> 0.325 | AG23: 0 | AH23: 0.3 | AJ23: 0.2 | AK23: =AK9+2.5% -> 0.325 | AM23: 0.3 | AN23: =AN9+2.5% -> 0.325 | AQ23: 0.3 | AT23: =AT9+2.5% -> 0.325 | AW23: 0.3 | AZ23: =AZ9+2.5% -> 0.325 | BC23: =BC9+2.5% -> 0.325 | BF23: =BF9+2.5% -> 0.325 | BH23: 0.25 | BI23: =BI9+2.5% -> 0.325 | BL23: 0.25 | BN23: 0.25
C26: PC [SOD] | D26: UPTO 1000 CC[P] [ NCB GT 25%] | G26: =G12+2.5% -> 0.125 | J26: =J12+2.5% -> 0.125 | M26: =M12+2.5% -> 0.215 | P26: =P12+2.5% -> 0.215 | S26: =S12+2.5% -> 0.125 | V26: 0.1 | Y26: =Y12+2.5% -> 0.215 | AB26: =AB12+2.5% -> 0.125 | AE26: =AE12+2.5% -> 0.125 | AH26: 0.1 | AK26: =AK12+2.5% -> 0.215 | AN26: =AN12+2.5% -> 0.125 | AQ26: 0.1 | AT26: =AT12+2.5% -> 0.125 | AW26: 0.1 | AZ26: =AZ12+2.5% -> 0.175 | BC26: =BC12+2.5% -> 0.125 | BF26: =BF12+2.5% -> 0.175 | BI26: =BI12+2.5% -> 0.125
D27: 1000 TO 1500 CC[P] [ NCB GT 25%] | G27: =G13+2.5% -> 0.215 | J27: =J13+2.5% -> 0.185 | M27: =M13+2.5% -> 0.215 | P27: =P13+2.5% -> 0.215 | S27: =S13+2.5% -> 0.185 | V27: 0.15 | Y27: =Y13+2.5% -> 0.215 | AB27: =AB13+2.5% -> 0.185 | AE27: =AE13+2.5% -> 0.215 | AH27: 0.15 | AK27: =AK13+2.5% -> 0.215 | AN27: =AN13+2.5% -> 0.175 | AQ27: 0.15 | AT27: =AT13+2.5% -> 0.175 | AW27: 0.15 | AZ27: =AZ13+2.5% -> 0.225 | BC27: =BC13+2.5% -> 0.175 | BF27: =BF13+2.5% -> 0.225 | BI27: =BI13+2.5% -> 0.175
D28: ABOVE 1500 CC[P] [ NCB GT 25%] | G28: =G14+2.5% -> 0.225 | J28: =J14+2.5% -> 0.225 | M28: =M14+2.5% -> 0.225 | P28: =P14+2.5% -> 0.225 | S28: =S14+2.5% -> 0.225 | V28: 0.2 | Y28: =Y14+2.5% -> 0.225 | AB28: =AB14+2.5% -> 0.225 | AE28: =AE14+2.5% -> 0.225 | AH28: 0.2 | AK28: =AK14+2.5% -> 0.225 | AN28: =AN14+2.5% -> 0.225 | AQ28: 0.2 | AT28: =AT14+2.5% -> 0.225 | AW28: 0.2 | AZ28: =AZ14+2.5% -> 0.275 | BC28: =BC14+2.5% -> 0.275 | BF28: =BF14+2.5% -> 0.275 | BI28: =BI14+2.5% -> 0.225
D30: UPTO 1000 CC[D] [ NCB GT 25%] | G30: =G16+2.5% -> 0.125 | J30: =J16+2.5% -> 0.125 | M30: =M16+2.5% -> 0.125 | P30: =P16+2.5% -> 0.125 | S30: =S16+2.5% -> 0.125 | V30: 0.1 | Y30: =Y16+2.5% -> 0.125 | AB30: =AB16+2.5% -> 0.125 | AE30: =AE16+2.5% -> 0.125 | AH30: 0.1 | AK30: =AK16+2.5% -> 0.125 | AN30: =AN16+2.5% -> 0.125 | AQ30: 0.1 | AT30: =AT16+2.5% -> 0.125 | AW30: 0.1 | AZ30: =AZ16+2.5% -> 0.125 | BC30: =BC16+2.5% -> 0.125 | BF30: =BF16+2.5% -> 0.125 | BI30: =BI16+2.5% -> 0.125
D31: 1000 TO 1500 CC[D] [ NCB GT 25%] | G31: =G17+2.5% -> 0.125 | J31: =J17+2.5% -> 0.125 | M31: =M17+2.5% -> 0.125 | P31: =P17+2.5% -> 0.125 | S31: =S17+2.5% -> 0.125 | V31: 0.1 | Y31: =Y17+2.5% -> 0.125 | AB31: =AB17+2.5% -> 0.125 | AE31: =AE17+2.5% -> 0.125 | AH31: 0.1 | AK31: =AK17+2.5% -> 0.125 | AN31: =AN17+2.5% -> 0.125 | AQ31: 0.1 | AT31: =AT17+2.5% -> 0.125 | AW31: 0.1 | AZ31: =AZ17+2.5% -> 0.175 | BC31: =BC17+2.5% -> 0.125 | BF31: =BF17+2.5% -> 0.175 | BI31: =BI17+2.5% -> 0.125
D32: ABOVE 1500 CC[D] [ NCB GT 25%] | G32: =G18+2.5% -> 0.175 | J32: =J18+2.5% -> 0.175 | M32: =M18+2.5% -> 0.175 | P32: =P18+2.5% -> 0.175 | S32: =S18+2.5% -> 0.175 | V32: 0.15 | Y32: =Y18+2.5% -> 0.175 | AB32: =AB18+2.5% -> 0.175 | AE32: =AE18+2.5% -> 0.175 | AH32: 0.15 | AK32: =AK18+2.5% -> 0.175 | AN32: =AN18+2.5% -> 0.175 | AQ32: 0.15 | AT32: =AT18+2.5% -> 0.175 | AW32: 0.15 | AZ32: =AZ18+2.5% -> 0.225 | BC32: =BC18+2.5% -> 0.225 | BF32: =BF18+2.5% -> 0.225 | BI32: =BI18+2.5% -> 0.175
C35: ** Please note that the above pay-out grid
C36: - For Private Car Package policy pay-out is on OD Cover Premium and Private Car Liability policy Pay-out is on TP/PA Premium
C37: - For Private Car Package & Liability policy CPA should be collected for individual Name Mandatorily
D38: if CPA is not collected for individual name then 1.5% of OD Pay-out will be deducted
C39: - For Private Car Electric Vehicle or LPG/CNG pay-out grid is same as Private Car Petrol grid

Sheet Private car AUG-25 
B2: Private Car Grid for the month of AUG 25
C4: PROD | D4: SUBCLASS | F4: AP/TS | I4: TN | L4: KA | O4: MH/GA | R4: GJ | U4: BH | X4: JH | AA4: OD | AD4: WB | AG4: CG | AJ4: AS/ML/TR/AR/NL | AM4: DL | AP4: PB | AS4: HP | AV4: JK | AY4: UP- East | BB4: UP | BE4: UK | BH4: AN | BK4: RJ | BM4: MP
F6: ACT | G6: PACK | I6: ACT | J6: PACK | L6: ACT | M6: PACK | O6: ACT | P6: PACK | R6: ACT | S6: PACK | U6: ACT | V6: PACK | X6: ACT | Y6: PACK | AA6: ACT | AB6: PACK | AD6: ACT | AE6: PACK | AG6: ACT | AH6: PACK | AJ6: ACT | AK6: PACK | AM6: ACT | AN6: PACK | AP6: ACT | AQ6: PACK | AS6: ACT | AT6: PACK | AV6: ACT | AW6: PACK | AY6: ACT | AZ6: PACK | BB6: ACT | BC6: PACK | BE6: ACT | BF6: PACK | BH6: ACT | BI6: PACK | BK6: ACT | BL6: PACK | BM6: ACT | BN6: PACK
C7: PC [PACK] | D7: UPTO 1000 CC | G7: 0.3 | J7: 0.25 | M7: 0.3 | O7: 0.25 | P7: 0.3 | S7: 0.3 | U7: 0.3 | V7: 0.3 | X7: 0.3 | Y7: 0.3 | AB7: 0.25 | AE7: 0.2 | AH7: 0.15 | AK7: 0.25 | AN7: 0.25 | AQ7: 0.25 | AT7: 0.25 | AW7: 0.25 | AZ7: 0.25 | BC7: 0.15 | BF7: 0.3 | BI7: 0.3 | BL7: 0.15 | BN7: 0.15
D8: 1000 TO 1500 CC | F8: 0.2 | G8: 0.3 | J8: 0.25 | M8: 0.3 | O8: 0.25 | P8: 0.3 | R8: 0.25 | S8: 0.3 | U8: 0.3 | V8: 0.3 | X8: 0.3 | Y8: 0.3 | AA8: 0.25 | AB8: 0.25 | AD8: 0.25 | AE8: 0.275 | AG8: 0 | AH8: 0.24 | AJ8: 0.25 | AK8: 0.25 | AM8: 0.3 | AN8: 0.25 | AQ8: 0.25 | AT8: 0.25 | AW8: 0.25 | AZ8: 0.25 | BC8: 0.2 | BF8: 0.3 | BH8: 0.25 | BI8: 0.3 | BL8: 0.2 | BN8: 0.2
D9: ABOVE 1500 CC | F9: 0.2 | G9: 0.3 | J9: 0.3 | L9: 0.1 | M9: 0.3 | O9: 0.25 | P9: 0.3 | R9: 0.2 | S9: 0.3 | U9: 0.3 | V9: 0.3 | X9: 0.3 | Y9: 0.3 | AA9: 0.3 | AB9: 0.3 | AD9: 0.25 | AE9: 0.3 | AG9: 0 | AH9: 0.3 | AJ9: 0.2 | AK9: 0.3 | AM9: 0.3 | AN9: 0.3 | AQ9: 0.3 | AT9: 0.3 | AW9: 0.3 | AZ9: 0.3 | BC9: 0.3 | BF9: 0.3 | BH9: 0.25 | BI9: 0.3 | BL9: 0.25 | BN9: 0.25
C12: PC [SOD] | D12: UPTO 1000 CC[P] | G12: 0.1 | J12: 0.1 | M12: 0.19 | P12: 0.19 | S12: 0.1 | V12: 0.1 | Y12: 0.19 | AB12: 0.1 | AE12: 0.1 | AH12: 0.1 | AK12: 0.19 | AN12: 0.1 | AQ12: 0.1 | AT12: 0.1 | AW12: 0.1 | AZ12: 0.15 | BC12: 0.1 | BF12: 0.15 | BI12: 0.1
D13: 1000 TO 1500 CC[P] | G13: 0.19 | J13: 0.16 | M13: 0.19 | P13: 0.19 | S13: 0.16 | V13: 0.15 | Y13: 0.19 | AB13: 0.16 | AE13: 0.19 | AH13: 0.15 | AK13: 0.19 | AN13: 0.15 | AQ13: 0.15 | AT13: 0.15 | AW13: 0.15 | AZ13: 0.2 | BC13: 0.15 | BF13: 0.2 | BI13: 0.15
D14: ABOVE 1500 CC[P] | G14: 0.2 | J14: 0.2 | M14: 0.2 | P14: 0.2 | S14: 0.2 | V14: 0.2 | Y14: 0.2 | AB14: 0.2 | AE14: 0.2 | AH14: 0.2 | AK14: 0.2 | AN14: 0.2 | AQ14: 0.2 | AT14: 0.2 | AW14: 0.2 | AZ14: 0.25 | BC14: 0.25 | BF14: 0.25 | BI14: 0.2
D16: UPTO 1000 CC[D] | G16: 0.1 | J16: 0.1 | M16: 0.1 | P16: 0.1 | S16: 0.1 | V16: 0.1 | Y16: 0.1 | AB16: 0.1 | AE16: 0.1 | AH16: 0.1 | AK16: 0.1 | AN16: 0.1 | AQ16: 0.1 | AT16: 0.1 | AW16: 0.1 | AZ16: 0.1 | BC16: 0.1 | BF16: 0.1 | BI16: 0.1
D17: 1000 TO 1500 CC[D] | G17: 0.1 | J17: 0.1 | M17: 0.1 | P17: 0.1 | S17: 0.1 | V17: 0.1 | Y17: 0.1 | AB17: 0.1 | AE17: 0.1 | AH17: 0.1 | AK17: 0.1 | AN17: 0.1 | AQ17: 0.1 | AT17: 0.1 | AW17: 0.1 | AZ17: 0.15 | BC17: 0.1 | BF17: 0.15 | BI17: 0.1
D18: ABOVE 1500 CC[D] | G18: 0.15 | J18: 0.15 | M18: 0.15 | P18: 0.15 | S18: 0.15 | V18: 0.15 | Y18: 0.15 | AB18: 0.15 | AE18: 0.15 | AH18: 0.15 | AK18: 0.15 | AN18: 0.15 | AQ18: 0.15 | AT18: 0.15 | AW18: 0.15 | AZ18: 0.2 | BC18: 0.2 | BF18: 0.2 | BI18: 0.15
C21: PC [PACK] | D21: UPTO 1000 CC[ NCB GT 25%] | G21: 0.35 | J21: 0.3 | M21: 0.35 | O21: 0.25 | P21: 0.35 | S21: 0.35 | U21: 0.3 | V21: 0.3 | X21: 0.3 | Y21: 0.35 | AB21: 0.3 | AE21: 0.25 | AH21: 0.15 | AK21: 0.3 | AN21: 0.3 | AQ21: 0.25 | AT21: 0.3 | AW21: 0.25 | AZ21: 0.3 | BC21: 0.2 | BF21: 0.35 | BI21: 0.35 | BL21: 0.15 | BN21: 0.15
D22: 1000 TO 1500 CC[ NCB GT 25%] | F22: 0.2 | G22: 0.35 | J22: 0.3 | M22: 0.35 | O22: 0.25 | P22: 0.35 | R22: 0.25 | S22: 0.35 | U22: 0.3 | V22: 0.3 | X22: 0.3 | Y22: 0.35 | AA22: 0.25 | AB22: 0.3 | AD22: 0.25 | AE22: 0.325 | AG22: 0 | AH22: 0.24 | AJ22: 0.25 | AK22: 0.3 | AM22: 0.3 | AN22: 0.3 | AQ22: 0.25 | AT22: 0.3 | AW22: 0.25 | AZ22: 0.3 | BC22: 0.25 | BF22: 0.35 | BH22: 0.25 | BI22: 0.35 | BL22: 0.2 | BN22: 0.2
D23: ABOVE 1500 CC[ NCB GT 25%] | F23: 0.2 | G23: 0.35 | J23: 0.35 | L23: 0.1 | M23: 0.35 | O23: 0.25 | P23: 0.35 | R23: 0.2 | S23: 0.35 | U23: 0.3 | V23: 0.3 | X23: 0.3 | Y23: 0.35 | AA23: 0.3 | AB23: 0.35 | AD23: 0.25 | AE23: 0.35 | AG23: 0 | AH23: 0.3 | AJ23: 0.2 | AK23: 0.35 | AM23: 0.3 | AN23: 0.35 | AQ23: 0.3 | AT23: 0.35 | AW23: 0.3 | AZ23: 0.35 | BC23: 0.35 | BF23: 0.35 | BH23: 0.25 | BI23: 0.35 | BL23: 0.25 | BN23: 0.25
C26: PC [SOD] | D26: UPTO 1000 CC[P] [ NCB GT 25%] | G26: 0.15 | J26: 0.15 | M26: 0.24 | P26: 0.24 | S26: 0.15 | V26: 0.1 | Y26: 0.24 | AB26: 0.15 | AE26: 0.15 | AH26: 0.1 | AK26: 0.24 | AN26: 0.15 | AQ26: 0.1 | AT26: 0.15 | AW26: 0.1 | AZ26: 0.2 | BC26: 0.15 | BF26: 0.2 | BI26: 0.15
D27: 1000 TO 1500 CC[P] [ NCB GT 25%] | G27: 0.24 | J27: 0.21 | M27: 0.24 | P27: 0.24 | S27: 0.21 | V27: 0.15 | Y27: 0.24 | AB27: 0.21 | AE27: 0.24 | AH27: 0.15 | AK27: 0.24 | AN27: 0.2 | AQ27: 0.15 | AT27: 0.2 | AW27: 0.15 | AZ27: 0.25 | BC27: 0.2 | BF27: 0.25 | BI27: 0.2
D28: ABOVE 1500 CC[P] [ NCB GT 25%] | G28: 0.25 | J28: 0.25 | M28: 0.25 | P28: 0.25 | S28: 0.25 | V28: 0.2 | Y28: 0.25 | AB28: 0.25 | AE28: 0.25 | AH28: 0.2 | AK28: 0.25 | AN28: 0.25 | AQ28: 0.2 | AT28: 0.25 | AW28: 0.2 | AZ28: 0.3 | BC28: 0.3 | BF28: 0.3 | BI28: 0.25
D30: UPTO 1000 CC[D] [ NCB GT 25%] | G30: 0.15 | J30: 0.15 | M30: 0.15 | P30: 0.15 | S30: 0.15 | V30: 0.1 | Y30: 0.15 | AB30: 0.15 | AE30: 0.15 | AH30: 0.1 | AK30: 0.15 | AN30: 0.15 | AQ30: 0.1 | AT30: 0.15 | AW30: 0.1 | AZ30: 0.15 | BC30: 0.15 | BF30: 0.15 | BI30: 0.15
D31: 1000 TO 1500 CC[D] [ NCB GT 25%] | G31: 0.15 | J31: 0.15 | M31: 0.15 | P31: 0.15 | S31: 0.15 | V31: 0.1 | Y31: 0.15 | AB31: 0.15 | AE31: 0.15 | AH31: 0.1 | AK31: 0.15 | AN31: 0.15 | AQ31: 0.1 | AT31: 0.15 | AW31: 0.1 | AZ31: 0.2 | BC31: 0.15 | BF31: 0.2 | BI31: 0.15
D32: ABOVE 1500 CC[D] [ NCB GT 25%] | G32: 0.2 | J32: 0.2 | M32: 0.2 | P32: 0.2 | S32: 0.2 | V32: 0.15 | Y32: 0.2 | AB32: 0.2 | AE32: 0.2 | AH32: 0.15 | AK32: 0.2 | AN32: 0.2 | AQ32: 0.15 | AT32: 0.2 | AW32: 0.15 | AZ32: 0.25 | BC32: 0.25 | BF32: 0.25 | BI32: 0.2
C35: ** Please note that the above pay-out grid
C36: - For Private Car Package policy pay-out is on OD Cover Premium and Private Car Liability policy Pay-out is on TP/PA Premium
C37: - For Private Car Package & Liability policy CPA should be collected for individual Name Mandatorily
D38: if CPA is not collected for individual name then 1.5% of OD Pay-out will be deducted
C39: - For Private Car Electric Vehicle or LPG/CNG pay-out grid is same as Private Car Petrol grid

Sheet PC DIFF
B2: Private Car Grid for the month of Jun 25
C4: PROD | D4: SUBCLASS | F4: AP/TS | I4: TN | L4: KA | O4: MH/GA | R4: GJ | U4: BH | X4: JH | AA4: OD | AD4: WB | AG4: CG | AJ4: AS/ML/TR/AR/NL | AM4: DL | AP4: PB | AS4: HP | AV4: JK | AY4: UP- East | BB4: UP | BE4: UK | BH4: AN | BK4: RJ | BM4: MP
F6: ACT | G6: PACK | I6: ACT | J6: PACK | L6: ACT | M6: PACK | O6: ACT | P6: PACK | R6: ACT | S6: PACK | U6: ACT | V6: PACK | X6: ACT | Y6: PACK | AA6: ACT | AB6: PACK | AD6: ACT | AE6: PACK | AG6: ACT | AH6: PACK | AJ6: ACT | AK6: PACK | AM6: ACT | AN6: PACK | AP6: ACT | AQ6: PACK | AS6: ACT | AT6: PACK | AV6: ACT | AW6: PACK | AY6: ACT | AZ6: PACK | BB6: ACT | BC6: PACK | BE6: ACT | BF6: PACK | BH6: ACT | BI6: PACK | BK6: ACT | BL6: PACK | BM6: ACT | BN6: PACK
C7: PC [PACK] | D7: UPTO 1000 CC | F7: ='Private car Nov-25 '!F7-'Private car AUG-25 '!F7 -> 0 | G7: ='Private car Nov-25 '!G7-'Private car AUG-25 '!G7 -> 0 | I7: ='Private car Nov-25 '!I7-'Private car AUG-25 '!I7 -> 0 | J7: ='Private car Nov-25 '!J7-'Private car AUG-25 '!J7 -> 0 | L7: ='Private car Nov-25 '!L7-'Private car AUG-25 '!L7 -> 0 | M7: ='Private car Nov-25 '!M7-'Private car AUG-25 '!M7 -> 0 | O7: ='Private car Nov-25 '!O7-'Private car AUG-25 '!O7 -> 0 | P7: ='Private car Nov-25 '!P7-'Private car AUG-25 '!P7 -> 0 | R7: ='Private car Nov-25 '!R7-'Private car AUG-25 '!R7 -> 0 | S7: ='Private car Nov-25 '!S7-'Private car AUG-25 '!S7 -> 0 | U7: ='Private car Nov-25 '!U7-'Private car AUG-25 '!U7 -> 0 | V7: ='Private car Nov-25 '!V7-'Private car AUG-25 '!V7 -> 0 | X7: ='Private car Nov-25 '!X7-'Private car AUG-25 '!X7 -> 0 | Y7: ='Private car Nov-25 '!Y7-'Private car AUG-25 '!Y7 -> 0 | AA7: ='Private car Nov-25 '!AA7-'Private car AUG-25 '!AA7 -> 0 | AB7: ='Private car Nov-25 '!AB7-'Private car AUG-25 '!AB7 -> 0 | AD7: ='Private car Nov-25 '!AD7-'Private car AUG-25 '!AD7 -> 0 | AE7: ='Private car Nov-25 '!AE7-'Private car AUG-25 '!AE7 -> 0 | AG7: ='Private car Nov-25 '!AG7-'Private car AUG-25 '!AG7 -> 0 | AH7: ='Private car Nov-25 '!AH7-'Private car AUG-25 '!AH7 -> 0 | AJ7: ='Private car Nov-25 '!AJ7-'Private car AUG-25 '!AJ7 -> 0 | AK7: ='Private car Nov-25 '!AK7-'Private car AUG-25 '!AK7 -> 0 | AM7: ='Private car Nov-25 '!AM7-'Private car AUG-25 '!AM7 -> 0 | AN7: ='Private car Nov-25 '!AN7-'Private car AUG-25 '!AN7 -> 0 | AP7: ='Private car Nov-25 '!AP7-'Private car AUG-25 '!AP7 -> 0 | AQ7: ='Private car Nov-25 '!AQ7-'Private car AUG-25 '!AQ7 -> 0 | AS7: ='Private car Nov-25 '!AS7-'Private car AUG-25 '!AS7 -> 0 | AT7: ='Private car Nov-25 '!AT7-'Private car AUG-25 '!AT7 -> 0 | AV7: ='Private car Nov-25 '!AV7-'Private car AUG-25 '!AV7 -> 0 | AW7: ='Private car Nov-25 '!AW7-'Private car AUG-25 '!AW7 -> 0 | AY7: ='Private car Nov-25 '!AY7-'Private car AUG-25 '!AY7 -> 0 | AZ7: ='Private car Nov-25 '!AZ7-'Private car AUG-25 '!AZ7 -> 0 | BB7: ='Private car Nov-25 '!BB7-'Private car AUG-25 '!BB7 -> 0 | BC7: ='Private car Nov-25 '!BC7-'Private car AUG-25 '!BC7 -> 0 | BE7: ='Private car Nov-25 '!BE7-'Private car AUG-25 '!BE7 -> 0 | BF7: ='Private car Nov-25 '!BF7-'Private car AUG-25 '!BF7 -> 0 | BH7: ='Private car Nov-25 '!BH7-'Private car AUG-25 '!BH7 -> 0 | BI7: ='Private car Nov-25 '!BI7-'Private car AUG-25 '!BI7 -> 0 | BK7: ='Private car Nov-25 '!BK7-'Private car AUG-25 '!BK7 -> 0 | BL7: ='Private car Nov-25 '!BL7-'Private car AUG-25 '!BL7 -> 0 | BM7: ='Private car Nov-25 '!BM7-'Private car AUG-25 '!BM7 -> 0 | BN7: ='Private car Nov-25 '!BN7-'Private car AUG-25 '!BN7 -> 0
D8: 1000 TO 1500 CC | F8: ='Private car Nov-25 '!F8-'Private car AUG-25 '!F8 -> 0 | G8: ='Private car Nov-25 '!G8-'Private car AUG-25 '!G8 -> 0 | I8: ='Private car Nov-25 '!I8-'Private car AUG-25 '!I8 -> 0 | J8: ='Private car Nov-25 '!J8-'Private car AUG-25 '!J8 -> 0 | L8: ='Private car Nov-25 '!L8-'Private car AUG-25 '!L8 -> 0 | M8: ='Private car Nov-25 '!M8-'Private car AUG-25 '!M8 -> 0 | O8: ='Private car Nov-25 '!O8-'Private car AUG-25 '!O8 -> 0 | P8: ='Private car Nov-25 '!P8-'Private car AUG-25 '!P8 -> 0 | R8: ='Private car Nov-25 '!R8-'Private car AUG-25 '!R8 -> 0 | S8: ='Private car Nov-25 '!S8-'Private car AUG-25 '!S8 -> 0 | U8: ='Private car Nov-25 '!U8-'Private car AUG-25 '!U8 -> 0 | V8: ='Private car Nov-25 '!V8-'Private car AUG-25 '!V8 -> 0 | X8: ='Private car Nov-25 '!X8-'Private car AUG-25 '!X8 -> 0 | Y8: ='Private car Nov-25 '!Y8-'Private car AUG-25 '!Y8 -> 0 | AA8: ='Private car Nov-25 '!AA8-'Private car AUG-25 '!AA8 -> 0 | AB8: ='Private car Nov-25 '!AB8-'Private car AUG-25 '!AB8 -> 0 | AD8: ='Private car Nov-25 '!AD8-'Private car AUG-25 '!AD8 -> 0 | AE8: ='Private car Nov-25 '!AE8-'Private car AUG-25 '!AE8 -> 0 | AG8: ='Private car Nov-25 '!AG8-'Private car AUG-25 '!AG8 -> 0 | AH8: ='Private car Nov-25 '!AH8-'Private car AUG-25 '!AH8 -> 0 | AJ8: ='Private car Nov-25 '!AJ8-'Private car AUG-25 '!AJ8 -> 0 | AK8: ='Private car Nov-25 '!AK8-'Private car AUG-25 '!AK8 -> 0 | AM8: ='Private car Nov-25 '!AM8-'Private car AUG-25 '!AM8 -> 0 | AN8: ='Private car Nov-25 '!AN8-'Private car AUG-25 '!AN8 -> 0 | AP8: ='Private car Nov-25 '!AP8-'Private car AUG-25 '!AP8 -> 0 | AQ8: ='Private car Nov-25 '!AQ8-'Private car AUG-25 '!AQ8 -> 0 | AS8: ='Private car Nov-25 '!AS8-'Private car AUG-25 '!AS8 -> 0 | AT8: ='Private car Nov-25 '!AT8-'Private car AUG-25 '!AT8 -> 0 | AV8: ='Private car Nov-25 '!AV8-'Private car AUG-25 '!AV8 -> 0 | AW8: ='Private car Nov-25 '!AW8-'Private car AUG-25 '!AW8 -> 0 | AY8: ='Private car Nov-25 '!AY8-'Private car AUG-25 '!AY8 -> 0 | AZ8: ='Private car Nov-25 '!AZ8-'Private car AUG-25 '!AZ8 -> 0 | BB8: ='Private car Nov-25 '!BB8-'Private car AUG-25 '!BB8 -> 0 | BC8: ='Private car Nov-25 '!BC8-'Private car AUG-25 '!BC8 -> 0 | BE8: ='Private car Nov-25 '!BE8-'Private car AUG-25 '!BE8 -> 0 | BF8: ='Private car Nov-25 '!BF8-'Private car AUG-25 '!BF8 -> 0 | BH8: ='Private car Nov-25 '!BH8-'Private car AUG-25 '!BH8 -> 0 | BI8: ='Private car Nov-25 '!BI8-'Private car AUG-25 '!BI8 -> 0 | BK8: ='Private car Nov-25 '!BK8-'Private car AUG-25 '!BK8 -> 0 | BL8: ='Private car Nov-25 '!BL8-'Private car AUG-25 '!BL8 -> 0 | BM8: ='Private car Nov-25 '!BM8-'Private car AUG-25 '!BM8 -> 0 | BN8: ='Private car Nov-25 '!BN8-'Private car AUG-25 '!BN8 -> 0
D9: ABOVE 1500 CC | F9: ='Private car Nov-25 '!F9-'Private car AUG-25 '!F9 -> 0 | G9: ='Private car Nov-25 '!G9-'Private car AUG-25 '!G9 -> 0 | I9: ='Private car Nov-25 '!I9-'Private car AUG-25 '!I9 -> 0 | J9: ='Private car Nov-25 '!J9-'Private car AUG-25 '!J9 -> 0 | L9: ='Private car Nov-25 '!L9-'Private car AUG-25 '!L9 -> 0 | M9: ='Private car Nov-25 '!M9-'Private car AUG-25 '!M9 -> 0 | O9: ='Private car Nov-25 '!O9-'Private car AUG-25 '!O9 -> 0 | P9: ='Private car Nov-25 '!P9-'Private car AUG-25 '!P9 -> 0 | R9: ='Private car Nov-25 '!R9-'Private car AUG-25 '!R9 -> 0 | S9: ='Private car Nov-25 '!S9-'Private car AUG-25 '!S9 -> 0 | U9: ='Private car Nov-25 '!U9-'Private car AUG-25 '!U9 -> 0 | V9: ='Private car Nov-25 '!V9-'Private car AUG-25 '!V9 -> 0 | X9: ='Private car Nov-25 '!X9-'Private car AUG-25 '!X9 -> 0 | Y9: ='Private car Nov-25 '!Y9-'Private car AUG-25 '!Y9 -> 0 | AA9: ='Private car Nov-25 '!AA9-'Private car AUG-25 '!AA9 -> 0 | AB9: ='Private car Nov-25 '!AB9-'Private car AUG-25 '!AB9 -> 0 | AD9: ='Private car Nov-25 '!AD9-'Private car AUG-25 '!AD9 -> 0 | AE9: ='Private car Nov-25 '!AE9-'Private car AUG-25 '!AE9 -> 0 | AG9: ='Private car Nov-25 '!AG9-'Private car AUG-25 '!AG9 -> 0 | AH9: ='Private car Nov-25 '!AH9-'Private car AUG-25 '!AH9 -> 0 | AJ9: ='Private car Nov-25 '!AJ9-'Private car AUG-25 '!AJ9 -> 0 | AK9: ='Private car Nov-25 '!AK9-'Private car AUG-25 '!AK9 -> 0 | AM9: ='Private car Nov-25 '!AM9-'Private car AUG-25 '!AM9 -> 0 | AN9: ='Private car Nov-25 '!AN9-'Private car AUG-25 '!AN9 -> 0 | AP9: ='Private car Nov-25 '!AP9-'Private car AUG-25 '!AP9 -> 0 | AQ9: ='Private car Nov-25 '!AQ9-'Private car AUG-25 '!AQ9 -> 0 | AS9: ='Private car Nov-25 '!AS9-'Private car AUG-25 '!AS9 -> 0 | AT9: ='Private car Nov-25 '!AT9-'Private car AUG-25 '!AT9 -> 0 | AV9: ='Private car Nov-25 '!AV9-'Private car AUG-25 '!AV9 -> 0 | AW9: ='Private car Nov-25 '!AW9-'Private car AUG-25 '!AW9 -> 0 | AY9: ='Private car Nov-25 '!AY9-'Private car AUG-25 '!AY9 -> 0 | AZ9: ='Private car Nov-25 '!AZ9-'Private car AUG-25 '!AZ9 -> 0 | BB9: ='Private car Nov-25 '!BB9-'Private car AUG-25 '!BB9 -> 0 | BC9: ='Private car Nov-25 '!BC9-'Private car AUG-25 '!BC9 -> 0 | BE9: ='Private car Nov-25 '!BE9-'Private car AUG-25 '!BE9 -> 0 | BF9: ='Private car Nov-25 '!BF9-'Private car AUG-25 '!BF9 -> 0 | BH9: ='Private car Nov-25 '!BH9-'Private car AUG-25 '!BH9 -> 0 | BI9: ='Private car Nov-25 '!BI9-'Private car AUG-25 '!BI9 -> 0 | BK9: ='Private car Nov-25 '!BK9-'Private car AUG-25 '!BK9 -> 0 | BL9: ='Private car Nov-25 '!BL9-'Private car AUG-25 '!BL9 -> 0 | BM9: ='Private car Nov-25 '!BM9-'Private car AUG-25 '!BM9 -> 0 | BN9: ='Private car Nov-25 '!BN9-'Private car AUG-25 '!BN9 -> 0
C12: PC [SOD] | D12: UPTO 1000 CC[P] | F12: ='Private car Nov-25 '!F12-'Private car AUG-25 '!F12 -> 0 | G12: ='Private car Nov-25 '!G12-'Private car AUG-25 '!G12 -> 0 | I12: ='Private car Nov-25 '!I12-'Private car AUG-25 '!I12 -> 0 | J12: ='Private car Nov-25 '!J12-'Private car AUG-25 '!J12 -> 0 | L12: ='Private car Nov-25 '!L12-'Private car AUG-25 '!L12 -> 0 | M12: ='Private car Nov-25 '!M12-'Private car AUG-25 '!M12 -> 0 | O12: ='Private car Nov-25 '!O12-'Private car AUG-25 '!O12 -> 0 | P12: ='Private car Nov-25 '!P12-'Private car AUG-25 '!P12 -> 0 | R12: ='Private car Nov-25 '!R12-'Private car AUG-25 '!R12 -> 0 | S12: ='Private car Nov-25 '!S12-'Private car AUG-25 '!S12 -> 0 | U12: ='Private car Nov-25 '!U12-'Private car AUG-25 '!U12 -> 0 | V12: ='Private car Nov-25 '!V12-'Private car AUG-25 '!V12 -> 0 | X12: ='Private car Nov-25 '!X12-'Private car AUG-25 '!X12 -> 0 | Y12: ='Private car Nov-25 '!Y12-'Private car AUG-25 '!Y12 -> 0 | AA12: ='Private car Nov-25 '!AA12-'Private car AUG-25 '!AA12 -> 0 | AB12: ='Private car Nov-25 '!AB12-'Private car AUG-25 '!AB12 -> 0 | AD12: ='Private car Nov-25 '!AD12-'Private car AUG-25 '!AD12 -> 0 | AE12: ='Private car Nov-25 '!AE12-'Private car AUG-25 '!AE12 -> 0 | AG12: ='Private car Nov-25 '!AG12-'Private car AUG-25 '!AG12 -> 0 | AH12: ='Private car Nov-25 '!AH12-'Private car AUG-25 '!AH12 -> 0 | AJ12: ='Private car Nov-25 '!AJ12-'Private car AUG-25 '!AJ12 -> 0 | AK12: ='Private car Nov-25 '!AK12-'Private car AUG-25 '!AK12 -> 0 | AM12: ='Private car Nov-25 '!AM12-'Private car AUG-25 '!AM12 -> 0 | AN12: ='Private car Nov-25 '!AN12-'Private car AUG-25 '!AN12 -> 0 | AP12: ='Private car Nov-25 '!AP12-'Private car AUG-25 '!AP12 -> 0 | AQ12: ='Private car Nov-25 '!AQ12-'Private car AUG-25 '!AQ12 -> 0 | AS12: ='Private car Nov-25 '!AS12-'Private car AUG-25 '!AS12 -> 0 | AT12: ='Private car Nov-25 '!AT12-'Private car AUG-25 '!AT12 -> 0 | AV12: ='Private car Nov-25 '!AV12-'Private car AUG-25 '!AV12 -> 0 | AW12: ='Private car Nov-25 '!AW12-'Private car AUG-25 '!AW12 -> 0 | AY12: ='Private car Nov-25 '!AY12-'Private car AUG-25 '!AY12 -> 0 | AZ12: ='Private car Nov-25 '!AZ12-'Private car AUG-25 '!AZ12 -> 0 | BB12: ='Private car Nov-25 '!BB12-'Private car AUG-25 '!BB12 -> 0 | BC12: ='Private car Nov-25 '!BC12-'Private car AUG-25 '!BC12 -> 0 | BE12: ='Private car Nov-25 '!BE12-'Private car AUG-25 '!BE12 -> 0 | BF12: ='Private car Nov-25 '!BF12-'Private car AUG-25 '!BF12 -> 0 | BH12: ='Private car Nov-25 '!BH12-'Private car AUG-25 '!BH12 -> 0 | BI12: ='Private car Nov-25 '!BI12-'Private car AUG-25 '!BI12 -> 0 | BK12: ='Private car Nov-25 '!BK12-'Private car AUG-25 '!BK12 -> 0 | BL12: ='Private car Nov-25 '!BL12-'Private car AUG-25 '!BL12 -> 0 | BM12: ='Private car Nov-25 '!BM12-'Private car AUG-25 '!BM12 -> 0 | BN12: ='Private car Nov-25 '!BN12-'Private car AUG-25 '!BN12 -> 0
D13: 1000 TO 1500 CC[P] | F13: ='Private car Nov-25 '!F13-'Private car AUG-25 '!F13 -> 0 | G13: ='Private car Nov-25 '!G13-'Private car AUG-25 '!G13 -> 0 | I13: ='Private car Nov-25 '!I13-'Private car AUG-25 '!I13 -> 0 | J13: ='Private car Nov-25 '!J13-'Private car AUG-25 '!J13 -> 0 | L13: ='Private car Nov-25 '!L13-'Private car AUG-25 '!L13 -> 0 | M13: ='Private car Nov-25 '!M13-'Private car AUG-25 '!M13 -> 0 | O13: ='Private car Nov-25 '!O13-'Private car AUG-25 '!O13 -> 0 | P13: ='Private car Nov-25 '!P13-'Private car AUG-25 '!P13 -> 0 | R13: ='Private car Nov-25 '!R13-'Private car AUG-25 '!R13 -> 0 | S13: ='Private car Nov-25 '!S13-'Private car AUG-25 '!S13 -> 0 | U13: ='Private car Nov-25 '!U13-'Private car AUG-25 '!U13 -> 0 | V13: ='Private car Nov-25 '!V13-'Private car AUG-25 '!V13 -> 0 | X13: ='Private car Nov-25 '!X13-'Private car AUG-25 '!X13 -> 0 | Y13: ='Private car Nov-25 '!Y13-'Private car AUG-25 '!Y13 -> 0 | AA13: ='Private car Nov-25 '!AA13-'Private car AUG-25 '!AA13 -> 0 | AB13: ='Private car Nov-25 '!AB13-'Private car AUG-25 '!AB13 -> 0 | AD13: ='Private car Nov-25 '!AD13-'Private car AUG-25 '!AD13 -> 0 | AE13: ='Private car Nov-25 '!AE13-'Private car AUG-25 '!AE13 -> 0 | AG13: ='Private car Nov-25 '!AG13-'Private car AUG-25 '!AG13 -> 0 | AH13: ='Private car Nov-25 '!AH13-'Private car AUG-25 '!AH13 -> 0 | AJ13: ='Private car Nov-25 '!AJ13-'Private car AUG-25 '!AJ13 -> 0 | AK13: ='Private car Nov-25 '!AK13-'Private car AUG-25 '!AK13 -> 0 | AM13: ='Private car Nov-25 '!AM13-'Private car AUG-25 '!AM13 -> 0 | AN13: ='Private car Nov-25 '!AN13-'Private car AUG-25 '!AN13 -> 0 | AP13: ='Private car Nov-25 '!AP13-'Private car AUG-25 '!AP13 -> 0 | AQ13: ='Private car Nov-25 '!AQ13-'Private car AUG-25 '!AQ13 -> 0 | AS13: ='Private car Nov-25 '!AS13-'Private car AUG-25 '!AS13 -> 0 | AT13: ='Private car Nov-25 '!AT13-'Private car AUG-25 '!AT13 -> 0 | AV13: ='Private car Nov-25 '!AV13-'Private car AUG-25 '!AV13 -> 0 | AW13: ='Private car Nov-25 '!AW13-'Private car AUG-25 '!AW13 -> 0 | AY13: ='Private car Nov-25 '!AY13-'Private car AUG-25 '!AY13 -> 0 | AZ13: ='Private car Nov-25 '!AZ13-'Private car AUG-25 '!AZ13 -> 0 | BB13: ='Private car Nov-25 '!BB13-'Private car AUG-25 '!BB13 -> 0 | BC13: ='Private car Nov-25 '!BC13-'Private car AUG-25 '!BC13 -> 0 | BE13: ='Private car Nov-25 '!BE13-'Private car AUG-25 '!BE13 -> 0 | BF13: ='Private car Nov-25 '!BF13-'Private car AUG-25 '!BF13 -> 0 | BH13: ='Private car Nov-25 '!BH13-'Private car AUG-25 '!BH13 -> 0 | BI13: ='Private car Nov-25 '!BI13-'Private car AUG-25 '!BI13 -> 0 | BK13: ='Private car Nov-25 '!BK13-'Private car AUG-25 '!BK13 -> 0 | BL13: ='Private car Nov-25 '!BL13-'Private car AUG-25 '!BL13 -> 0 | BM13: ='Private car Nov-25 '!BM13-'Private car AUG-25 '!BM13 -> 0 | BN13: ='Private car Nov-25 '!BN13-'Private car AUG-25 '!BN13 -> 0
D14: ABOVE 1500 CC[P] | F14: ='Private car Nov-25 '!F14-'Private car AUG-25 '!F14 -> 0 | G14: ='Private car Nov-25 '!G14-'Private car AUG-25 '!G14 -> 0 | I14: ='Private car Nov-25 '!I14-'Private car AUG-25 '!I14 -> 0 | J14: ='Private car Nov-25 '!J14-'Private car AUG-25 '!J14 -> 0 | L14: ='Private car Nov-25 '!L14-'Private car AUG-25 '!L14 -> 0 | M14: ='Private car Nov-25 '!M14-'Private car AUG-25 '!M14 -> 0 | O14: ='Private car Nov-25 '!O14-'Private car AUG-25 '!O14 -> 0 | P14: ='Private car Nov-25 '!P14-'Private car AUG-25 '!P14 -> 0 | R14: ='Private car Nov-25 '!R14-'Private car AUG-25 '!R14 -> 0 | S14: ='Private car Nov-25 '!S14-'Private car AUG-25 '!S14 -> 0 | U14: ='Private car Nov-25 '!U14-'Private car AUG-25 '!U14 -> 0 | V14: ='Private car Nov-25 '!V14-'Private car AUG-25 '!V14 -> 0 | X14: ='Private car Nov-25 '!X14-'Private car AUG-25 '!X14 -> 0 | Y14: ='Private car Nov-25 '!Y14-'Private car AUG-25 '!Y14 -> 0 | AA14: ='Private car Nov-25 '!AA14-'Private car AUG-25 '!AA14 -> 0 | AB14: ='Private car Nov-25 '!AB14-'Private car AUG-25 '!AB14 -> 0 | AD14: ='Private car Nov-25 '!AD14-'Private car AUG-25 '!AD14 -> 0 | AE14: ='Private car Nov-25 '!AE14-'Private car AUG-25 '!AE14 -> 0 | AG14: ='Private car Nov-25 '!AG14-'Private car AUG-25 '!AG14 -> 0 | AH14: ='Private car Nov-25 '!AH14-'Private car AUG-25 '!AH14 -> 0 | AJ14: ='Private car Nov-25 '!AJ14-'Private car AUG-25 '!AJ14 -> 0 | AK14: ='Private car Nov-25 '!AK14-'Private car AUG-25 '!AK14 -> 0 | AM14: ='Private car Nov-25 '!AM14-'Private car AUG-25 '!AM14 -> 0 | AN14: ='Private car Nov-25 '!AN14-'Private car AUG-25 '!AN14 -> 0 | AP14: ='Private car Nov-25 '!AP14-'Private car AUG-25 '!AP14 -> 0 | AQ14: ='Private car Nov-25 '!AQ14-'Private car AUG-25 '!AQ14 -> 0 | AS14: ='Private car Nov-25 '!AS14-'Private car AUG-25 '!AS14 -> 0 | AT14: ='Private car Nov-25 '!AT14-'Private car AUG-25 '!AT14 -> 0 | AV14: ='Private car Nov-25 '!AV14-'Private car AUG-25 '!AV14 -> 0 | AW14: ='Private car Nov-25 '!AW14-'Private car AUG-25 '!AW14 -> 0 | AY14: ='Private car Nov-25 '!AY14-'Private car AUG-25 '!AY14 -> 0 | AZ14: ='Private car Nov-25 '!AZ14-'Private car AUG-25 '!AZ14 -> 0 | BB14: ='Private car Nov-25 '!BB14-'Private car AUG-25 '!BB14 -> 0 | BC14: ='Private car Nov-25 '!BC14-'Private car AUG-25 '!BC14 -> 0 | BE14: ='Private car Nov-25 '!BE14-'Private car AUG-25 '!BE14 -> 0 | BF14: ='Private car Nov-25 '!BF14-'Private car AUG-25 '!BF14 -> 0 | BH14: ='Private car Nov-25 '!BH14-'Private car AUG-25 '!BH14 -> 0 | BI14: ='Private car Nov-25 '!BI14-'Private car AUG-25 '!BI14 -> 0 | BK14: ='Private car Nov-25 '!BK14-'Private car AUG-25 '!BK14 -> 0 | BL14: ='Private car Nov-25 '!BL14-'Private car AUG-25 '!BL14 -> 0 | BM14: ='Private car Nov-25 '!BM14-'Private car AUG-25 '!BM14 -> 0 | BN14: ='Private car Nov-25 '!BN14-'Private car AUG-25 '!BN14 -> 0
D16: UPTO 1000 CC[D] | F16: ='Private car Nov-25 '!F16-'Private car AUG-25 '!F16 -> 0 | G16: ='Private car Nov-25 '!G16-'Private car AUG-25 '!G16 -> 0 | I16: ='Private car Nov-25 '!I16-'Private car AUG-25 '!I16 -> 0 | J16: ='Private car Nov-25 '!J16-'Private car AUG-25 '!J16 -> 0 | L16: ='Private car Nov-25 '!L16-'Private car AUG-25 '!L16 -> 0 | M16: ='Private car Nov-25 '!M16-'Private car AUG-25 '!M16 -> 0 | O16: ='Private car Nov-25 '!O16-'Private car AUG-25 '!O16 -> 0 | P16: ='Private car Nov-25 '!P16-'Private car AUG-25 '!P16 -> 0 | R16: ='Private car Nov-25 '!R16-'Private car AUG-25 '!R16 -> 0 | S16: ='Private car Nov-25 '!S16-'Private car AUG-25 '!S16 -> 0 | U16: ='Private car Nov-25 '!U16-'Private car AUG-25 '!U16 -> 0 | V16: ='Private car Nov-25 '!V16-'Private car AUG-25 '!V16 -> 0 | X16: ='Private car Nov-25 '!X16-'Private car AUG-25 '!X16 -> 0 | Y16: ='Private car Nov-25 '!Y16-'Private car AUG-25 '!Y16 -> 0 | AA16: ='Private car Nov-25 '!AA16-'Private car AUG-25 '!AA16 -> 0 | AB16: ='Private car Nov-25 '!AB16-'Private car AUG-25 '!AB16 -> 0 | AD16: ='Private car Nov-25 '!AD16-'Private car AUG-25 '!AD16 -> 0 | AE16: ='Private car Nov-25 '!AE16-'Private car AUG-25 '!AE16 -> 0 | AG16: ='Private car Nov-25 '!AG16-'Private car AUG-25 '!AG16 -> 0 | AH16: ='Private car Nov-25 '!AH16-'Private car AUG-25 '!AH16 -> 0 | AJ16: ='Private car Nov-25 '!AJ16-'Private car AUG-25 '!AJ16 -> 0 | AK16: ='Private car Nov-25 '!AK16-'Private car AUG-25 '!AK16 -> 0 | AM16: ='Private car Nov-25 '!AM16-'Private car AUG-25 '!AM16 -> 0 | AN16: ='Private car Nov-25 '!AN16-'Private car AUG-25 '!AN16 -> 0 | AP16: ='Private car Nov-25 '!AP16-'Private car AUG-25 '!AP16 -> 0 | AQ16: ='Private car Nov-25 '!AQ16-'Private car AUG-25 '!AQ16 -> 0 | AS16: ='Private car Nov-25 '!AS16-'Private car AUG-25 '!AS16 -> 0 | AT16: ='Private car Nov-25 '!AT16-'Private car AUG-25 '!AT16 -> 0 | AV16: ='Private car Nov-25 '!AV16-'Private car AUG-25 '!AV16 -> 0 | AW16: ='Private car Nov-25 '!AW16-'Private car AUG-25 '!AW16 -> 0 | AY16: ='Private car Nov-25 '!AY16-'Private car AUG-25 '!AY16 -> 0 | AZ16: ='Private car Nov-25 '!AZ16-'Private car AUG-25 '!AZ16 -> 0 | BB16: ='Private car Nov-25 '!BB16-'Private car AUG-25 '!BB16 -> 0 | BC16: ='Private car Nov-25 '!BC16-'Private car AUG-25 '!BC16 -> 0 | BE16: ='Private car Nov-25 '!BE16-'Private car AUG-25 '!BE16 -> 0 | BF16: ='Private car Nov-25 '!BF16-'Private car AUG-25 '!BF16 -> 0 | BH16: ='Private car Nov-25 '!BH16-'Private car AUG-25 '!BH16 -> 0 | BI16: ='Private car Nov-25 '!BI16-'Private car AUG-25 '!BI16 -> 0 | BK16: ='Private car Nov-25 '!BK16-'Private car AUG-25 '!BK16 -> 0 | BL16: ='Private car Nov-25 '!BL16-'Private car AUG-25 '!BL16 -> 0 | BM16: ='Private car Nov-25 '!BM16-'Private car AUG-25 '!BM16 -> 0 | BN16: ='Private car Nov-25 '!BN16-'Private car AUG-25 '!BN16 -> 0
D17: 1000 TO 1500 CC[D] | F17: ='Private car Nov-25 '!F17-'Private car AUG-25 '!F17 -> 0 | G17: ='Private car Nov-25 '!G17-'Private car AUG-25 '!G17 -> 0 | I17: ='Private car Nov-25 '!I17-'Private car AUG-25 '!I17 -> 0 | J17: ='Private car Nov-25 '!J17-'Private car AUG-25 '!J17 -> 0 | L17: ='Private car Nov-25 '!L17-'Private car AUG-25 '!L17 -> 0 | M17: ='Private car Nov-25 '!M17-'Private car AUG-25 '!M17 -> 0 | O17: ='Private car Nov-25 '!O17-'Private car AUG-25 '!O17 -> 0 | P17: ='Private car Nov-25 '!P17-'Private car AUG-25 '!P17 -> 0 | R17: ='Private car Nov-25 '!R17-'Private car AUG-25 '!R17 -> 0 | S17: ='Private car Nov-25 '!S17-'Private car AUG-25 '!S17 -> 0 | U17: ='Private car Nov-25 '!U17-'Private car AUG-25 '!U17 -> 0 | V17: ='Private car Nov-25 '!V17-'Private car AUG-25 '!V17 -> 0 | X17: ='Private car Nov-25 '!X17-'Private car AUG-25 '!X17 -> 0 | Y17: ='Private car Nov-25 '!Y17-'Private car AUG-25 '!Y17 -> 0 | AA17: ='Private car Nov-25 '!AA17-'Private car AUG-25 '!AA17 -> 0 | AB17: ='Private car Nov-25 '!AB17-'Private car AUG-25 '!AB17 -> 0 | AD17: ='Private car Nov-25 '!AD17-'Private car AUG-25 '!AD17 -> 0 | AE17: ='Private car Nov-25 '!AE17-'Private car AUG-25 '!AE17 -> 0 | AG17: ='Private car Nov-25 '!AG17-'Private car AUG-25 '!AG17 -> 0 | AH17: ='Private car Nov-25 '!AH17-'Private car AUG-25 '!AH17 -> 0 | AJ17: ='Private car Nov-25 '!AJ17-'Private car AUG-25 '!AJ17 -> 0 | AK17: ='Private car Nov-25 '!AK17-'Private car AUG-25 '!AK17 -> 0 | AM17: ='Private car Nov-25 '!AM17-'Private car AUG-25 '!AM17 -> 0 | AN17: ='Private car Nov-25 '!AN17-'Private car AUG-25 '!AN17 -> 0 | AP17: ='Private car Nov-25 '!AP17-'Private car AUG-25 '!AP17 -> 0 | AQ17: ='Private car Nov-25 '!AQ17-'Private car AUG-25 '!AQ17 -> 0 | AS17: ='Private car Nov-25 '!AS17-'Private car AUG-25 '!AS17 -> 0 | AT17: ='Private car Nov-25 '!AT17-'Private car AUG-25 '!AT17 -> 0 | AV17: ='Private car Nov-25 '!AV17-'Private car AUG-25 '!AV17 -> 0 | AW17: ='Private car Nov-25 '!AW17-'Private car AUG-25 '!AW17 -> 0 | AY17: ='Private car Nov-25 '!AY17-'Private car AUG-25 '!AY17 -> 0 | AZ17: ='Private car Nov-25 '!AZ17-'Private car AUG-25 '!AZ17 -> 0 | BB17: ='Private car Nov-25 '!BB17-'Private car AUG-25 '!BB17 -> 0 | BC17: ='Private car Nov-25 '!BC17-'Private car AUG-25 '!BC17 -> 0 | BE17: ='Private car Nov-25 '!BE17-'Private car AUG-25 '!BE17 -> 0 | BF17: ='Private car Nov-25 '!BF17-'Private car AUG-25 '!BF17 -> 0 | BH17: ='Private car Nov-25 '!BH17-'Private car AUG-25 '!BH17 -> 0 | BI17: ='Private car Nov-25 '!BI17-'Private car AUG-25 '!BI17 -> 0 | BK17: ='Private car Nov-25 '!BK17-'Private car AUG-25 '!BK17 -> 0 | BL17: ='Private car Nov-25 '!BL17-'Private car AUG-25 '!BL17 -> 0 | BM17: ='Private car Nov-25 '!BM17-'Private car AUG-25 '!BM17 -> 0 | BN17: ='Private car Nov-25 '!BN17-'Private car AUG-25 '!BN17 -> 0
D18: ABOVE 1500 CC[D] | F18: ='Private car Nov-25 '!F18-'Private car AUG-25 '!F18 -> 0 | G18: ='Private car Nov-25 '!G18-'Private car AUG-25 '!G18 -> 0 | I18: ='Private car Nov-25 '!I18-'Private car AUG-25 '!I18 -> 0 | J18: ='Private car Nov-25 '!J18-'Private car AUG-25 '!J18 -> 0 | L18: ='Private car Nov-25 '!L18-'Private car AUG-25 '!L18 -> 0 | M18: ='Private car Nov-25 '!M18-'Private car AUG-25 '!M18 -> 0 | O18: ='Private car Nov-25 '!O18-'Private car AUG-25 '!O18 -> 0 | P18: ='Private car Nov-25 '!P18-'Private car AUG-25 '!P18 -> 0 | R18: ='Private car Nov-25 '!R18-'Private car AUG-25 '!R18 -> 0 | S18: ='Private car Nov-25 '!S18-'Private car AUG-25 '!S18 -> 0 | U18: ='Private car Nov-25 '!U18-'Private car AUG-25 '!U18 -> 0 | V18: ='Private car Nov-25 '!V18-'Private car AUG-25 '!V18 -> 0 | X18: ='Private car Nov-25 '!X18-'Private car AUG-25 '!X18 -> 0 | Y18: ='Private car Nov-25 '!Y18-'Private car AUG-25 '!Y18 -> 0 | AA18: ='Private car Nov-25 '!AA18-'Private car AUG-25 '!AA18 -> 0 | AB18: ='Private car Nov-25 '!AB18-'Private car AUG-25 '!AB18 -> 0 | AD18: ='Private car Nov-25 '!AD18-'Private car AUG-25 '!AD18 -> 0 | AE18: ='Private car Nov-25 '!AE18-'Private car AUG-25 '!AE18 -> 0 | AG18: ='Private car Nov-25 '!AG18-'Private car AUG-25 '!AG18 -> 0 | AH18: ='Private car Nov-25 '!AH18-'Private car AUG-25 '!AH18 -> 0 | AJ18: ='Private car Nov-25 '!AJ18-'Private car AUG-25 '!AJ18 -> 0 | AK18: ='Private car Nov-25 '!AK18-'Private car AUG-25 '!AK18 -> 0 | AM18: ='Private car Nov-25 '!AM18-'Private car AUG-25 '!AM18 -> 0 | AN18: ='Private car Nov-25 '!AN18-'Private car AUG-25 '!AN18 -> 0 | AP18: ='Private car Nov-25 '!AP18-'Private car AUG-25 '!AP18 -> 0 | AQ18: ='Private car Nov-25 '!AQ18-'Private car AUG-25 '!AQ18 -> 0 | AS18: ='Private car Nov-25 '!AS18-'Private car AUG-25 '!AS18 -> 0 | AT18: ='Private car Nov-25 '!AT18-'Private car AUG-25 '!AT18 -> 0 | AV18: ='Private car Nov-25 '!AV18-'Private car AUG-25 '!AV18 -> 0 | AW18: ='Private car Nov-25 '!AW18-'Private car AUG-25 '!AW18 -> 0 | AY18: ='Private car Nov-25 '!AY18-'Private car AUG-25 '!AY18 -> 0 | AZ18: ='Private car Nov-25 '!AZ18-'Private car AUG-25 '!AZ18 -> 0 | BB18: ='Private car Nov-25 '!BB18-'Private car AUG-25 '!BB18 -> 0 | BC18: ='Private car Nov-25 '!BC18-'Private car AUG-25 '!BC18 -> 0 | BE18: ='Private car Nov-25 '!BE18-'Private car AUG-25 '!BE18 -> 0 | BF18: ='Private car Nov-25 '!BF18-'Private car AUG-25 '!BF18 -> 0 | BH18: ='Private car Nov-25 '!BH18-'Private car AUG-25 '!BH18 -> 0 | BI18: ='Private car Nov-25 '!BI18-'Private car AUG-25 '!BI18 -> 0 | BK18: ='Private car Nov-25 '!BK18-'Private car AUG-25 '!BK18 -> 0 | BL18: ='Private car Nov-25 '!BL18-'Private car AUG-25 '!BL18 -> 0 | BM18: ='Private car Nov-25 '!BM18-'Private car AUG-25 '!BM18 -> 0 | BN18: ='Private car Nov-25 '!BN18-'Private car AUG-25 '!BN18 -> 0
