Workbook

Sheet model
A1: Company | B1: State | C1: RTO_Code | D1: Vehicle_Category | E1: Date_from | F1: Date_till | G1: Make | H1: Model | I1: Vehicle_Type | J1: Fuel_Type | K1: Vehicle_Age_Min | L1: Vehicle_Age_Max | M1: Policy_Type | N1: Business_Type | O1: CC_Slab | P1: GVW_Min | Q1: GVW_Max | R1: Watt_Slab | S1: Seating_Capacity | T1: Conditions | U1: NCB_Slab | V1: CPA_Cover | W1: Zero_Depreciation | X1: Trailer | Y1: Final Payout
A2: Shriram | B2: TN | C2: Entire Tamilnadu | D2: GCV | E2: N/A | F2: N/A | G2: N/A | H2: N/A | I2: 3 Wheeler Goods | J2: Petrol,Diesel,CNG | K2: =IF(Sheet1!E2="All","N/A", IF(LEFT(Sheet1!E2,4)="upto","N/A", IF(LEFT(Sheet1!E2,5)="Above",VALUE(MID(Sheet1!E2,7,2))+1, IF(ISNUMBER(SEARCH("to",Sheet1!E2)),VALUE(LEFT(Sheet1!E2,FIND(" to",Sheet1!E2)-1)), "N/A")))) -> N/A | L2: =IF(Sheet1!E2="All","N/A", IF(LEFT(Sheet1!E2,4)="upto",VALUE(MID(Sheet1!E2,6,2)), IF(LEFT(Sheet1!E2,5)="Above","N/A", IF(ISNUMBER(SEARCH("to",Sheet1!E2)),VALUE(MID(Sheet1!E2,FIND("to ",Sheet1!E2)+3,2)), "N/A")))) -> 15 | M2: Comprehensive (1+1),SATP | N2: New,Old,Renewal,Rollover | O2: No | P2: =IF(Sheet1!A2="No","No", IF(LEFT(Sheet1!A2,5)="Up to",0, VALUE(LEFT(Sheet1!A2,FIND(" ",Sheet1!A2)-1)))) -> No | Q2: =IF(Sheet1!A2="No","No", IF(LEFT(Sheet1!A2,5)="Up to", VALUE(MID(Sheet1!A2,7,FIND("kg",Sheet1!A2)-7)), VALUE(MID(Sheet1!A2,FIND("to",Sheet1!A2)+3,FIND("kg",Sheet1!A2)-FIND("to",Sheet1!A2)-3)))) -> No | R2: No | S2: No | T2: No | U2: No | V2: No | W2: No | X2: No | Y2: =Sheet1!C2-Sheet1!D2 -> 0.2499
A3: Shriram | B3: TN | C3: Entire Tamilnadu | D3: GCV | E3: N/A | F3: N/A | G3: N/A | H3: N/A | I3: 3 Wheeler Goods | J3: EV | K3: =IF(Sheet1!E3="All","N/A", IF(LEFT(Sheet1!E3,4)="upto","N/A", IF(LEFT(Sheet1!E3,5)="Above",VALUE(MID(Sheet1!E3,7,2))+1, IF(ISNUMBER(SEARCH("to",Sheet1!E3)),VALUE(LEFT(Sheet1!E3,FIND(" to",Sheet1!E3)-1)), "N/A")))) -> N/A | L3: =IF(Sheet1!E3="All","N/A", IF(LEFT(Sheet1!E3,4)="upto",VALUE(MID(Sheet1!E3,6,2)), IF(LEFT(Sheet1!E3,5)="Above","N/A", IF(ISNUMBER(SEARCH("to",Sheet1!E3)),VALUE(MID(Sheet1!E3,FIND("to ",Sheet1!E3)+3,2)), "N/A")))) -> 15 | M3: Comprehensive (1+1),SATP | N3: New,Old,Renewal,Rollover | O3: No | P3: =IF(Sheet1!A3="No","No", IF(LEFT(Sheet1!A3,5)="Up to",0, VALUE(LEFT(Sheet1!A3,FIND(" ",Sheet1!A3)-1)))) -> No | Q3: =IF(Sheet1!A3="No","No", IF(LEFT(Sheet1!A3,5)="Up to", VALUE(MID(Sheet1!A3,7,FIND("kg",Sheet1!A3)-7)), VALUE(MID(Sheet1!A3,FIND("to",Sheet1!A3)+3,FIND("kg",Sheet1!A3)-FIND("to",Sheet1!A3)-3)))) -> No | R3: Upto 2000 | S3: No | T3: No | U3: No | V3: No | W3: No | X3: No | Y3: =Sheet1!C3-Sheet1!D3 -> 0.3479
A4: Shriram | B4: TN | C4: Entire Tamilnadu | D4: GCV | E4: N/A | F4: N/A | G4: N/A | H4: N/A | I4: 3 Wheeler Goods | J4: EV | K4: =IF(Sheet1!E4="All","N/A", IF(LEFT(Sheet1!E4,4)="upto","N/A", IF(LEFT(Sheet1!E4,5)="Above",VALUE(MID(Sheet1!E4,7,2))+1, IF(ISNUMBER(SEARCH("to",Sheet1!E4)),VALUE(LEFT(Sheet1!E4,FIND(" to",Sheet1!E4)-1)), "N/A")))) -> N/A | L4: =IF(Sheet1!E4="All","N/A", IF(LEFT(Sheet1!E4,4)="upto",VALUE(MID(Sheet1!E4,6,2)), IF(LEFT(Sheet1!E4,5)="Above","N/A", IF(ISNUMBER(SEARCH("to",Sheet1!E4)),VALUE(MID(Sheet1!E4,FIND("to ",Sheet1!E4)+3,2)), "N/A")))) -> 15 | M4: Comprehensive (1+1),SATP | N4: New,Old,Renewal,Rollover | O4: No | P4: =IF(Sheet1!A4="No","No", IF(LEFT(Sheet1!A4,5)="Up to",0, VALUE(LEFT(Sheet1!A4,FIND(" ",Sheet1!A4)-1)))) -> No | Q4: =IF(Sheet1!A4="No","No", IF(LEFT(Sheet1!A4,5)="Up to", VALUE(MID(Sheet1!A4,7,FIND("kg",Sheet1!A4)-7)), VALUE(MID(Sheet1!A4,FIND("to",Sheet1!A4)+3,FIND("kg",Sheet1!A4)-FIND("to",Sheet1!A4)-3)))) -> No | R4: Above 2000 | S4: No | T4: No | U4: No | V4: No | W4: No | X4: No | Y4: =Sheet1!C4-Sheet1!D4 -> 0.2744
A5: Royal | B5: TN | C5: 19 | D5: GCV | E5: N/A | F5: N/A | G5: N/A | H5: N/A | I5: 3 Wheeler Goods | J5: EV | K5: =IF(Sheet1!E5="All","N/A", IF(LEFT(Sheet1!E5,4)="upto","N/A", IF(LEFT(Sheet1!E5,5)="Above",VALUE(MID(Sheet1!E5,7,2))+1, IF(ISNUMBER(SEARCH("to",Sheet1!E5)),VALUE(LEFT(Sheet1!E5,FIND(" to",Sheet1!E5)-1)), "N/A")))) -> N/A | L5: =IF(Sheet1!E5="All","N/A", IF(LEFT(Sheet1!E5,4)="upto",VALUE(MID(Sheet1!E5,6,2)), IF(LEFT(Sheet1!E5,5)="Above","N/A", IF(ISNUMBER(SEARCH("to",Sheet1!E5)),VALUE(MID(Sheet1!E5,FIND("to ",Sheet1!E5)+3,2)), "N/A")))) -> N/A | M5: Comprehensive (1+1) | N5: New,Old,Renewal,Rollover | O5: No | P5: =IF(Sheet1!A5="No","No", IF(LEFT(Sheet1!A5,5)="Up to",0, VALUE(LEFT(Sheet1!A5,FIND(" ",Sheet1!A5)-1)))) -> No | Q5: =IF(Sheet1!A5="No","No", IF(LEFT(Sheet1!A5,5)="Up to", VALUE(MID(Sheet1!A5,7,FIND("kg",Sheet1!A5)-7)), VALUE(MID(Sheet1!A5,FIND("to",Sheet1!A5)+3,FIND("kg",Sheet1!A5)-FIND("to",Sheet1!A5)-3)))) -> No | R5: No | S5: No | T5: No | U5: No | V5: No | W5: No | X5: No | Y5: =Sheet1!C5-Sheet1!D5 -> 0.0441
A6: Royal | B6: TN | C6: 01,02,03,04,05,06,07,09,10,11,12,13,14,18,22,85,21 ,72 | D6: GCV | E6: N/A | F6: N/A | G6: N/A | H6: N/A | I6: 3 Wheeler Goods | J6: EV | K6: =IF(Sheet1!E6="All","N/A", IF(LEFT(Sheet1!E6,4)="upto","N/A", IF(LEFT(Sheet1!E6,5)="Above",VALUE(MID(Sheet1!E6,7,2))+1, IF(ISNUMBER(SEARCH("to",Sheet1!E6)),VALUE(LEFT(Sheet1!E6,FIND(" to",Sheet1!E6)-1)), "N/A")))) -> N/A | L6: =IF(Sheet1!E6="All","N/A", IF(LEFT(Sheet1!E6,4)="upto",VALUE(MID(Sheet1!E6,6,2)), IF(LEFT(Sheet1!E6,5)="Above","N/A", IF(ISNUMBER(SEARCH("to",Sheet1!E6)),VALUE(MID(Sheet1!E6,FIND("to ",Sheet1!E6)+3,2)), "N/A")))) -> N/A | M6: Comprehensive (1+1) | N6: New,Old,Renewal,Rollover | O6: No | P6: =IF(Sheet1!A6="No","No", IF(LEFT(Sheet1!A6,5)="Up to",0, VALUE(LEFT(Sheet1!A6,FIND(" ",Sheet1!A6)-1)))) -> No | Q6: =IF(Sheet1!A6="No","No", IF(LEFT(Sheet1!A6,5)="Up to", VALUE(MID(Sheet1!A6,7,FIND("kg",Sheet1!A6)-7)), VALUE(MID(Sheet1!A6,FIND("to",Sheet1!A6)+3,FIND("kg",Sheet1!A6)-FIND("to",Sheet1!A6)-3)))) -> No | R6: No | S6: No | T6: No | U6: No | V6: No | W6: No | X6: No | Y6: =Sheet1!C6-Sheet1!D6 -> 0.2107
A7: Royal | B7: TN | C7: 37,38,40,41,66,99 | D7: GCV | E7: N/A | F7: N/A | G7: N/A | H7: N/A | I7: 3 Wheeler Goods | J7: EV | K7: =IF(Sheet1!E7="All","N/A", IF(LEFT(Sheet1!E7,4)="upto","N/A", IF(LEFT(Sheet1!E7,5)="Above",VALUE(MID(Sheet1!E7,7,2))+1, IF(ISNUMBER(SEARCH("to",Sheet1!E7)),VALUE(LEFT(Sheet1!E7,FIND(" to",Sheet1!E7)-1)), "N/A")))) -> N/A | L7: =IF(Sheet1!E7="All","N/A", IF(LEFT(Sheet1!E7,4)="upto",VALUE(MID(Sheet1!E7,6,2)), IF(LEFT(Sheet1!E7,5)="Above","N/A", IF(ISNUMBER(SEARCH("to",Sheet1!E7)),VALUE(MID(Sheet1!E7,FIND("to ",Sheet1!E7)+3,2)), "N/A")))) -> N/A | M7: Comprehensive (1+1) | N7: New,Old,Renewal,Rollover | O7: No | P7: =IF(Sheet1!A7="No","No", IF(LEFT(Sheet1!A7,5)="Up to",0, VALUE(LEFT(Sheet1!A7,FIND(" ",Sheet1!A7)-1)))) -> No | Q7: =IF(Sheet1!A7="No","No", IF(LEFT(Sheet1!A7,5)="Up to", VALUE(MID(Sheet1!A7,7,FIND("kg",Sheet1!A7)-7)), VALUE(MID(Sheet1!A7,FIND("to",Sheet1!A7)+3,FIND("kg",Sheet1!A7)-FIND("to",Sheet1!A7)-3)))) -> No | R7: No | S7: No | T7: No | U7: No | V7: No | W7: No | X7: No | Y7: =Sheet1!C7-Sheet1!D7 -> 0.1421
A8: Royal | B8: TN | C8: 33,86 | D8: GCV | E8: N/A | F8: N/A | G8: N/A | H8: N/A | I8: 3 Wheeler Goods | J8: EV | K8: =IF(Sheet1!E8="All","N/A", IF(LEFT(Sheet1!E8,4)="upto","N/A", IF(LEFT(Sheet1!E8,5)="Above",VALUE(MID(Sheet1!E8,7,2))+1, IF(ISNUMBER(SEARCH("to",Sheet1!E8)),VALUE(LEFT(Sheet1!E8,FIND(" to",Sheet1!E8)-1)), "N/A")))) -> N/A | L8: =IF(Sheet1!E8="All","N/A", IF(LEFT(Sheet1!E8,4)="upto",VALUE(MID(Sheet1!E8,6,2)), IF(LEFT(Sheet1!E8,5)="Above","N/A", IF(ISNUMBER(SEARCH("to",Sheet1!E8)),VALUE(MID(Sheet1!E8,FIND("to ",Sheet1!E8)+3,2)), "N/A")))) -> N/A | M8: Comprehensive (1+1) | N8: New,Old,Renewal,Rollover | O8: No | P8: =IF(Sheet1!A8="No","No", IF(LEFT(Sheet1!A8,5)="Up to",0, VALUE(LEFT(Sheet1!A8,FIND(" ",Sheet1!A8)-1)))) -> No | Q8: =IF(Sheet1!A8="No","No", IF(LEFT(Sheet1!A8,5)="Up to", VALUE(MID(Sheet1!A8,7,FIND("kg",Sheet1!A8)-7)), VALUE(MID(Sheet1!A8,FIND("to",Sheet1!A8)+3,FIND("kg",Sheet1!A8)-FIND("to",Sheet1!A8)-3)))) -> No | R8: No | S8: No | T8: No | U8: No | V8: No | W8: No | X8: No | Y8: =Sheet1!C8-Sheet1!D8 -> 0.0343
A9: Royal | B9: TN | C9: 75 | D9: GCV | E9: N/A | F9: N/A | G9: N/A | H9: N/A | I9: 3 Wheeler Goods | J9: EV | K9: =IF(Sheet1!E9="All","N/A", IF(LEFT(Sheet1!E9,4)="upto","N/A", IF(LEFT(Sheet1!E9,5)="Above",VALUE(MID(Sheet1!E9,7,2))+1, IF(ISNUMBER(SEARCH("to",Sheet1!E9)),VALUE(LEFT(Sheet1!E9,FIND(" to",Sheet1!E9)-1)), "N/A")))) -> N/A | L9: =IF(Sheet1!E9="All","N/A", IF(LEFT(Sheet1!E9,4)="upto",VALUE(MID(Sheet1!E9,6,2)), IF(LEFT(Sheet1!E9,5)="Above","N/A", IF(ISNUMBER(SEARCH("to",Sheet1!E9)),VALUE(MID(Sheet1!E9,FIND("to ",Sheet1!E9)+3,2)), "N/A")))) -> N/A | M9: Comprehensive (1+1) | N9: New,Old,Renewal,Rollover | O9: No | P9: =IF(Sheet1!A9="No","No", IF(LEFT(Sheet1!A9,5)="Up to",0, VALUE(LEFT(Sheet1!A9,FIND(" ",Sheet1!A9)-1)))) -> No | Q9: =IF(Sheet1!A9="No","No", IF(LEFT(Sheet1!A9,5)="Up to", VALUE(MID(Sheet1!A9,7,FIND("kg",Sheet1!A9)-7)), VALUE(MID(Sheet1!A9,FIND("to",Sheet1!A9)+3,FIND("kg",Sheet1!A9)-FIND("to",Sheet1!A9)-3)))) -> No | R9: No | S9: No | T9: No | U9: No | V9: No | W9: No | X9: No | Y9: =Sheet1!C9-Sheet1!D9 -> 0.1617
A10: Royal | B10: TN | C10: 62,67 | D10: GCV | E10: N/A | F10: N/A | G10: N/A | H10: N/A | I10: 3 Wheeler Goods | J10: EV | K10: =IF(Sheet1!E10="All","N/A", IF(LEFT(Sheet1!E10,4)="upto","N/A", IF(LEFT(Sheet1!E10,5)="Above",VALUE(MID(Sheet1!E10,7,2))+1, IF(ISNUMBER(SEARCH("to",Sheet1!E10)),VALUE(LEFT(Sheet1!E10,FIND(" to",Sheet1!E10)-1)), "N/A")))) -> N/A | L10: =IF(Sheet1!E10="All","N/A", IF(LEFT(Sheet1!E10,4)="upto",VALUE(MID(Sheet1!E10,6,2)), IF(LEFT(Sheet1!E10,5)="Above","N/A", IF(ISNUMBER(SEARCH("to",Sheet1!E10)),VALUE(MID(Sheet1!E10,FIND("to ",Sheet1!E10)+3,2)), "N/A")))) -> N/A | M10: Comprehensive (1+1) | N10: New,Old,Renewal,Rollover | O10: No | P10: =IF(Sheet1!A10="No","No", IF(LEFT(Sheet1!A10,5)="Up to",0, VALUE(LEFT(Sheet1!A10,FIND(" ",Sheet1!A10)-1)))) -> No | Q10: =IF(Sheet1!A10="No","No", IF(LEFT(Sheet1!A10,5)="Up to", VALUE(MID(Sheet1!A10,7,FIND("kg",Sheet1!A10)-7)), VALUE(MID(Sheet1!A10,FIND("to",Sheet1!A10)+3,FIND("kg",Sheet1!A10)-FIND("to",Sheet1!A10)-3)))) -> No | R10: No | S10: No | T10: No | U10: No | V10: No | W10: No | X10: No | Y10: =Sheet1!C10-Sheet1!D10 -> 0.1911
A11: Royal | B11: TN | C11: 39,42 | D11: GCV | E11: N/A | F11: N/A | G11: N/A | H11: N/A | I11: 3 Wheeler Goods | J11: EV | K11: =IF(Sheet1!E11="All","N/A", IF(LEFT(Sheet1!E11,4)="upto","N/A", IF(LEFT(Sheet1!E11,5)="Above",VALUE(MID(Sheet1!E11,7,2))+1, IF(ISNUMBER(SEARCH("to",Sheet1!E11)),VALUE(LEFT(Sheet1!E11,FIND(" to",Sheet1!E11)-1)), "N/A")))) -> N/A | L11: =IF(Sheet1!E11="All","N/A", IF(LEFT(Sheet1!E11,4)="upto",VALUE(MID(Sheet1!E11,6,2)), IF(LEFT(Sheet1!E11,5)="Above","N/A", IF(ISNUMBER(SEARCH("to",Sheet1!E11)),VALUE(MID(Sheet1!E11,FIND("to ",Sheet1!E11)+3,2)), "N/A")))) -> N/A | M11: Comprehensive (1+1) | N11: New,Old,Renewal,Rollover | O11: No | P11: =IF(Sheet1!A11="No","No", IF(LEFT(Sheet1!A11,5)="Up to",0, VALUE(LEFT(Sheet1!A11,FIND(" ",Sheet1!A11)-1)))) -> No | Q11: =IF(Sheet1!A11="No","No", IF(LEFT(Sheet1!A11,5)="Up to", VALUE(MID(Sheet1!A11,7,FIND("kg",Sheet1!A11)-7)), VALUE(MID(Sheet1!A11,FIND("to",Sheet1!A11)+3,FIND("kg",Sheet1!A11)-FIND("to",Sheet1!A11)-3)))) -> No | R11: No | S11: No | T11: No | U11: No | V11: No | W11: No | X11: No | Y11: =Sheet1!C11-Sheet1!D11 -> 0.1029
A12: Royal | B12: TN | C12: 20 | D12: GCV | E12: N/A | F12: N/A | G12: N/A | H12: N/A | I12: 3 Wheeler Goods | J12: EV | K12: =IF(Sheet1!E12="All","N/A", IF(LEFT(Sheet1!E12,4)="upto","N/A", IF(LEFT(Sheet1!E12,5)="Above",VALUE(MID(Sheet1!E12,7,2))+1, IF(ISNUMBER(SEARCH("to",Sheet1!E12)),VALUE(LEFT(Sheet1!E12,FIND(" to",Sheet1!E12)-1)), "N/A")))) -> N/A | L12: =IF(Sheet1!E12="All","N/A", IF(LEFT(Sheet1!E12,4)="upto",VALUE(MID(Sheet1!E12,6,2)), IF(LEFT(Sheet1!E12,5)="Above","N/A", IF(ISNUMBER(SEARCH("to",Sheet1!E12)),VALUE(MID(Sheet1!E12,FIND("to ",Sheet1!E12)+3,2)), "N/A")))) -> N/A | M12: Comprehensive (1+1) | N12: New,Old,Renewal,Rollover | O12: No | P12: =IF(Sheet1!A12="No","No", IF(LEFT(Sheet1!A12,5)="Up to",0, VALUE(LEFT(Sheet1!A12,FIND(" ",Sheet1!A12)-1)))) -> No | Q12: =IF(Sheet1!A12="No","No", IF(LEFT(Sheet1!A12,5)="Up to", VALUE(MID(Sheet1!A12,7,FIND("kg",Sheet1!A12)-7)), VALUE(MID(Sheet1!A12,FIND("to",Sheet1!A12)+3,FIND("kg",Sheet1!A12)-FIND("to",Sheet1!A12)-3)))) -> No | R12: No | S12: No | T12: No | U12: No | V12: No | W12: No | X12: No | Y12: =Sheet1!C12-Sheet1!D12 -> 0.1127
A13: Royal | B13: TN | C13: 19 | D13: GCV | E13: N/A | F13: N/A | G13: N/A | H13: N/A | I13: 3 Wheeler Goods | J13: EV | K13: =IF(Sheet1!E13="All","N/A", IF(LEFT(Sheet1!E13,4)="upto","N/A", IF(LEFT(Sheet1!E13,5)="Above",VALUE(MID(Sheet1!E13,7,2))+1, IF(ISNUMBER(SEARCH("to",Sheet1!E13)),VALUE(LEFT(Sheet1!E13,FIND(" to",Sheet1!E13)-1)), "N/A")))) -> N/A | L13: =IF(Sheet1!E13="All","N/A", IF(LEFT(Sheet1!E13,4)="upto",VALUE(MID(Sheet1!E13,6,2)), IF(LEFT(Sheet1!E13,5)="Above","N/A", IF(ISNUMBER(SEARCH("to",Sheet1!E13)),VALUE(MID(Sheet1!E13,FIND("to ",Sheet1!E13)+3,2)), "N/A")))) -> N/A | M13: SATP | N13: New,Old,Renewal,Rollover | O13: No | P13: =IF(Sheet1!A13="No","No", IF(LEFT(Sheet1!A13,5)="Up to",0, VALUE(LEFT(Sheet1!A13,FIND(" ",Sheet1!A13)-1)))) -> No | Q13: =IF(Sheet1!A13="No","No", IF(LEFT(Sheet1!A13,5)="Up to", VALUE(MID(Sheet1!A13,7,FIND("kg",Sheet1!A13)-7)), VALUE(MID(Sheet1!A13,FIND("to",Sheet1!A13)+3,FIND("kg",Sheet1!A13)-FIND("to",Sheet1!A13)-3)))) -> No | R13: No | S13: No | T13: No | U13: No | V13: No | W13: No | X13: No | Y13: =Sheet1!C13-Sheet1!D13 -> 0.0049
A14: Royal | B14: TN | C14: 01,02,03,04,05,06,07,09,10,11,12,13,14,18,22,85,21 | D14: GCV | E14: N/A | F14: N/A | G14: N/A | H14: N/A | I14: 3 Wheeler Goods | J14: EV | K14: =IF(Sheet1!E14="All","N/A", IF(LEFT(Sheet1!E14,4)="upto","N/A", IF(LEFT(Sheet1!E14,5)="Above",VALUE(MID(Sheet1!E14,7,2))+1, IF(ISNUMBER(SEARCH("to",Sheet1!E14)),VALUE(LEFT(Sheet1!E14,FIND(" to",Sheet1!E14)-1)), "N/A")))) -> N/A | L14: =IF(Sheet1!E14="All","N/A", IF(LEFT(Sheet1!E14,4)="upto",VALUE(MID(Sheet1!E14,6,2)), IF(LEFT(Sheet1!E14,5)="Above","N/A", IF(ISNUMBER(SEARCH("to",Sheet1!E14)),VALUE(MID(Sheet1!E14,FIND("to ",Sheet1!E14)+3,2)), "N/A")))) -> N/A | M14: SATP | N14: New,Old,Renewal,Rollover | O14: No | P14: =IF(Sheet1!A14="No","No", IF(LEFT(Sheet1!A14,5)="Up to",0, VALUE(LEFT(Sheet1!A14,FIND(" ",Sheet1!A14)-1)))) -> No | Q14: =IF(Sheet1!A14="No","No", IF(LEFT(Sheet1!A14,5)="Up to", VALUE(MID(Sheet1!A14,7,FIND("kg",Sheet1!A14)-7)), VALUE(MID(Sheet1!A14,FIND("to",Sheet1!A14)+3,FIND("kg",Sheet1!A14)-FIND("to",Sheet1!A14)-3)))) -> No | R14: No | S14: No | T14: No | U14: No | V14: No | W14: No | X14: No | Y14: =Sheet1!C14-Sheet1!D14 -> 0.2597
A15: Royal | B15: TN | C15: 37,38,40,41,66,99 | D15: GCV | E15: N/A | F15: N/A | G15: N/A | H15: N/A | I15: 3 Wheeler Goods | J15: EV | K15: =IF(Sheet1!E15="All","N/A", IF(LEFT(Sheet1!E15,4)="upto","N/A", IF(LEFT(Sheet1!E15,5)="Above",VALUE(MID(Sheet1!E15,7,2))+1, IF(ISNUMBER(SEARCH("to",Sheet1!E15)),VALUE(LEFT(Sheet1!E15,FIND(" to",Sheet1!E15)-1)), "N/A")))) -> N/A | L15: =IF(Sheet1!E15="All","N/A", IF(LEFT(Sheet1!E15,4)="upto",VALUE(MID(Sheet1!E15,6,2)), IF(LEFT(Sheet1!E15,5)="Above","N/A", IF(ISNUMBER(SEARCH("to",Sheet1!E15)),VALUE(MID(Sheet1!E15,FIND("to ",Sheet1!E15)+3,2)), "N/A")))) -> N/A | M15: SATP | N15: New,Old,Renewal,Rollover | O15: No | P15: =IF(Sheet1!A15="No","No", IF(LEFT(Sheet1!A15,5)="Up to",0, VALUE(LEFT(Sheet1!A15,FIND(" ",Sheet1!A15)-1)))) -> No | Q15: =IF(Sheet1!A15="No","No", IF(LEFT(Sheet1!A15,5)="Up to", VALUE(MID(Sheet1!A15,7,FIND("kg",Sheet1!A15)-7)), VALUE(MID(Sheet1!A15,FIND("to",Sheet1!A15)+3,FIND("kg",Sheet1!A15)-FIND("to",Sheet1!A15)-3)))) -> No | R15: No | S15: No | T15: No | U15: No | V15: No | W15: No | X15: No | Y15: =Sheet1!C15-Sheet1!D15 -> 0.1617
A16: Royal | B16: TN | C16: 33,86 | D16: GCV | E16: N/A | F16: N/A | G16: N/A | H16: N/A | I16: 3 Wheeler Goods | J16: EV | K16: =IF(Sheet1!E16="All","N/A", IF(LEFT(Sheet1!E16,4)="upto","N/A", IF(LEFT(Sheet1!E16,5)="Above",VALUE(MID(Sheet1!E16,7,2))+1, IF(ISNUMBER(SEARCH("to",Sheet1!E16)),VALUE(LEFT(Sheet1!E16,FIND(" to",Sheet1!E16)-1)), "N/A")))) -> N/A | L16: =IF(Sheet1!E16="All","N/A", IF(LEFT(Sheet1!E16,4)="upto",VALUE(MID(Sheet1!E16,6,2)), IF(LEFT(Sheet1!E16,5)="Above","N/A", IF(ISNUMBER(SEARCH("to",Sheet1!E16)),VALUE(MID(Sheet1!E16,FIND("to ",Sheet1!E16)+3,2)), "N/A")))) -> N/A | M16: SATP | N16: New,Old,Renewal,Rollover | O16: No | P16: =IF(Sheet1!A16="No","No", IF(LEFT(Sheet1!A16,5)="Up to",0, VALUE(LEFT(Sheet1!A16,FIND(" ",Sheet1!A16)-1)))) -> No | Q16: =IF(Sheet1!A16="No","No", IF(LEFT(Sheet1!A16,5)="Up to", VALUE(MID(Sheet1!A16,7,FIND("kg",Sheet1!A16)-7)), VALUE(MID(Sheet1!A16,FIND("to",Sheet1!A16)+3,FIND("kg",Sheet1!A16)-FIND("to",Sheet1!A16)-3)))) -> No | R16: No | S16: No | T16: No | U16: No | V16: No | W16: No | X16: No | Y16: =Sheet1!C16-Sheet1!D16 -> -0.0147
A17: Royal | B17: TN | C17: 75 | D17: GCV | E17: N/A | F17: N/A | G17: N/A | H17: N/A | I17: 3 Wheeler Goods | J17: EV | K17: =IF(Sheet1!E17="All","N/A", IF(LEFT(Sheet1!E17,4)="upto","N/A", IF(LEFT(Sheet1!E17,5)="Above",VALUE(MID(Sheet1!E17,7,2))+1, IF(ISNUMBER(SEARCH("to",Sheet1!E17)),VALUE(LEFT(Sheet1!E17,FIND(" to",Sheet1!E17)-1)), "N/A")))) -> N/A | L17: =IF(Sheet1!E17="All","N/A", IF(LEFT(Sheet1!E17,4)="upto",VALUE(MID(Sheet1!E17,6,2)), IF(LEFT(Sheet1!E17,5)="Above","N/A", IF(ISNUMBER(SEARCH("to",Sheet1!E17)),VALUE(MID(Sheet1!E17,FIND("to ",Sheet1!E17)+3,2)), "N/A")))) -> N/A | M17: SATP | N17: New,Old,Renewal,Rollover | O17: No | P17: =IF(Sheet1!A17="No","No", IF(LEFT(Sheet1!A17,5)="Up to",0, VALUE(LEFT(Sheet1!A17,FIND(" ",Sheet1!A17)-1)))) -> No | Q17: =IF(Sheet1!A17="No","No", IF(LEFT(Sheet1!A17,5)="Up to", VALUE(MID(Sheet1!A17,7,FIND("kg",Sheet1!A17)-7)), VALUE(MID(Sheet1!A17,FIND("to",Sheet1!A17)+3,FIND("kg",Sheet1!A17)-FIND("to",Sheet1!A17)-3)))) -> No | R17: No | S17: No | T17: No | U17: No | V17: No | W17: No | X17: No | Y17: =Sheet1!C17-Sheet1!D17 -> 0.1813
A18: Royal | B18: TN | C18: 62,67 | D18: GCV | E18: N/A | F18: N/A | G18: N/A | H18: N/A | I18: 3 Wheeler Goods | J18: EV | K18: =IF(Sheet1!E18="All","N/A", IF(LEFT(Sheet1!E18,4)="upto","N/A", IF(LEFT(Sheet1!E18,5)="Above",VALUE(MID(Sheet1!E18,7,2))+1, IF(ISNUMBER(SEARCH("to",Sheet1!E18)),VALUE(LEFT(Sheet1!E18,FIND(" to",Sheet1!E18)-1)), "N/A")))) -> N/A | L18: =IF(Sheet1!E18="All","N/A", IF(LEFT(Sheet1!E18,4)="upto",VALUE(MID(Sheet1!E18,6,2)), IF(LEFT(Sheet1!E18,5)="Above","N/A", IF(ISNUMBER(SEARCH("to",Sheet1!E18)),VALUE(MID(Sheet1!E18,FIND("to ",Sheet1!E18)+3,2)), "N/A")))) -> N/A | M18: SATP | N18: New,Old,Renewal,Rollover | O18: No | P18: =IF(Sheet1!A18="No","No", IF(LEFT(Sheet1!A18,5)="Up to",0, VALUE(LEFT(Sheet1!A18,FIND(" ",Sheet1!A18)-1)))) -> No | Q18: =IF(Sheet1!A18="No","No", IF(LEFT(Sheet1!A18,5)="Up to", VALUE(MID(Sheet1!A18,7,FIND("kg",Sheet1!A18)-7)), VALUE(MID(Sheet1!A18,FIND("to",Sheet1!A18)+3,FIND("kg",Sheet1!A18)-FIND("to",Sheet1!A18)-3)))) -> No | R18: No | S18: No | T18: No | U18: No | V18: No | W18: No | X18: No | Y18: =Sheet1!C18-Sheet1!D18 -> 0.2303
A19: Royal | B19: TN | C19: 39,42,20 | D19: GCV | E19: N/A | F19: N/A | G19: N/A | H19: N/A | I19: 3 Wheeler Goods | J19: EV | K19: =IF(Sheet1!E19="All","N/A", IF(LEFT(Sheet1!E19,4)="upto","N/A", IF(LEFT(Sheet1!E19,5)="Above",VALUE(MID(Sheet1!E19,7,2))+1, IF(ISNUMBER(SEARCH("to",Sheet1!E19)),VALUE(LEFT(Sheet1!E19,FIND(" to",Sheet1!E19)-1)), "N/A")))) -> N/A | L19: =IF(Sheet1!E19="All","N/A", IF(LEFT(Sheet1!E19,4)="upto",VALUE(MID(Sheet1!E19,6,2)), IF(LEFT(Sheet1!E19,5)="Above","N/A", IF(ISNUMBER(SEARCH("to",Sheet1!E19)),VALUE(MID(Sheet1!E19,FIND("to ",Sheet1!E19)+3,2)), "N/A")))) -> N/A | M19: SATP | N19: New,Old,Renewal,Rollover | O19: No | P19: =IF(Sheet1!A19="No","No", IF(LEFT(Sheet1!A19,5)="Up to",0, VALUE(LEFT(Sheet1!A19,FIND(" ",Sheet1!A19)-1)))) -> No | Q19: =IF(Sheet1!A19="No","No", IF(LEFT(Sheet1!A19,5)="Up to", VALUE(MID(Sheet1!A19,7,FIND("kg",Sheet1!A19)-7)), VALUE(MID(Sheet1!A19,FIND("to",Sheet1!A19)+3,FIND("kg",Sheet1!A19)-FIND("to",Sheet1!A19)-3)))) -> No | R19: No | S19: No | T19: No | U19: No | V19: No | W19: No | X19: No | Y19: =Sheet1!C19-Sheet1!D19 -> 0.1029
A20: Royal | B20: TN | C20: 01,02,03,04,05,06,07,09,10,11,12,13,14,18,22,85,21,72 | D20: GCV | E20: N/A | F20: N/A | G20: N/A | H20: N/A | I20: 3 Wheeler Goods | J20: Petrol,Diesel,CNG | K20: =IF(Sheet1!E20="All","N/A", IF(LEFT(Sheet1!E20,4)="upto","N/A", IF(LEFT(Sheet1!E20,5)="Above",VALUE(MID(Sheet1!E20,7,2))+1, IF(ISNUMBER(SEARCH("to",Sheet1!E20)),VALUE(LEFT(Sheet1!E20,FIND(" to",Sheet1!E20)-1)), "N/A")))) -> N/A | L20: =IF(Sheet1!E20="All","N/A", IF(LEFT(Sheet1!E20,4)="upto",VALUE(MID(Sheet1!E20,6,2)), IF(LEFT(Sheet1!E20,5)="Above","N/A", IF(ISNUMBER(SEARCH("to",Sheet1!E20)),VALUE(MID(Sheet1!E20,FIND("to ",Sheet1!E20)+3,2)), "N/A")))) -> N/A | M20: Comprehensive (1+1) | N20: New,Old,Renewal,Rollover | O20: No | P20: =IF(Sheet1!A20="No","No", IF(LEFT(Sheet1!A20,5)="Up to",0, VALUE(LEFT(Sheet1!A20,FIND(" ",Sheet1!A20)-1)))) -> No | Q20: =IF(Sheet1!A20="No","No", IF(LEFT(Sheet1!A20,5)="Up to", VALUE(MID(Sheet1!A20,7,FIND("kg",Sheet1!A20)-7)), VALUE(MID(Sheet1!A20,FIND("to",Sheet1!A20)+3,FIND("kg",Sheet1!A20)-FIND("to",Sheet1!A20)-3)))) -> No | R20: No | S20: No | T20: No | U20: No | V20: No | W20: No | X20: No | Y20: =Sheet1!C20-Sheet1!D20 -> 0.0245
A21: Royal | B21: TN | C21: 01,02,03,04,05,06,07,09,10,11,12,13,14,18,22,85,21,72 | D21: GCV | E21: N/A | F21: N/A | G21: N/A | H21: N/A | I21: 3 Wheeler Goods | J21: Petrol,Diesel,CNG | K21: =IF(Sheet1!E21="All","N/A", IF(LEFT(Sheet1!E21,4)="upto","N/A", IF(LEFT(Sheet1!E21,5)="Above",VALUE(MID(Sheet1!E21,7,2))+1, IF(ISNUMBER(SEARCH("to",Sheet1!E21)),VALUE(LEFT(Sheet1!E21,FIND(" to",Sheet1!E21)-1)), "N/A")))) -> N/A | L21: =IF(Sheet1!E21="All","N/A", IF(LEFT(Sheet1!E21,4)="upto",VALUE(MID(Sheet1!E21,6,2)), IF(LEFT(Sheet1!E21,5)="Above","N/A", IF(ISNUMBER(SEARCH("to",Sheet1!E21)),VALUE(MID(Sheet1!E21,FIND("to ",Sheet1!E21)+3,2)), "N/A")))) -> N/A | M21: SATP | N21: New,Old,Renewal,Rollover | O21: No | P21: =IF(Sheet1!A21="No","No", IF(LEFT(Sheet1!A21,5)="Up to",0, VALUE(LEFT(Sheet1!A21,FIND(" ",Sheet1!A21)-1)))) -> No | Q21: =IF(Sheet1!A21="No","No", IF(LEFT(Sheet1!A21,5)="Up to", VALUE(MID(Sheet1!A21,7,FIND("kg",Sheet1!A21)-7)), VALUE(MID(Sheet1!A21,FIND("to",Sheet1!A21)+3,FIND("kg",Sheet1!A21)-FIND("to",Sheet1!A21)-3)))) -> No | R21: No | S21: No | T21: No | U21: No | V21: No | W21: No | X21: No | Y21: =Sheet1!C21-Sheet1!D21 -> 0.0833
A22: Royal | B22: TN | C22: 62,67 | D22: GCV | E22: N/A | F22: N/A | G22: N/A | H22: N/A | I22: 3 Wheeler Goods | J22: Petrol,Diesel,CNG | K22: =IF(Sheet1!E22="All","N/A", IF(LEFT(Sheet1!E22,4)="upto","N/A", IF(LEFT(Sheet1!E22,5)="Above",VALUE(MID(Sheet1!E22,7,2))+1, IF(ISNUMBER(SEARCH("to",Sheet1!E22)),VALUE(LEFT(Sheet1!E22,FIND(" to",Sheet1!E22)-1)), "N/A")))) -> N/A | L22: =IF(Sheet1!E22="All","N/A", IF(LEFT(Sheet1!E22,4)="upto",VALUE(MID(Sheet1!E22,6,2)), IF(LEFT(Sheet1!E22,5)="Above","N/A", IF(ISNUMBER(SEARCH("to",Sheet1!E22)),VALUE(MID(Sheet1!E22,FIND("to ",Sheet1!E22)+3,2)), "N/A")))) -> N/A | M22: SATP | N22: New,Old,Renewal,Rollover | O22: No | P22: =IF(Sheet1!A22="No","No", IF(LEFT(Sheet1!A22,5)="Up to",0, VALUE(LEFT(Sheet1!A22,FIND(" ",Sheet1!A22)-1)))) -> No | Q22: =IF(Sheet1!A22="No","No", IF(LEFT(Sheet1!A22,5)="Up to", VALUE(MID(Sheet1!A22,7,FIND("kg",Sheet1!A22)-7)), VALUE(MID(Sheet1!A22,FIND("to",Sheet1!A22)+3,FIND("kg",Sheet1!A22)-FIND("to",Sheet1!A22)-3)))) -> No | R22: No | S22: No | T22: No | U22: No | V22: No | W22: No | X22: No | Y22: =Sheet1!C22-Sheet1!D22 -> 0.0441
A23: Chola | B23: TN | C23: Entire Tamilnadu | D23: GCV | E23: N/A | F23: N/A | G23: N/A | H23: N/A | I23: 3 Wheeler Goods | J23: All | K23: =IF(Sheet1!E23="All","N/A", IF(LEFT(Sheet1!E23,4)="upto","N/A", IF(LEFT(Sheet1!E23,5)="Above",VALUE(MID(Sheet1!E23,7,2))+1, IF(ISNUMBER(SEARCH("to",Sheet1!E23)),VALUE(LEFT(Sheet1!E23,FIND(" to",Sheet1!E23)-1)), "N/A")))) -> N/A | L23: =IF(Sheet1!E23="All","N/A", IF(LEFT(Sheet1!E23,4)="upto",VALUE(MID(Sheet1!E23,6,2)), IF(LEFT(Sheet1!E23,5)="Above","N/A", IF(ISNUMBER(SEARCH("to",Sheet1!E23)),VALUE(MID(Sheet1!E23,FIND("to ",Sheet1!E23)+3,2)), "N/A")))) -> N/A | M23: Comprehensive (1+1) | N23: New,Old,Renewal,Rollover | O23: No | P23: =IF(Sheet1!A23="No","No", IF(LEFT(Sheet1!A23,5)="Up to",0, VALUE(LEFT(Sheet1!A23,FIND(" ",Sheet1!A23)-1)))) -> No | Q23: =IF(Sheet1!A23="No","No", IF(LEFT(Sheet1!A23,5)="Up to", VALUE(MID(Sheet1!A23,7,FIND("kg",Sheet1!A23)-7)), VALUE(MID(Sheet1!A23,FIND("to",Sheet1!A23)+3,FIND("kg",Sheet1!A23)-FIND("to",Sheet1!A23)-3)))) -> No | R23: No | S23: No | T23: No | U23: No | V23: Yes | W23: No | X23: No | Y23: =Sheet1!C23-Sheet1!D23 -> 0.2254
A24: ICICI | B24: TN | C24: Entire Tamilnadu | D24: GCV | E24: N/A | F24: N/A | G24: N/A | H24: N/A | I24: 3 Wheeler Goods | J24: Petrol,Diesel,CNG | K24: =IF(Sheet1!E24="All","N/A", IF(LEFT(Sheet1!E24,4)="upto","N/A", IF(LEFT(Sheet1!E24,5)="Above",VALUE(MID(Sheet1!E24,7,2))+1, IF(ISNUMBER(SEARCH("to",Sheet1!E24)),VALUE(LEFT(Sheet1!E24,FIND(" to",Sheet1!E24)-1)), "N/A")))) -> N/A | L24: =IF(Sheet1!E24="All","N/A", IF(LEFT(Sheet1!E24,4)="upto",VALUE(MID(Sheet1!E24,6,2)), IF(LEFT(Sheet1!E24,5)="Above","N/A", IF(ISNUMBER(SEARCH("to",Sheet1!E24)),VALUE(MID(Sheet1!E24,FIND("to ",Sheet1!E24)+3,2)), "N/A")))) -> N/A | M24: Comprehensive (1+1) | N24: Old | O24: No | P24: =IF(Sheet1!A24="No","No", IF(LEFT(Sheet1!A24,5)="Up to",0, VALUE(LEFT(Sheet1!A24,FIND(" ",Sheet1!A24)-1)))) -> No | Q24: =IF(Sheet1!A24="No","No", IF(LEFT(Sheet1!A24,5)="Up to", VALUE(MID(Sheet1!A24,7,FIND("kg",Sheet1!A24)-7)), VALUE(MID(Sheet1!A24,FIND("to",Sheet1!A24)+3,FIND("kg",Sheet1!A24)-FIND("to",Sheet1!A24)-3)))) -> No | R24: No | S24: No | T24: No | U24: No | V24: No | W24: No | X24: No | Y24: =Sheet1!C24-Sheet1!D24 -> 0.4949
A25: ICICI | B25: TN | C25: 01,02,03,04,05,06,07,09,10,11,12,13,14,18,22,85 | D25: GCV | E25: N/A | F25: N/A | G25: N/A | H25: N/A | I25: 3 Wheeler Goods | J25: EV | K25: =IF(Sheet1!E25="All","N/A", IF(LEFT(Sheet1!E25,4)="upto","N/A", IF(LEFT(Sheet1!E25,5)="Above",VALUE(MID(Sheet1!E25,7,2))+1, IF(ISNUMBER(SEARCH("to",Sheet1!E25)),VALUE(LEFT(Sheet1!E25,FIND(" to",Sheet1!E25)-1)), "N/A")))) -> N/A | L25: =IF(Sheet1!E25="All","N/A", IF(LEFT(Sheet1!E25,4)="upto",VALUE(MID(Sheet1!E25,6,2)), IF(LEFT(Sheet1!E25,5)="Above","N/A", IF(ISNUMBER(SEARCH("to",Sheet1!E25)),VALUE(MID(Sheet1!E25,FIND("to ",Sheet1!E25)+3,2)), "N/A")))) -> N/A | M25: Comprehensive (1+1) | N25: New,Old,Renewal,Rollover | O25: No | P25: =IF(Sheet1!A25="No","No", IF(LEFT(Sheet1!A25,5)="Up to",0, VALUE(LEFT(Sheet1!A25,FIND(" ",Sheet1!A25)-1)))) -> No | Q25: =IF(Sheet1!A25="No","No", IF(LEFT(Sheet1!A25,5)="Up to", VALUE(MID(Sheet1!A25,7,FIND("kg",Sheet1!A25)-7)), VALUE(MID(Sheet1!A25,FIND("to",Sheet1!A25)+3,FIND("kg",Sheet1!A25)-FIND("to",Sheet1!A25)-3)))) -> No | R25: No | S25: No | T25: No | U25: No | V25: No | W25: No | X25: No | Y25: =Sheet1!C25-Sheet1!D25 -> 0.0539
A26: ICICI | B26: TN | C26: 37,38,40,41,66,99 | D26: GCV | E26: N/A | F26: N/A | G26: N/A | H26: N/A | I26: 3 Wheeler Goods | J26: EV | K26: =IF(Sheet1!E26="All","N/A", IF(LEFT(Sheet1!E26,4)="upto","N/A", IF(LEFT(Sheet1!E26,5)="Above",VALUE(MID(Sheet1!E26,7,2))+1, IF(ISNUMBER(SEARCH("to",Sheet1!E26)),VALUE(LEFT(Sheet1!E26,FIND(" to",Sheet1!E26)-1)), "N/A")))) -> N/A | L26: =IF(Sheet1!E26="All","N/A", IF(LEFT(Sheet1!E26,4)="upto",VALUE(MID(Sheet1!E26,6,2)), IF(LEFT(Sheet1!E26,5)="Above","N/A", IF(ISNUMBER(SEARCH("to",Sheet1!E26)),VALUE(MID(Sheet1!E26,FIND("to ",Sheet1!E26)+3,2)), "N/A")))) -> N/A | M26: Comprehensive (1+1) | N26: New,Old,Renewal,Rollover | O26: No | P26: =IF(Sheet1!A26="No","No", IF(LEFT(Sheet1!A26,5)="Up to",0, VALUE(LEFT(Sheet1!A26,FIND(" ",Sheet1!A26)-1)))) -> No | Q26: =IF(Sheet1!A26="No","No", IF(LEFT(Sheet1!A26,5)="Up to", VALUE(MID(Sheet1!A26,7,FIND("kg",Sheet1!A26)-7)), VALUE(MID(Sheet1!A26,FIND("to",Sheet1!A26)+3,FIND("kg",Sheet1!A26)-FIND("to",Sheet1!A26)-3)))) -> No | R26: No | S26: No | T26: No | U26: No | V26: No | W26: No | X26: No | Y26: =Sheet1!C26-Sheet1!D26 -> 0.0833
A27: Universal | B27: TN | C27: Entire Tamilnadu | D27: GCV | E27: N/A | F27: N/A | G27: N/A | H27: N/A | I27: 3 Wheeler Goods | J27: All | K27: =IF(Sheet1!E27="All","N/A", IF(LEFT(Sheet1!E27,4)="upto","N/A", IF(LEFT(Sheet1!E27,5)="Above",VALUE(MID(Sheet1!E27,7,2))+1, IF(ISNUMBER(SEARCH("to",Sheet1!E27)),VALUE(LEFT(Sheet1!E27,FIND(" to",Sheet1!E27)-1)), "N/A")))) -> N/A | L27: =IF(Sheet1!E27="All","N/A", IF(LEFT(Sheet1!E27,4)="upto",VALUE(MID(Sheet1!E27,6,2)), IF(LEFT(Sheet1!E27,5)="Above","N/A", IF(ISNUMBER(SEARCH("to",Sheet1!E27)),VALUE(MID(Sheet1!E27,FIND("to ",Sheet1!E27)+3,2)), "N/A")))) -> N/A | M27: Comprehensive (1+1),SATP | N27: New,Old,Renewal,Rollover | O27: No | P27: =IF(Sheet1!A27="No","No", IF(LEFT(Sheet1!A27,5)="Up to",0, VALUE(LEFT(Sheet1!A27,FIND(" ",Sheet1!A27)-1)))) -> No | Q27: =IF(Sheet1!A27="No","No", IF(LEFT(Sheet1!A27,5)="Up to", VALUE(MID(Sheet1!A27,7,FIND("kg",Sheet1!A27)-7)), VALUE(MID(Sheet1!A27,FIND("to",Sheet1!A27)+3,FIND("kg",Sheet1!A27)-FIND("to",Sheet1!A27)-3)))) -> No | R27: No | S27: No | T27: No | U27: No | V27: No | W27: No | X27: No | Y27: =Sheet1!C27-Sheet1!D27 -> 0.2989
A28: Universal | B28: TN | C28: Entire pondicherry | D28: GCV | E28: N/A | F28: N/A | G28: N/A | H28: N/A | I28: 3 Wheeler Goods | J28: All | K28: =IF(Sheet1!E28="All","N/A", IF(LEFT(Sheet1!E28,4)="upto","N/A", IF(LEFT(Sheet1!E28,5)="Above",VALUE(MID(Sheet1!E28,7,2))+1, IF(ISNUMBER(SEARCH("to",Sheet1!E28)),VALUE(LEFT(Sheet1!E28,FIND(" to",Sheet1!E28)-1)), "N/A")))) -> N/A | L28: =IF(Sheet1!E28="All","N/A", IF(LEFT(Sheet1!E28,4)="upto",VALUE(MID(Sheet1!E28,6,2)), IF(LEFT(Sheet1!E28,5)="Above","N/A", IF(ISNUMBER(SEARCH("to",Sheet1!E28)),VALUE(MID(Sheet1!E28,FIND("to ",Sheet1!E28)+3,2)), "N/A")))) -> N/A | M28: Comprehensive (1+1),SATP | N28: New,Old,Renewal,Rollover | O28: No | P28: =IF(Sheet1!A28="No","No", IF(LEFT(Sheet1!A28,5)="Up to",0, VALUE(LEFT(Sheet1!A28,FIND(" ",Sheet1!A28)-1)))) -> No | Q28: =IF(Sheet1!A28="No","No", IF(LEFT(Sheet1!A28,5)="Up to", VALUE(MID(Sheet1!A28,7,FIND("kg",Sheet1!A28)-7)), VALUE(MID(Sheet1!A28,FIND("to",Sheet1!A28)+3,FIND("kg",Sheet1!A28)-FIND("to",Sheet1!A28)-3)))) -> No | R28: No | S28: No | T28: No | U28: No | V28: No | W28: No | X28: No | Y28: =Sheet1!C28-Sheet1!D28 -> 0.2891
A29: Tata AIG | B29: TN-CHN | C29: 01,02,03,04,05,06,07,09,10,11,12,13,14,18,22,85 | D29: GCV | E29: N/A | F29: N/A | G29: N/A | H29: N/A | I29: 3 Wheeler Goods | J29: All | K29: =IF(Sheet1!E29="All","N/A", IF(LEFT(Sheet1!E29,4)="upto","N/A", IF(LEFT(Sheet1!E29,5)="Above",VALUE(MID(Sheet1!E29,7,2))+1, IF(ISNUMBER(SEARCH("to",Sheet1!E29)),VALUE(LEFT(Sheet1!E29,FIND(" to",Sheet1!E29)-1)), "N/A")))) -> N/A | L29: =IF(Sheet1!E29="All","N/A", IF(LEFT(Sheet1!E29,4)="upto",VALUE(MID(Sheet1!E29,6,2)), IF(LEFT(Sheet1!E29,5)="Above","N/A", IF(ISNUMBER(SEARCH("to",Sheet1!E29)),VALUE(MID(Sheet1!E29,FIND("to ",Sheet1!E29)+3,2)), "N/A")))) -> N/A | M29: Comprehensive (1+1),SATP | N29: New,Old,Renewal,Rollover | O29: No | P29: =IF(Sheet1!A29="No","No", IF(LEFT(Sheet1!A29,5)="Up to",0, VALUE(LEFT(Sheet1!A29,FIND(" ",Sheet1!A29)-1)))) -> No | Q29: =IF(Sheet1!A29="No","No", IF(LEFT(Sheet1!A29,5)="Up to", VALUE(MID(Sheet1!A29,7,FIND("kg",Sheet1!A29)-7)), VALUE(MID(Sheet1!A29,FIND("to",Sheet1!A29)+3,FIND("kg",Sheet1!A29)-FIND("to",Sheet1!A29)-3)))) -> No | R29: No | S29: No | T29: No | U29: No | V29: No | W29: No | X29: No | Y29: =Sheet1!C29-Sheet1!D29 -> 0.3577
... A34: Royal | B34: TN | C34: 72, 76, 79 | D34: GCV | E34: N/A | F34: N/A | G34: N/A | H34: N/A | I34: 4 Wheeler Goods | J34: Petrol,Diesel,CNG | K34: =IF(Sheet1!E34="All","N/A", IF(LEFT(Sheet1!E34,4)="upto","N/A", IF(LEFT(Sheet1!E34,5)="Above",VALUE(MID(Sheet1!E34,7,2))+1, IF(ISNUMBER(SEARCH("to",Sheet1!E34)),VALUE(LEFT(Sheet1!E34,FIND(" to",Sheet1!E34)-1)), "N/A")))) -> N/A | L34: =IF(Sheet1!E34="All","N/A", IF(LEFT(Sheet1!E34,4)="upto",VALUE(MID(Sheet1!E34,6,2)), IF(LEFT(Sheet1!E34,5)="Above","N/A", IF(ISNUMBER(SEARCH("to",Sheet1!E34)),VALUE(MID(Sheet1!E34,FIND("to ",Sheet1!E34)+3,2)), "N/A")))) -> N/A | M34: Comprehensive (1+1) | N34: New,Old,Renewal,Rollover | O34: No | P34: =IF(Sheet1!A34="No","No", IF(LEFT(Sheet1!A34,5)="Up to",0, VALUE(LEFT(Sheet1!A34,FIND(" ",Sheet1!A34)-1)))) -> 0 | Q34: =IF(Sheet1!A34="No","No", IF(LEFT(Sheet1!A34,5)="Up to", VALUE(MID(Sheet1!A34,7,FIND("kg",Sheet1!A34)-7)), VALUE(MID(Sheet1!A34,FIND("to",Sheet1!A34)+3,FIND("kg",Sheet1!A34)-FIND("to",Sheet1!A34)-3)))) -> 2300 | R34: No | S34: No | T34: No | U34: No | V34: No | W34: No | X34: No | Y34: =Sheet1!C34-Sheet1!D34 -> 0.3871
A35: Royal | B35: TN | C35: 67 | D35: GCV | E35: N/A | F35: N/A | G35: N/A | H35: N/A | I35: 4 Wheeler Goods | J35: Petrol,Diesel,CNG | K35: =IF(Sheet1!E35="All","N/A", IF(LEFT(Sheet1!E35,4)="upto","N/A", IF(LEFT(Sheet1!E35,5)="Above",VALUE(MID(Sheet1!E35,7,2))+1, IF(ISNUMBER(SEARCH("to",Sheet1!E35)),VALUE(LEFT(Sheet1!E35,FIND(" to",Sheet1!E35)-1)), "N/A")))) -> N/A | L35: =IF(Sheet1!E35="All","N/A", IF(LEFT(Sheet1!E35,4)="upto",VALUE(MID(Sheet1!E35,6,2)), IF(LEFT(Sheet1!E35,5)="Above","N/A", IF(ISNUMBER(SEARCH("to",Sheet1!E35)),VALUE(MID(Sheet1!E35,FIND("to ",Sheet1!E35)+3,2)), "N/A")))) -> N/A | M35: Comprehensive (1+1) | N35: New,Old,Renewal,Rollover | O35: No | P35: =IF(Sheet1!A35="No","No", IF(LEFT(Sheet1!A35,5)="Up to",0, VALUE(LEFT(Sheet1!A35,FIND(" ",Sheet1!A35)-1)))) -> 0 | Q35: =IF(Sheet1!A35="No","No", IF(LEFT(Sheet1!A35,5)="Up to", VALUE(MID(Sheet1!A35,7,FIND("kg",Sheet1!A35)-7)), VALUE(MID(Sheet1!A35,FIND("to",Sheet1!A35)+3,FIND("kg",Sheet1!A35)-FIND("to",Sheet1!A35)-3)))) -> 2300 | R35: No | S35: No | T35: No | U35: No | V35: No | W35: No | X35: No | Y35: =Sheet1!C35-Sheet1!D35 -> 0.3675
A36: Royal | B36: TN | C36: 33, 36, 86,39, 42, 78,15,16,23,24,25,28,29,31,32,34,43,45,46,47,48,49,50,51,52,55,56,57,58,59,60,61,63,64,65,68,70,73,81,82,83,84,88,91,93,94,95,97 | D36: GCV | E36: N/A | F36: N/A | G36: N/A | H36: N/A | I36: 4 Wheeler Goods | J36: Petrol,Diesel,CNG | K36: =IF(Sheet1!E36="All","N/A", IF(LEFT(Sheet1!E36,4)="upto","N/A", IF(LEFT(Sheet1!E36,5)="Above",VALUE(MID(Sheet1!E36,7,2))+1, IF(ISNUMBER(SEARCH("to",Sheet1!E36)),VALUE(LEFT(Sheet1!E36,FIND(" to",Sheet1!E36)-1)), "N/A")))) -> N/A | L36: =IF(Sheet1!E36="All","N/A", IF(LEFT(Sheet1!E36,4)="upto",VALUE(MID(Sheet1!E36,6,2)), IF(LEFT(Sheet1!E36,5)="Above","N/A", IF(ISNUMBER(SEARCH("to",Sheet1!E36)),VALUE(MID(Sheet1!E36,FIND("to ",Sheet1!E36)+3,2)), "N/A")))) -> N/A | M36: Comprehensive (1+1) | N36: New,Old,Renewal,Rollover | O36: No | P36: =IF(Sheet1!A36="No","No", IF(LEFT(Sheet1!A36,5)="Up to",0, VALUE(LEFT(Sheet1!A36,FIND(" ",Sheet1!A36)-1)))) -> 0 | Q36: =IF(Sheet1!A36="No","No", IF(LEFT(Sheet1!A36,5)="Up to", VALUE(MID(Sheet1!A36,7,FIND("kg",Sheet1!A36)-7)), VALUE(MID(Sheet1!A36,FIND("to",Sheet1!A36)+3,FIND("kg",Sheet1!A36)-FIND("to",Sheet1!A36)-3)))) -> 2300 | R36: No | S36: No | T36: No | U36: No | V36: No | W36: No | X36: No | Y36: =Sheet1!C36-Sheet1!D36 -> 0.3381
A37: Royal | B37: TN | C37: 27, 30, 54, 77, 90 | D37: GCV | E37: N/A | F37: N/A | G37: N/A | H37: N/A | I37: 4 Wheeler Goods | J37: Petrol,Diesel,CNG | K37: =IF(Sheet1!E37="All","N/A", IF(LEFT(Sheet1!E37,4)="upto","N/A", IF(LEFT(Sheet1!E37,5)="Above",VALUE(MID(Sheet1!E37,7,2))+1, IF(ISNUMBER(SEARCH("to",Sheet1!E37)),VALUE(LEFT(Sheet1!E37,FIND(" to",Sheet1!E37)-1)), "N/A")))) -> N/A | L37: =IF(Sheet1!E37="All","N/A", IF(LEFT(Sheet1!E37,4)="upto",VALUE(MID(Sheet1!E37,6,2)), IF(LEFT(Sheet1!E37,5)="Above","N/A", IF(ISNUMBER(SEARCH("to",Sheet1!E37)),VALUE(MID(Sheet1!E37,FIND("to ",Sheet1!E37)+3,2)), "N/A")))) -> N/A | M37: Comprehensive (1+1) | N37: New,Old,Renewal,Rollover | O37: No | P37: =IF(Sheet1!A37="No","No", IF(LEFT(Sheet1!A37,5)="Up to",0, VALUE(LEFT(Sheet1!A37,FIND(" ",Sheet1!A37)-1)))) -> 0 | Q37: =IF(Sheet1!A37="No","No", IF(LEFT(Sheet1!A37,5)="Up to", VALUE(MID(Sheet1!A37,7,FIND("kg",Sheet1!A37)-7)), VALUE(MID(Sheet1!A37,FIND("to",Sheet1!A37)+3,FIND("kg",Sheet1!A37)-FIND("to",Sheet1!A37)-3)))) -> 2300 | R37: No | S37: No | T37: No | U37: No | V37: No | W37: No | X37: No | Y37: =Sheet1!C37-Sheet1!D37 -> 0.3283
A38: Royal | B38: TN | C38: 01,02,03,05 | D38: GCV | E38: N/A | F38: N/A | G38: N/A | H38: N/A | I38: 4 Wheeler Goods | J38: Petrol,Diesel,CNG | K38: =IF(Sheet1!E38="All","N/A", IF(LEFT(Sheet1!E38,4)="upto","N/A", IF(LEFT(Sheet1!E38,5)="Above",VALUE(MID(Sheet1!E38,7,2))+1, IF(ISNUMBER(SEARCH("to",Sheet1!E38)),VALUE(LEFT(Sheet1!E38,FIND(" to",Sheet1!E38)-1)), "N/A")))) -> N/A | L38: =IF(Sheet1!E38="All","N/A", IF(LEFT(Sheet1!E38,4)="upto",VALUE(MID(Sheet1!E38,6,2)), IF(LEFT(Sheet1!E38,5)="Above","N/A", IF(ISNUMBER(SEARCH("to",Sheet1!E38)),VALUE(MID(Sheet1!E38,FIND("to ",Sheet1!E38)+3,2)), "N/A")))) -> N/A | M38: Comprehensive (1+1) | N38: New,Old,Renewal,Rollover | O38: No | P38: =IF(Sheet1!A38="No","No", IF(LEFT(Sheet1!A38,5)="Up to",0, VALUE(LEFT(Sheet1!A38,FIND(" ",Sheet1!A38)-1)))) -> 0 | Q38: =IF(Sheet1!A38="No","No", IF(LEFT(Sheet1!A38,5)="Up to", VALUE(MID(Sheet1!A38,7,FIND("kg",Sheet1!A38)-7)), VALUE(MID(Sheet1!A38,FIND("to",Sheet1!A38)+3,FIND("kg",Sheet1!A38)-FIND("to",Sheet1!A38)-3)))) -> 2300 | R38: No | S38: No | T38: No | U38: No | V38: No | W38: No | X38: No | Y38: =Sheet1!C38-Sheet1!D38 -> 0.0931
A39: Royal | B39: TN | C39: 19 | D39: GCV | E39: N/A | F39: N/A | G39: N/A | H39: N/A | I39: 4 Wheeler Goods | J39: Petrol,Diesel,CNG | K39: =IF(Sheet1!E39="All","N/A", IF(LEFT(Sheet1!E39,4)="upto","N/A", IF(LEFT(Sheet1!E39,5)="Above",VALUE(MID(Sheet1!E39,7,2))+1, IF(ISNUMBER(SEARCH("to",Sheet1!E39)),VALUE(LEFT(Sheet1!E39,FIND(" to",Sheet1!E39)-1)), "N/A")))) -> N/A | L39: =IF(Sheet1!E39="All","N/A", IF(LEFT(Sheet1!E39,4)="upto",VALUE(MID(Sheet1!E39,6,2)), IF(LEFT(Sheet1!E39,5)="Above","N/A", IF(ISNUMBER(SEARCH("to",Sheet1!E39)),VALUE(MID(Sheet1!E39,FIND("to ",Sheet1!E39)+3,2)), "N/A")))) -> N/A | M39: SATP | N39: New,Old,Renewal,Rollover | O39: No | P39: =IF(Sheet1!A39="No","No", IF(LEFT(Sheet1!A39,5)="Up to",0, VALUE(LEFT(Sheet1!A39,FIND(" ",Sheet1!A39)-1)))) -> 0 | Q39: =IF(Sheet1!A39="No","No", IF(LEFT(Sheet1!A39,5)="Up to", VALUE(MID(Sheet1!A39,7,FIND("kg",Sheet1!A39)-7)), VALUE(MID(Sheet1!A39,FIND("to",Sheet1!A39)+3,FIND("kg",Sheet1!A39)-FIND("to",Sheet1!A39)-3)))) -> 2300 | R39: No | S39: No | T39: No | U39: No | V39: No | W39: No | X39: No | Y39: =Sheet1!C39-Sheet1!D39 -> 0.2891
A40: Royal | B40: TN | C40: 01,02,03,04,05,06,07,09,10,11,12,13,14,18,22,85,21,62,72,67 | D40: GCV | E40: N/A | F40: N/A | G40: N/A | H40: N/A | I40: 4 Wheeler Goods | J40: Petrol,Diesel,CNG | K40: =IF(Sheet1!E40="All","N/A", IF(LEFT(Sheet1!E40,4)="upto","N/A", IF(LEFT(Sheet1!E40,5)="Above",VALUE(MID(Sheet1!E40,7,2))+1, IF(ISNUMBER(SEARCH("to",Sheet1!E40)),VALUE(LEFT(Sheet1!E40,FIND(" to",Sheet1!E40)-1)), "N/A")))) -> N/A | L40: =IF(Sheet1!E40="All","N/A", IF(LEFT(Sheet1!E40,4)="upto",VALUE(MID(Sheet1!E40,6,2)), IF(LEFT(Sheet1!E40,5)="Above","N/A", IF(ISNUMBER(SEARCH("to",Sheet1!E40)),VALUE(MID(Sheet1!E40,FIND("to ",Sheet1!E40)+3,2)), "N/A")))) -> N/A | M40: SATP | N40: New,Old,Renewal,Rollover | O40: No | P40: =IF(Sheet1!A40="No","No", IF(LEFT(Sheet1!A40,5)="Up to",0, VALUE(LEFT(Sheet1!A40,FIND(" ",Sheet1!A40)-1)))) -> 0 | Q40: =IF(Sheet1!A40="No","No", IF(LEFT(Sheet1!A40,5)="Up to", VALUE(MID(Sheet1!A40,7,FIND("kg",Sheet1!A40)-7)), VALUE(MID(Sheet1!A40,FIND("to",Sheet1!A40)+3,FIND("kg",Sheet1!A40)-FIND("to",Sheet1!A40)-3)))) -> 2300 | R40: No | S40: No | T40: No | U40: No | V40: No | W40: No | X40: No | Y40: =Sheet1!C40-Sheet1!D40 -> 0.3969
A41: Royal | B41: TN | C41: 37,38,40,41,66,99 | D41: GCV | E41: N/A | F41: N/A | G41: N/A | H41: N/A | I41: 4 Wheeler Goods | J41: Petrol,Diesel,CNG | K41: =IF(Sheet1!E41="All","N/A", IF(LEFT(Sheet1!E41,4)="upto","N/A", IF(LEFT(Sheet1!E41,5)="Above",VALUE(MID(Sheet1!E41,7,2))+1, IF(ISNUMBER(SEARCH("to",Sheet1!E41)),VALUE(LEFT(Sheet1!E41,FIND(" to",Sheet1!E41)-1)), "N/A")))) -> N/A | L41: =IF(Sheet1!E41="All","N/A", IF(LEFT(Sheet1!E41,4)="upto",VALUE(MID(Sheet1!E41,6,2)), IF(LEFT(Sheet1!E41,5)="Above","N/A", IF(ISNUMBER(SEARCH("to",Sheet1!E41)),VALUE(MID(Sheet1!E41,FIND("to ",Sheet1!E41)+3,2)), "N/A")))) -> N/A | M41: SATP | N41: New,Old,Renewal,Rollover | O41: No | P41: =IF(Sheet1!A41="No","No", IF(LEFT(Sheet1!A41,5)="Up to",0, VALUE(LEFT(Sheet1!A41,FIND(" ",Sheet1!A41)-1)))) -> 0 | Q41: =IF(Sheet1!A41="No","No", IF(LEFT(Sheet1!A41,5)="Up to", VALUE(MID(Sheet1!A41,7,FIND("kg",Sheet1!A41)-7)), VALUE(MID(Sheet1!A41,FIND("to",Sheet1!A41)+3,FIND("kg",Sheet1!A41)-FIND("to",Sheet1!A41)-3)))) -> 2300 | R41: No | S41: No | T41: No | U41: No | V41: No | W41: No | X41: No | Y41: =Sheet1!C41-Sheet1!D41 -> 0.3675
A42: Royal | B42: TN | C42: 33,86 | D42: GCV | E42: N/A | F42: N/A | G42: N/A | H42: N/A | I42: 4 Wheeler Goods | J42: Petrol,Diesel,CNG | K42: =IF(Sheet1!E42="All","N/A", IF(LEFT(Sheet1!E42,4)="upto","N/A", IF(LEFT(Sheet1!E42,5)="Above",VALUE(MID(Sheet1!E42,7,2))+1, IF(ISNUMBER(SEARCH("to",Sheet1!E42)),VALUE(LEFT(Sheet1!E42,FIND(" to",Sheet1!E42)-1)), "N/A")))) -> N/A | L42: =IF(Sheet1!E42="All","N/A", IF(LEFT(Sheet1!E42,4)="upto",VALUE(MID(Sheet1!E42,6,2)), IF(LEFT(Sheet1!E42,5)="Above","N/A", IF(ISNUMBER(SEARCH("to",Sheet1!E42)),VALUE(MID(Sheet1!E42,FIND("to ",Sheet1!E42)+3,2)), "N/A")))) -> N/A | M42: SATP | N42: New,Old,Renewal,Rollover | O42: No | P42: =IF(Sheet1!A42="No","No", IF(LEFT(Sheet1!A42,5)="Up to",0, VALUE(LEFT(Sheet1!A42,FIND(" ",Sheet1!A42)-1)))) -> 0 | Q42: =IF(Sheet1!A42="No","No", IF(LEFT(Sheet1!A42,5)="Up to", VALUE(MID(Sheet1!A42,7,FIND("kg",Sheet1!A42)-7)), VALUE(MID(Sheet1!A42,FIND("to",Sheet1!A42)+3,FIND("kg",Sheet1!A42)-FIND("to",Sheet1!A42)-3)))) -> 2300 | R42: No | S42: No | T42: No | U42: No | V42: No | W42: No | X42: No | Y42: =Sheet1!C42-Sheet1!D42 -> 0.2695
A43: Royal | B43: TN | C43: 75 | D43: GCV | E43: N/A | F43: N/A | G43: N/A | H43: N/A | I43: 4 Wheeler Goods | J43: Petrol,Diesel,CNG | K43: =IF(Sheet1!E43="All","N/A", IF(LEFT(Sheet1!E43,4)="upto","N/A", IF(LEFT(Sheet1!E43,5)="Above",VALUE(MID(Sheet1!E43,7,2))+1, IF(ISNUMBER(SEARCH("to",Sheet1!E43)),VALUE(LEFT(Sheet1!E43,FIND(" to",Sheet1!E43)-1)), "N/A")))) -> N/A | L43: =IF(Sheet1!E43="All","N/A", IF(LEFT(Sheet1!E43,4)="upto",VALUE(MID(Sheet1!E43,6,2)), IF(LEFT(Sheet1!E43,5)="Above","N/A", IF(ISNUMBER(SEARCH("to",Sheet1!E43)),VALUE(MID(Sheet1!E43,FIND("to ",Sheet1!E43)+3,2)), "N/A")))) -> N/A | M43: SATP | N43: New,Old,Renewal,Rollover | O43: No | P43: =IF(Sheet1!A43="No","No", IF(LEFT(Sheet1!A43,5)="Up to",0, VALUE(LEFT(Sheet1!A43,FIND(" ",Sheet1!A43)-1)))) -> 0 | Q43: =IF(Sheet1!A43="No","No", IF(LEFT(Sheet1!A43,5)="Up to", VALUE(MID(Sheet1!A43,7,FIND("kg",Sheet1!A43)-7)), VALUE(MID(Sheet1!A43,FIND("to",Sheet1!A43)+3,FIND("kg",Sheet1!A43)-FIND("to",Sheet1!A43)-3)))) -> 2300 | R43: No | S43: No | T43: No | U43: No | V43: No | W43: No | X43: No | Y43: =Sheet1!C43-Sheet1!D43 -> 0.3577
A44: Royal | B44: TN | C44: ro-chn | D44: GCV | E44: N/A | F44: N/A | G44: N/A | H44: N/A | I44: 4 Wheeler Goods | J44: Petrol,Diesel,CNG | K44: =IF(Sheet1!E44="All","N/A", IF(LEFT(Sheet1!E44,4)="upto","N/A", IF(LEFT(Sheet1!E44,5)="Above",VALUE(MID(Sheet1!E44,7,2))+1, IF(ISNUMBER(SEARCH("to",Sheet1!E44)),VALUE(LEFT(Sheet1!E44,FIND(" to",Sheet1!E44)-1)), "N/A")))) -> N/A | L44: =IF(Sheet1!E44="All","N/A", IF(LEFT(Sheet1!E44,4)="upto",VALUE(MID(Sheet1!E44,6,2)), IF(LEFT(Sheet1!E44,5)="Above","N/A", IF(ISNUMBER(SEARCH("to",Sheet1!E44)),VALUE(MID(Sheet1!E44,FIND("to ",Sheet1!E44)+3,2)), "N/A")))) -> N/A | M44: SATP | N44: New,Old,Renewal,Rollover | O44: No | P44: =IF(Sheet1!A44="No","No", IF(LEFT(Sheet1!A44,5)="Up to",0, VALUE(LEFT(Sheet1!A44,FIND(" ",Sheet1!A44)-1)))) -> 0 | Q44: =IF(Sheet1!A44="No","No", IF(LEFT(Sheet1!A44,5)="Up to", VALUE(MID(Sheet1!A44,7,FIND("kg",Sheet1!A44)-7)), VALUE(MID(Sheet1!A44,FIND("to",Sheet1!A44)+3,FIND("kg",Sheet1!A44)-FIND("to",Sheet1!A44)-3)))) -> 2300 | R44: No | S44: No | T44: No | U44: No | V44: No | W44: No | X44: No | Y44: =Sheet1!C44-Sheet1!D44 -> 0.1911
...

Sheet Sheet1
A1: GVW_Slab | B1: Payin | C1: Gross_payout | D1: Out TDS | E1: Vehicle_Age
A2: No | B2: 0.3 | C2: =B2-4.5% -> 0.255 | D2: =C2*2% -> 0.0051 | E2: upto 15 years
A3: No | B3: 0.4 | C3: =B3-4.5% -> 0.355 | D3: =C3*2% -> 0.0071 | E3: upto 15 years
A4: No | B4: 0.325 | C4: =B4-4.5% -> 0.28 | D4: =C4*2% -> 0.0056 | E4: upto 15 years
A5: No | B5: 0.09 | C5: =B5-4.5% -> 0.045 | D5: =C5*2% -> 0.0009 | E5: All
A6: No | B6: 0.26 | C6: =B6-4.5% -> 0.215 | D6: =C6*2% -> 0.0043 | E6: All
A7: No | B7: 0.19 | C7: =B7-4.5% -> 0.145 | D7: =C7*2% -> 0.0029 | E7: All
A8: No | B8: 0.08 | C8: =B8-4.5% -> 0.035 | D8: =C8*2% -> 0.0007 | E8: All
A9: No | B9: 0.21 | C9: =B9-4.5% -> 0.165 | D9: =C9*2% -> 0.0033 | E9: All
A10: No | B10: 0.24 | C10: =B10-4.5% -> 0.195 | D10: =C10*2% -> 0.0039 | E10: All
A11: No | B11: 0.15 | C11: =B11-4.5% -> 0.105 | D11: =C11*2% -> 0.0021 | E11: All
A12: No | B12: 0.16 | C12: =B12-4.5% -> 0.115 | D12: =C12*2% -> 0.0023 | E12: All
A13: No | B13: 0.05 | C13: =B13-4.5% -> 0.005 | D13: =C13*2% -> 0.0001 | E13: All
... A185: No | B185: 0.55 | C185: =B185-4.5% -> 0.505 | D185: =C185*2% -> 0.0101 | E185: All
