Workbook

Sheet School Bus grid
D1: Applicable from 1st of January, 2026
D2: School Bus (PCV 8 & Above)
D3: State_1 | E3: RTO Cluster | F3: Seating Capacity | G3: In the Name of School / School Bus Rating | K3: On Contract (Transporter) | L3: On Contract (Individual)
G4: First Policy Onwards | H4: SB Volume >1.5L | I4: SB Volume >3L
D5: Gujarat, Punjab & Delhi NCR | E5: Gujarat | F5: 8 & above | G5: 0.7 | H5: 0.72 | I5: 0.74 | K5: 0.625 | L5: D
E6: Punjab | F6: 8 & above | G6: 0.7 | H6: 0.72 | I6: 0.74 | K6: 0.625 | L6: D
E7: Delhi NCR | F7: 8 & above | G7: 0.7 | H7: 0.72 | I7: 0.74 | K7: 0.625 | L7: D
D8: Uttar Pradesh | E8: UP Open | F8: 8 & above | G8: 0.7 | H8: 0.72 | I8: 0.74 | K8: 0.625 | L8: 0.625
E9: UP Declined | F9: 8 & above | G9: 0.5 | H9: 0.52 | I9: 0.55 | K9: D
D10: Andhra Pradesh | E10: Vijaywada | F10: 8 & above | G10: 0.7 | H10: 0.72 | I10: 0.74 | K10: 0.625 | L10: 0.625
E11: Rest of AP | F11: 8 & above | G11: 0.7 | H11: 0.72 | I11: 0.74 | K11: 0.625 | L11: 0.625
D12: Telangana | E12: TS Open | F12: 8 & above | G12: 0.7 | H12: 0.72 | I12: 0.74 | K12: 0.625 | L12: 0.625
E13: TS Declined | F13: 8 & above | G13: D | K13: D
D14: Haryana | E14: HR Open | F14: 8 & above | G14: 0.7 | H14: 0.72 | I14: 0.74 | K14: 0.625 | L14: 0.625
E15: Rest of HR | F15: 8 & above | G15: 0.63 | H15: 0.64 | I15: 0.65 | K15: 0.625 | L15: 0.625
D16: Rajasthan | E16: Jaipur/Jodhpur | F16: 8 & above | G16: 0.7 | H16: 0.705 | I16: 0.715 | K16: 0.625 | L16: 0.625
E17: Rest of RJ | F17: 8 & above | G17: 0.7 | H17: 0.705 | I17: 0.715 | K17: 0.5 | L17: D
E18: Udaipur | F18: 8 & above | G18: 0.64 | H18: 0.645 | I18: 0.65 | K18: 0.5 | L18: D
E19: RJ Declined | F19: All | G19: D | K19: D
D20: Karnataka | E20: Bangalore | F20: 8 & above | G20: 0.68 | H20: 0.69 | I20: 0.7 | K20: 0.625 | L20: 0.625
E21: KA Open | F21: 8 & above | G21: 0.525 | H21: 0.525 | I21: 0.525 | K21: D
E22: KA Declined | F22: All | G22: D | K22: D
D23: Tamil Nadu | E23: TN Open | F23: 8-60 | G23: 0.54 | H23: 0.545 | I23: 0.55 | K23: 0.525 | L23: D
F24: >60 | G24: D | K24: D
E25: TN Declined | F25: All | G25: D | K25: D
D26: Kerala | E26: Kerala | F26: 8 & above | G26: 0.56 | H26: 0.58 | I26: 0.6 | K26: 0.525 | L26: D
E27: KL Declined | F27: All | G27: D | K27: D
D28: MP | E28: MP | F28: 8 & above | G28: D | K28: D
D29: Rest of India | E29: Rest of India | F29: 8 & above | G29: 0.7 | H29: 0.72 | I29: 0.74 | K29: 0.625 | L29: 0.625
D31: Important Terms & Condition
D32: 1. Short Term Policies - CD2 reduction of 25% on the above Rate
D33: 2. School Bus (Less Than 8 Seater) - No School Bus Rate will be applied. Taxi Rate of that RTO if applicable will be applied, else NIL Payout
D34: 3. Discount as per system
D35: 4. Refer to the attached excel for RTO Cluster Definition
D36: 5. Any rates communicated earlier is not valid from 1st January, 2026
D38: Note: U/W approval is required if School name not avaliable on RC or permit, process slip will be generated in quote creation to verify same

Sheet Staff Bus Grid
C2: State_1 | D2: RTO | E2: Corporate | F2: Contract Carriage | G2: Contract Carriage | H2: Seating Capacity | I2: Documents required - Corporate Self-Usage | J2: Documents required - Contract Carriage - Transporter & Individual
E3: [Self-Usage] | F3: Transporter | G3: Individual
C4: Tamil Nadu | D4: Tamil Nadu | E4: CD1 95% / CD2 42.5% | F4: Decline | G4: Decline | H4: >10 | I4: 1. Permit Copy (Private Service/ Contract Carriage) | J4: 1. Valid and Effective Permit Copy (Private Service/ Contract Carriage)
C5: =D5 -> Kerala | D5: Kerala | E5: CD1 95% / CD2 42.5% | F5: Decline | G5: Decline | I5: 2. Self-declaration from customer for uses of vehicle will be limited to staff transportation of their own employee | J5: 2. Contract Agreement copy with corporate for which vehicles are attached
C6: Andra Pradesh | D6: AP | E6: CD1 95% / CD2 42.5% | F6: Decline | G6: Decline
D7: Vijaywada | E7: CD1 95% / CD2 55% | F7: CD1 95% / CD2 55% | G7: Decline
C8: Karnataka | D8: KA | E8: CD1 95% / CD2 42.5% | F8: Decline | G8: Decline
D9: Bangalore | E9: CD1 95% / CD2 55% | F9: CD1 95% / CD2 35% | G9: Decline
C10: Gujarat | D10: Gujarat | E10: CD1 95% / CD2 55% | F10: CD1 95% / CD2 55% | G10: CD1 95% / CD2 37.5%
C11: Goa | D11: Goa | E11: CD1 95% / CD2 55% | F11: CD1 95% / CD2 55% | G11: CD1 95% / CD2 37.5%
C12: Delhi NCR | D12: Delhi NCR | E12: CD1 95% / CD2 55% | F12: CD1 95% / CD2 55% | G12: CD1 95% / CD2 37.5%
C13: MAHARASTRA | D13: Mumbai | E13: CD1 95% / CD2 55% | F13: CD1 95% / CD2 55% | G13: CD1 95% / CD2 37.5%
D14: Pune | E14: CD1 95% / CD2 55% | F14: CD1 95% / CD2 37.5% | G14: CD1 95% / CD2 37.5%
D15: ROM | E15: CD1 95% / CD2 55% | F15: CD1 95% / CD2 37.5% | G15: CD1 95% / CD2 37.5%
C16: MP | D16: MP | E16: Decline | F16: Decline | G16: Decline
C17: Rest of India | D17: Rest of India | E17: CD1 95% / CD2 55% | F17: CD1 95% / CD2 30% | G17: Decline
C18: Note:
C19: For New vehicles, permit copy will not be required. CD2 of Contract Carriage Bus will be on hold for Permit copy.
C20: System guidelines will be applicable.
C21: For New vehicles, vehicle invoice/ pre- invoice with confirmation of seating capacity will be mandatory.
C22: Buses which are blocked in exception table or due to other underwriting validation will remain decline.
C23: CD2 for Short-term policies will be 5% lesser than above mentioned grid subject to maximum 45%.
C24: For Seating Capacity up to 10-seater, CD1_85% & CD2_20% in all open cohorts.
C25: Above Grid is applicable for Non-Electric Bus.

Sheet RTO Mapping School & Staff Bus
B1: RTO Mapping-School bus | E1: RTO Mapping -Staff bus
A2: RTO Code | B2: State | C2: State_1 | D2: CV_PCV_6+Seating | E2: State | F2: State_1 | G2: CV_PCV_6+Seating
A3: PY01 | B3: PONDICHERRY | C3: TAMIL NADU | D3: TN OPEN | E3: =_xlfn.XLOOKUP($A3,'[1]RTO Mapping -Staff bus'!$A:$A,'[1]RTO Mapping -Staff bus'!B:B) -> PONDICHERRY | F3: =_xlfn.XLOOKUP($A3,'[1]RTO Mapping -Staff bus'!$A:$A,'[1]RTO Mapping -Staff bus'!C:C) -> TAMIL NADU | G3: =_xlfn.XLOOKUP($A3,'[1]RTO Mapping -Staff bus'!$A:$A,'[1]RTO Mapping -Staff bus'!D:D) -> TAMIL NADU | H3: =_xlfn.XLOOKUP(A3,'Connect_RTO Mapping'!A:A,'Connect_RTO Mapping'!A:A) -> PY01
A4: PY02 | B4: PONDICHERRY | C4: TAMIL NADU | D4: TN OPEN | E4: =_xlfn.XLOOKUP($A4,'[1]RTO Mapping -Staff bus'!$A:$A,'[1]RTO Mapping -Staff bus'!B:B) -> PONDICHERRY | F4: =_xlfn.XLOOKUP($A4,'[1]RTO Mapping -Staff bus'!$A:$A,'[1]RTO Mapping -Staff bus'!C:C) -> TAMIL NADU | G4: =_xlfn.XLOOKUP($A4,'[1]RTO Mapping -Staff bus'!$A:$A,'[1]RTO Mapping -Staff bus'!D:D) -> TAMIL NADU | H4: =_xlfn.XLOOKUP(A4,'Connect_RTO Mapping'!A:A,'Connect_RTO Mapping'!A:A) -> PY02
A5: PY03 | B5: PONDICHERRY | C5: TAMIL NADU | D5: TN OPEN | E5: =_xlfn.XLOOKUP($A5,'[1]RTO Mapping -Staff bus'!$A:$A,'[1]RTO Mapping -Staff bus'!B:B) -> PONDICHERRY | F5: =_xlfn.XLOOKUP($A5,'[1]RTO Mapping -Staff bus'!$A:$A,'[1]RTO Mapping -Staff bus'!C:C) -> TAMIL NADU | G5: =_xlfn.XLOOKUP($A5,'[1]RTO Mapping -Staff bus'!$A:$A,'[1]RTO Mapping -Staff bus'!D:D) -> TAMIL NADU | H5: =_xlfn.XLOOKUP(A5,'Connect_RTO Mapping'!A:A,'Connect_RTO Mapping'!A:A) -> PY03
A6: PY04 | B6: PONDICHERRY | C6: TAMIL NADU | D6: TN OPEN | E6: =_xlfn.XLOOKUP($A6,'[1]RTO Mapping -Staff bus'!$A:$A,'[1]RTO Mapping -Staff bus'!B:B) -> PONDICHERRY | F6: =_xlfn.XLOOKUP($A6,'[1]RTO Mapping -Staff bus'!$A:$A,'[1]RTO Mapping -Staff bus'!C:C) -> TAMIL NADU | G6: =_xlfn.XLOOKUP($A6,'[1]RTO Mapping -Staff bus'!$A:$A,'[1]RTO Mapping -Staff bus'!D:D) -> TAMIL NADU | H6: =_xlfn.XLOOKUP(A6,'Connect_RTO Mapping'!A:A,'Connect_RTO Mapping'!A:A) -> PY04
A7: PY05 | B7: PONDICHERRY | C7: TAMIL NADU | D7: TN OPEN | E7: =_xlfn.XLOOKUP($A7,'[1]RTO Mapping -Staff bus'!$A:$A,'[1]RTO Mapping -Staff bus'!B:B) -> PONDICHERRY | F7: =_xlfn.XLOOKUP($A7,'[1]RTO Mapping -Staff bus'!$A:$A,'[1]RTO Mapping -Staff bus'!C:C) -> TAMIL NADU | G7: =_xlfn.XLOOKUP($A7,'[1]RTO Mapping -Staff bus'!$A:$A,'[1]RTO Mapping -Staff bus'!D:D) -> TAMIL NADU | H7: =_xlfn.XLOOKUP(A7,'Connect_RTO Mapping'!A:A,'Connect_RTO Mapping'!A:A) -> PY05
A8: TN19 | B8: TAMIL NADU | C8: TAMIL NADU | D8: TN DECLINED | E8: =_xlfn.XLOOKUP($A8,'[1]RTO Mapping -Staff bus'!$A:$A,'[1]RTO Mapping -Staff bus'!B:B) -> TAMIL NADU | F8: =_xlfn.XLOOKUP($A8,'[1]RTO Mapping -Staff bus'!$A:$A,'[1]RTO Mapping -Staff bus'!C:C) -> TAMIL NADU | G8: =_xlfn.XLOOKUP($A8,'[1]RTO Mapping -Staff bus'!$A:$A,'[1]RTO Mapping -Staff bus'!D:D) -> TAMIL NADU | H8: =_xlfn.XLOOKUP(A8,'Connect_RTO Mapping'!A:A,'Connect_RTO Mapping'!A:A) -> TN19
A9: TN21 | B9: TAMIL NADU | C9: TAMIL NADU | D9: TN DECLINED | E9: =_xlfn.XLOOKUP($A9,'[1]RTO Mapping -Staff bus'!$A:$A,'[1]RTO Mapping -Staff bus'!B:B) -> TAMIL NADU | F9: =_xlfn.XLOOKUP($A9,'[1]RTO Mapping -Staff bus'!$A:$A,'[1]RTO Mapping -Staff bus'!C:C) -> TAMIL NADU | G9: =_xlfn.XLOOKUP($A9,'[1]RTO Mapping -Staff bus'!$A:$A,'[1]RTO Mapping -Staff bus'!D:D) -> TAMIL NADU | H9: =_xlfn.XLOOKUP(A9,'Connect_RTO Mapping'!A:A,'Connect_RTO Mapping'!A:A) -> TN21
A10: TN22 | B10: TAMIL NADU | C10: TAMIL NADU | D10: TN OPEN | E10: =_xlfn.XLOOKUP($A10,'[1]RTO Mapping -Staff bus'!$A:$A,'[1]RTO Mapping -Staff bus'!B:B) -> TAMIL NADU | F10: =_xlfn.XLOOKUP($A10,'[1]RTO Mapping -Staff bus'!$A:$A,'[1]RTO Mapping -Staff bus'!C:C) -> TAMIL NADU | G10: =_xlfn.XLOOKUP($A10,'[1]RTO Mapping -Staff bus'!$A:$A,'[1]RTO Mapping -Staff bus'!D:D) -> TAMIL NADU | H10: =_xlfn.XLOOKUP(A10,'Connect_RTO Mapping'!A:A,'Connect_RTO Mapping'!A:A) -> TN22
A11: TN23 | B11: TAMIL NADU | C11: TAMIL NADU | D11: TN OPEN | E11: =_xlfn.XLOOKUP($A11,'[1]RTO Mapping -Staff bus'!$A:$A,'[1]RTO Mapping -Staff bus'!B:B) -> TAMIL NADU | F11: =_xlfn.XLOOKUP($A11,'[1]RTO Mapping -Staff bus'!$A:$A,'[1]RTO Mapping -Staff bus'!C:C) -> TAMIL NADU | G11: =_xlfn.XLOOKUP($A11,'[1]RTO Mapping -Staff bus'!$A:$A,'[1]RTO Mapping -Staff bus'!D:D) -> TAMIL NADU | H11: =_xlfn.XLOOKUP(A11,'Connect_RTO Mapping'!A:A,'Connect_RTO Mapping'!A:A) -> TN23
A12: TN27 | B12: TAMIL NADU | C12: TAMIL NADU | D12: TN OPEN | E12: =_xlfn.XLOOKUP($A12,'[1]RTO Mapping -Staff bus'!$A:$A,'[1]RTO Mapping -Staff bus'!B:B) -> TAMIL NADU | F12: =_xlfn.XLOOKUP($A12,'[1]RTO Mapping -Staff bus'!$A:$A,'[1]RTO Mapping -Staff bus'!C:C) -> TAMIL NADU | G12: =_xlfn.XLOOKUP($A12,'[1]RTO Mapping -Staff bus'!$A:$A,'[1]RTO Mapping -Staff bus'!D:D) -> TAMIL NADU | H12: =_xlfn.XLOOKUP(A12,'Connect_RTO Mapping'!A:A,'Connect_RTO Mapping'!A:A) -> TN27
A13: TN28 | B13: TAMIL NADU | C13: TAMIL NADU | D13: TN OPEN | E13: =_xlfn.XLOOKUP($A13,'[1]RTO Mapping -Staff bus'!$A:$A,'[1]RTO Mapping -Staff bus'!B:B) -> TAMIL NADU | F13: =_xlfn.XLOOKUP($A13,'[1]RTO Mapping -Staff bus'!$A:$A,'[1]RTO Mapping -Staff bus'!C:C) -> TAMIL NADU | G13: =_xlfn.XLOOKUP($A13,'[1]RTO Mapping -Staff bus'!$A:$A,'[1]RTO Mapping -Staff bus'!D:D) -> TAMIL NADU | H13: =_xlfn.XLOOKUP(A13,'Connect_RTO Mapping'!A:A,'Connect_RTO Mapping'!A:A) -> TN28
A14: TN29 | B14: TAMIL NADU | C14: TAMIL NADU | D14: TN OPEN | E14: =_xlfn.XLOOKUP($A14,'[1]RTO Mapping -Staff bus'!$A:$A,'[1]RTO Mapping -Staff bus'!B:B) -> TAMIL NADU | F14: =_xlfn.XLOOKUP($A14,'[1]RTO Mapping -Staff bus'!$A:$A,'[1]RTO Mapping -Staff bus'!C:C) -> TAMIL NADU | G14: =_xlfn.XLOOKUP($A14,'[1]RTO Mapping -Staff bus'!$A:$A,'[1]RTO Mapping -Staff bus'!D:D) -> TAMIL NADU | H14: =_xlfn.XLOOKUP(A14,'Connect_RTO Mapping'!A:A,'Connect_RTO Mapping'!A:A) -> TN29
... A124: TN48 | B124: SRIRANGAM | C124: TAMIL NADU | D124: TN DECLINED | E124: =_xlfn.XLOOKUP($A124,'[1]RTO Mapping -Staff bus'!$A:$A,'[1]RTO Mapping -Staff bus'!B:B) -> SRIRANGAM | F124: =_xlfn.XLOOKUP($A124,'[1]RTO Mapping -Staff bus'!$A:$A,'[1]RTO Mapping -Staff bus'!C:C) -> TAMIL NADU | G124: =_xlfn.XLOOKUP($A124,'[1]RTO Mapping -Staff bus'!$A:$A,'[1]RTO Mapping -Staff bus'!D:D) -> TAMIL NADU | H124: =_xlfn.XLOOKUP(A124,'Connect_RTO Mapping'!A:A,'Connect_RTO Mapping'!A:A) -> TN48

Sheet CV Grid 
A1: Good TN CV Grid
C2: Digit_FY 25-26 Comp | F2: Digit_FY 25-26 CVTP
A3: Segment | B3: Make | C3: CD1 | D3: Avg CD2 | E3: Max CD2 | F3: Avg CD2 | G3: Max CD2
A4: GCV3 | B4: All | C4: 0.6 | D4: 0.075 | E4: 0.075 | F4: 0.075 | G4: 0.075
A5: GCV4 upto 2.5T 0-2 years | B5: All | C5: 0.7 | D5: 0.425 | E5: 0.45 | F5: 0.425 | G5: 0.45
A6: GCV4 upto 2.5T 3+ years | B6: All | C6: 0.7 | D6: 0.5 | E6: 0.525 | F6: 0.5 | G6: 0.525
A7: GCV4 2.5 To 3.5T | B7: All | C7: D | D7: D | E7: D | F7: D | G7: D
A8: GCV4 3.5 To 7.5T | B8: All | C8: D | D8: D | E8: D | F8: D | G8: D
A9: GCV4 7.5 to 12T | B9: All | C9: D | D9: D | E9: D | F9: D | G9: D
A10: JCB | B10: All | C10: 0.65 | D10: 0.2 | E10: 0.225 | F10: 0.15 | G10: 0.17
A11: Misc D | B11: All | C11: 0.65 | D11: 0.2 | E11: 0.225 | F11: 0.15 | G11: 0.17 | H11: Body type CRANE is declined
A12: Tractor 0 to 5 years | B12: All | C12: D | D12: D | E12: D | F12: D | G12: D
A13: Tractor 6+ years | B13: All | C13: D | D13: D | E13: D | F13: D | G13: D
A14: E-Loaders | B14: All | C14: 0.6 | D14: 0.025 | E14: 0.05 | F14: 0.025 | G14: 0.05
A15: E-Rickshaw | B15: All | C15: 0.5 | D15: 0.18 | E15: 0.205 | F15: 0.205 | G15: 0.255
A16: PCV3W non-diesel | B16: All | C16: 0.7 | D16: 0.025 | E16: 0.025 | F16: 0.025 | G16: 0.025
A17: PCV3W diesel | B17: All | C17: D | D17: D | E17: D | F17: D | G17: D
A18: Taxi 6-9 seater | B18: All | C18: D | D18: D | E18: D | F18: D | G18: D
A22: Bad TN CV Grid
C23: Digit_FY 25-26 Comp | F23: Digit_FY 25-26 CVTP
A24: Segment | B24: Make | C24: CD1 | D24: Avg CD2 | E24: Max CD2 | F24: Avg CD2 | G24: Max CD2
A25: GCV3 | B25: All | C25: D | D25: D | E25: D | F25: D | G25: D
A26: GCV4 upto 1.6T | B26: All | C26: 0.7 | D26: =E26-2.5% -> 0.225 | E26: 0.25 | F26: 0.225 | G26: 0.25
A27: GCV4 1.6T-2.5T (Low CD2 RTOs @ 20% CD2) | B27: All | C27: 0.8 | D27: 0.2 | E27: 0.2 | F27: 0.2 | G27: 0.2 | H27: Only for TN39, TN42, TN48, TN63 & TN72 RTOs
A28: GCV4 1.6T-2.5T (Low CD2 RTOs @ 10% CD2) | B28: All | C28: 0.8 | D28: 0.1 | E28: 0.1 | F28: 0.1 | G28: 0.1 | H28: Only for TN30, TN33, TN36, TN40, TN45, TN47, TN49, TN56 & TN70 RTOs
A29: GCV4 1.6T-2.5T 6+ Years (Low CD2 RTOs @ 10% CD2) | B29: All | C29: 0.8 | D29: 0.1 | E29: 0.1 | F29: 0.1 | G29: 0.1 | H29: Only for TN54 RTO
A30: GCV4 1.6T-2.5T 6+ Years (Low CD2 RTOs @ 3% CD2) | B30: All | C30: 0.8 | D30: 0.03 | E30: 0.03 | F30: 0.03 | G30: 0.03 | H30: Only for TN52 RTO
A31: GCV4 1.6T-2.5T (Declined RTOs) | B31: All | C31: D | D31: D | E31: D | F31: D | G31: D | H31: All other RTOs of the cluster
A32: GCV4 2.5 To 3.5T | B32: All | C32: D | D32: D | E32: D | F32: D | G32: D
A33: GCV4 3.5 To 7.5T | B33: All | C33: D | D33: D | E33: D | F33: D | G33: D
A34: GCV4 7.5 to 12T | B34: All | C34: D | D34: D | E34: D | F34: D | G34: D
A35: GCV4 12 To 20T 6+ years (Low_CD2 RTOs @ 10% CD2) | B35: All excluding Volvo and Scania* | C35: 0.75 | D35: 0.1 | E35: 0.1 | F35: 0.1 | G35: 0.1 | H35: Only for TN45 RTO
A36: JCB | B36: All | C36: Age 0 to 5-80% Age>=6 -20% | D36: Age 0 to 5-5% Age>=6 -20% | E36: Age 0 to 5-5% Age>=6 -20% | F36: 0.15 | G36: 0.15
A37: Misc D | B37: All | C37: Age 0 to 5-80% Age>=6 -20% | D37: Age 0 to 5-5% Age>=6 -20% | E37: Age 0 to 5-5% Age>=6 -20% | F37: 0.15 | G37: 0.15 | H37: Body type CRANE is declined
A38: Tractor 0 to 5 years | B38: All | C38: D | D38: D | E38: D | F38: D | G38: D
A39: Tractor 6+ years | B39: All | C39: D | D39: D | E39: D | F39: D | G39: D
A40: E-Loaders | B40: All | C40: D | D40: D | E40: D | F40: D | G40: D
A41: E-Rickshaw | B41: All | C41: 0.5 | D41: 0.18 | E41: 0.205 | F41: 0.205 | G41: 0.255
A42: PCV3W non-diesel | B42: All | C42: 0.7 | D42: 0.025 | E42: 0.025 | F42: 0.025 | G42: 0.025
A43: PCV3W diesel | B43: All | C43: D | D43: D | E43: D | F43: D | G43: D
...

Sheet HCV Grid
G1: Non-Dumper/Tipper | L1: Dumper/Tipper | Q1: Oil Tanker | V1: Gas Tanker
G2: Comp | J2: SATP | L2: Comp | O2: SATP | Q2: Comp | T2: SATP | V2: Comp | Y2: SATP
B3: Cluster | C3: Segment | D3: Make | E3: Age From | F3: Age To | G3: CD1 | H3: Avg CD2 | I3: Max CD2 | J3: Avg CD2 | K3: Max CD2 | L3: CD1 | M3: Avg CD2 | N3: Max CD2 | O3: Avg CD2 | P3: Max CD2 | Q3: CD1 | R3: Avg CD2 | S3: Max CD2 | T3: Avg CD2 | U3: Max CD2 | V3: CD1 | W3: Avg CD2 | X3: Max CD2 | Y3: Avg CD2 | Z3: Max CD2
B4: Good TN | C4: GCV4 12 to 20T | D4: All | E4: 0 | F4: 1 | G4: D | H4: D | I4: D | J4: D | K4: D | L4: 0.85 | M4: 0.125 | N4: 0.15 | O4: 0.125 | P4: 0.15 | Q4: For 0-1 age Non Dumper Tipper grids to be referred
B5: Good TN | C5: GCV4 12 to 20T | D5: All | E5: 2 | F5: 5 | G5: D | H5: D | I5: D | J5: D | K5: D | L5: 0.85 | M5: 0.125 | N5: 0.15 | O5: 0.125 | P5: 0.15 | Q5: 0.8 | R5: 0.125 | S5: 0.15 | T5: 0.125 | U5: 0.15 | V5: 0.85 | W5: 0.125 | X5: 0.15 | Y5: 0.125 | Z5: 0.15
B6: Good TN | C6: GCV4 12 to 20T | D6: All | E6: 6 | F6: 99 | G6: D | H6: D | I6: D | J6: D | K6: D | L6: 0.85 | M6: 0.125 | N6: 0.15 | O6: 0.125 | P6: 0.15 | Q6: 0.8 | R6: 0.125 | S6: 0.15 | T6: 0.125 | U6: 0.15 | V6: 0.85 | W6: 0.125 | X6: 0.15 | Y6: 0.125 | Z6: 0.15
B7: Good TN | C7: GCV4 20 to 40T | D7: All | E7: 0 | F7: 1 | G7: D | H7: D | I7: D | J7: D | K7: D | L7: 0.85 | M7: 0.125 | N7: 0.15 | O7: 0.125 | P7: 0.15 | Q7: For 0-1 age Non Dumper Tipper grids to be referred
B8: Good TN | C8: GCV4 20 to 40T | D8: All | E8: 2 | F8: 5 | G8: D | H8: D | I8: D | J8: D | K8: D | L8: 0.85 | M8: 0.125 | N8: 0.15 | O8: 0.125 | P8: 0.15 | Q8: 0.8 | R8: 0.125 | S8: 0.15 | T8: 0.125 | U8: 0.15 | V8: 0.85 | W8: 0.125 | X8: 0.15 | Y8: 0.125 | Z8: 0.15
B9: Good TN | C9: GCV4 20 to 40T | D9: All | E9: 6 | F9: 99 | G9: D | H9: D | I9: D | J9: D | K9: D | L9: 0.85 | M9: 0.125 | N9: 0.15 | O9: 0.125 | P9: 0.15 | Q9: 0.8 | R9: 0.125 | S9: 0.15 | T9: 0.125 | U9: 0.15 | V9: 0.85 | W9: 0.125 | X9: 0.15 | Y9: 0.125 | Z9: 0.15
B10: Good TN | C10: GCV4 40-44T | D10: All | E10: 2 | F10: 5 | G10: D | H10: D | I10: D | J10: D | K10: D | L10: 0.85 | M10: 0.125 | N10: 0.15 | O10: 0.125 | P10: 0.15 | Q10: D | R10: D | S10: D | T10: D | U10: D | V10: 0.85 | W10: 0.125 | X10: 0.15 | Y10: 0.125 | Z10: 0.15
B11: Good TN | C11: GCV4 40-44T | D11: All | E11: 6 | F11: 99 | G11: D | H11: D | I11: D | J11: D | K11: D | L11: 0.85 | M11: 0.125 | N11: 0.15 | O11: 0.125 | P11: 0.15 | Q11: D | R11: D | S11: D | T11: D | U11: D | V11: 0.85 | W11: 0.125 | X11: 0.15 | Y11: 0.125 | Z11: 0.15
B12: Good TN | C12: GCV4 40T+ | D12: All | E12: 0 | F12: 1 | G12: D | H12: D | I12: D | J12: D | K12: D | L12: 0.85 | M12: 0.125 | N12: 0.15 | O12: 0.125 | P12: 0.15 | Q12: For 0-1 age Non Dumper Tipper grids to be referred
B13: Good TN | C13: GCV4 44T+ | D13: All | E13: 2 | F13: 5 | G13: D | H13: D | I13: D | J13: D | K13: D | L13: 0.85 | M13: 0.125 | N13: 0.15 | O13: 0.125 | P13: 0.15 | Q13: D | R13: D | S13: D | T13: D | U13: D | V13: D | W13: D | X13: D | Y13: D | Z13: D
B14: Good TN | C14: GCV4 44T+ | D14: All | E14: 6 | F14: 99 | G14: D | H14: D | I14: D | J14: D | K14: D | L14: 0.85 | M14: 0.125 | N14: 0.15 | O14: 0.125 | P14: 0.15 | Q14: D | R14: D | S14: D | T14: D | U14: D | V14: D | W14: D | X14: D | Y14: D | Z14: D
B15: Bad TN | C15: GCV4 12 to 20T | D15: All | E15: 0 | F15: 1 | G15: D | H15: D | I15: D | J15: D | K15: D | L15: 0.85 | M15: 0.125 | N15: 0.15 | O15: 0.125 | P15: 0.15 | Q15: For 0-1 age Non Dumper Tipper grids to be referred
B16: Bad TN | C16: GCV4 12 to 20T | D16: All | E16: 2 | F16: 5 | G16: D | H16: D | I16: D | J16: D | K16: D | L16: 0.85 | M16: 0.125 | N16: 0.15 | O16: 0.125 | P16: 0.15 | Q16: 0.8 | R16: 0.125 | S16: 0.15 | T16: 0.125 | U16: 0.15 | V16: 0.85 | W16: 0.125 | X16: 0.15 | Y16: 0.125 | Z16: 0.15
B17: Bad TN | C17: GCV4 12 to 20T | D17: All | E17: 6 | F17: 99 | G17: D | H17: D | I17: D | J17: D | K17: D | L17: 0.85 | M17: 0.125 | N17: 0.15 | O17: 0.125 | P17: 0.15 | Q17: 0.8 | R17: 0.125 | S17: 0.15 | T17: 0.125 | U17: 0.15 | V17: 0.85 | W17: 0.125 | X17: 0.15 | Y17: 0.125 | Z17: 0.15
B18: Bad TN | C18: GCV4 20 to 40T | D18: All | E18: 0 | F18: 1 | G18: D | H18: D | I18: D | J18: D | K18: D | L18: 0.85 | M18: 0.125 | N18: 0.15 | O18: 0.125 | P18: 0.15 | Q18: For 0-1 age Non Dumper Tipper grids to be referred
B19: Bad TN | C19: GCV4 20 to 40T | D19: All | E19: 2 | F19: 5 | G19: D | H19: D | I19: D | J19: D | K19: D | L19: 0.85 | M19: 0.125 | N19: 0.15 | O19: 0.125 | P19: 0.15 | Q19: 0.8 | R19: 0.125 | S19: 0.15 | T19: 0.125 | U19: 0.15 | V19: 0.85 | W19: 0.125 | X19: 0.15 | Y19: 0.125 | Z19: 0.15
B20: Bad TN | C20: GCV4 20 to 40T | D20: All | E20: 6 | F20: 99 | G20: D | H20: D | I20: D | J20: D | K20: D | L20: 0.85 | M20: 0.125 | N20: 0.15 | O20: 0.125 | P20: 0.15 | Q20: 0.8 | R20: 0.125 | S20: 0.15 | T20: 0.125 | U20: 0.15 | V20: 0.85 | W20: 0.125 | X20: 0.15 | Y20: 0.125 | Z20: 0.15
B21: Bad TN | C21: GCV4 40-44T | D21: All | E21: 2 | F21: 5 | G21: D | H21: D | I21: D | J21: D | K21: D | L21: 0.85 | M21: 0.125 | N21: 0.15 | O21: 0.125 | P21: 0.15 | Q21: D | R21: D | S21: D | T21: D | U21: D | V21: 0.85 | W21: 0.125 | X21: 0.15 | Y21: 0.125 | Z21: 0.15
B22: Bad TN | C22: GCV4 40-44T | D22: All | E22: 6 | F22: 99 | G22: D | H22: D | I22: D | J22: D | K22: D | L22: 0.85 | M22: 0.125 | N22: 0.15 | O22: 0.125 | P22: 0.15 | Q22: D | R22: D | S22: D | T22: D | U22: D | V22: 0.85 | W22: 0.125 | X22: 0.15 | Y22: 0.125 | Z22: 0.15
B23: Bad TN | C23: GCV4 40T+ | D23: All | E23: 0 | F23: 1 | G23: D | H23: D | I23: D | J23: D | K23: D | L23: 0.85 | M23: 0.125 | N23: 0.15 | O23: 0.125 | P23: 0.15 | Q23: For 0-1 age Non Dumper Tipper grids to be referred
B24: Bad TN | C24: GCV4 44T+ | D24: All | E24: 2 | F24: 5 | G24: D | H24: D | I24: D | J24: D | K24: D | L24: 0.85 | M24: 0.125 | N24: 0.15 | O24: 0.125 | P24: 0.15 | Q24: D | R24: D | S24: D | T24: D | U24: D | V24: D | W24: D | X24: D | Y24: D | Z24: D
B25: Bad TN | C25: GCV4 44T+ | D25: All | E25: 6 | F25: 99 | G25: D | H25: D | I25: D | J25: D | K25: D | L25: 0.85 | M25: 0.125 | N25: 0.15 | O25: 0.125 | P25: 0.15 | Q25: D | R25: D | S25: D | T25: D | U25: D | V25: D | W25: D | X25: D | Y25: D | Z25: D
B27: Note: Volvo, Scania to block. Only for Non-Dumper/Tipper: Diamler, Bharat Benz and Mahindra to operate at 70% CD1

Sheet 4W SATP Grid 
B2: Cluster | C2: New Segment | D2: New Age Band | E2: Max CD2 | F2: Avg CD2
B3: South_Ref | C3: CNG | D3: All | E3: 0 | F3: 0
B4: South_Ref | C4: Diesel<1500 | D4: All | E4: 0 | F4: 0
B5: South_Ref | C5: Diesel>1500 | D5: All | E5: 0 | F5: 0
B6: South_Ref | C6: Petrol<1000 | D6: All | E6: 0 | F6: 0
B7: South_Ref | C7: Petrol 1000-1500 | D7: All | E7: 0 | F7: 0
B8: South_Ref | C8: Petrol>1500 | D8: All | E8: 0.38 | F8: 0.345
B9: TN_Good | C9: CNG | D9: All | E9: 0.05 | F9: 0.05
B10: TN_Good | C10: CNG | D10: All | E10: 0.05 | F10: 0.05
B11: TN_Good | C11: Diesel<1500 | D11: All | E11: 0 | F11: 0
B12: TN_Good | C12: Diesel>1500 | D12: All | E12: 0.255 | F12: 0.23
B13: TN_Good | C13: Petrol<1000 | D13: <10 | E13: 0.05 | F13: 0.05
B14: TN_Good | C14: Petrol<1000 | D14: >10 | E14: 0.18 | F14: 0.165
... B16: TN_Good | C16: Petrol>1500 | D16: All | E16: 0.35 | F16: 0.315

Sheet Pvt Car Comp+SAOD Grid
C2: Non HEV; 90:10 | M2: HEV
C3: Comp | H3: SAOD | M3: HEV
B4: Cluster | C4: 0- 25k | D4: 25k- 50k | E4: 50k - 1lac | F4: 1-3 L | G4: >3 L | H4: 0- 25k | I4: 25k- 50k | J4: 50k - 1lac | K4: 1-3 L | L4: >3 L
B5: TN | C5: 0.195 | D5: 0.195 | E5: 0.21 | F5: 0.22 | G5: 0.22 | H5: 0.195 | I5: 0.215 | J5: 0.23 | K5: 0.23 | L5: 0.24 | M5: 0.195
B7: **HEV standard grid: 19.5% on OD with applicability of 80:20 rule.

Sheet 2W Grid_1+1 & SATP
D2: 1+1 | G2: SATP
B3: Agency/PB Clusters | C3: Agency/PB Seg | D3: CD1 | E3: Max CD2 | F3: Avg CD2 | G3: Max CD2 | H3: Avg CD2
B4: TN_Chennai | C4: SC/EV | D4: 0.6 | E4: 0.46 | F4: 0.425 | G4: 0.4 | H4: 0.365
B5: TN_Chennai | C5: MC <= 180 Hero/Honda | D5: -0.5 | E5: 0.025 | F5: 0.025 | G5: 0 | H5: 0
B6: TN_Chennai | C6: MC <= 180 Others | D6: -0.5 | E6: 0.025 | F6: 0.025 | G6: 0 | H6: 0
B7: TN_Chennai | C7: MC_180-350_RE | D7: 0 | E7: 0 | F7: 0 | G7: 0 | H7: 0
B8: TN_Chennai | C8: MC_180-350_Other than RE | D8: -0.6 | E8: 0.025 | F8: 0.025 | G8: 0 | H8: 0
B9: TN_Chennai | C9: MC>350 | D9: -5 | E9: 0.025 | F9: 0.025 | G9: 0 | H9: 0
B10: TN+KL Good | C10: SC/EV | D10: 0.4 | E10: 0.39 | F10: 0.355 | G10: 0.2 | H10: 0.185
B11: TN+KL Good | C11: MC <= 180 Hero/Honda | D11: 0 | E11: 0 | F11: 0 | G11: 0 | H11: 0
B12: TN+KL Good | C12: MC <= 180 Others | D12: 0 | E12: 0 | F12: 0 | G12: 0 | H12: 0
B13: TN+KL Good | C13: MC_180-350_RE | D13: 0 | E13: 0 | F13: 0 | G13: 0 | H13: 0
B14: TN+KL Good | C14: MC_180-350_Other than RE | D14: 0 | E14: 0 | F14: 0 | G14: 0 | H14: 0
B15: TN+KL Good | C15: MC>350 | D15: -5.2 | E15: 0.025 | F15: 0.025 | G15: 0 | H15: 0
... B27: TN+KL+KA REF | C27: MC>350 | D27: 0 | E27: 0 | F27: 0 | G27: 0 | H27: 0

Sheet 2W_SAOD
B4: Cluster | C4: Segment | D4: Min CD1 | E4: Max CD1 for NoBreakIn | F4: Max CD1 for BreakIn | G4: Max 1 year SAOD CD2 | H4: Max 2 year SAOD CD2 | I4: Max 3rd year SAOD CD2 | J4: Max 4th year SAOD CD2
B5: Chennai_Coimbatore | C5: MC <155 | D5: 0 | E5: 0.75 | F5: 0.75 | G5: 0.4 | H5: 0.35 | I5: 0.325 | J5: 0.3
B6: Chennai_Coimbatore | C6: MC>155 | D6: 0 | E6: 0.5 | F6: 0.5 | G6: 0.4 | H6: 0.35 | I6: 0.325 | J6: 0.3
B7: Chennai_Coimbatore | C7: RE | D7: 0 | E7: 0.75 | F7: 0.5 | G7: 0.4 | H7: 0.35 | I7: 0.325 | J7: 0.3
B8: Chennai_Coimbatore | C8: SC | D8: 0 | E8: 0.8 | F8: 0.2 | G8: 0.4 | H8: 0.35 | I8: 0.325 | J8: 0.3
B9: Chennai_Coimbatore | C9: SC_EV | D9: 0 | E9: 0.5 | F9: 0 | G9: 0.4 | H9: 0.35 | I9: 0.325 | J9: 0.3
B10: TN | C10: MC <155 | D10: 0 | E10: 0.7 | F10: 0.6 | G10: 0.4 | H10: 0.35 | I10: 0.325 | J10: 0.3
B11: TN | C11: MC>155 | D11: 0 | E11: 0.5 | F11: 0.5 | G11: 0.4 | H11: 0.35 | I11: 0.325 | J11: 0.3
B12: TN | C12: RE | D12: 0 | E12: 0.5 | F12: 0.5 | G12: 0.4 | H12: 0.35 | I12: 0.325 | J12: 0.3
B13: TN | C13: SC | D13: 0 | E13: 0.75 | F13: 0.75 | G13: 0.4 | H13: 0.35 | I13: 0.325 | J13: 0.3
B14: TN | C14: SC_EV | D14: 0 | E14: 0 | F14: 0 | G14: 0.375 | H14: 0.325 | I14: 0.3 | J14: 0.25

Sheet TN RTO Mapping
A1: CV | L1: 4W SATP | P1: 2W_1+1 & SATP | T1: 2W_1+5 | W1: 2W_SAOD | AA1: RTO cluster definition for school bus
A2: RTO | B2: CV_GCV3(EV/Non-EV) | C2: LCV | D2: MCV | E2: HCV | F2: PCV2W(All)_3W_Non-electric | G2: PCV_3W_Electric | H2: PCV4 (Upto 5 seating) | I2: Misc. D + Tractor | J2: Comments | L2: RTO | M2: New Cluster | P2: RTO | Q2: Cluster Name | R2: City | T2: RTO | U2: Cluster Name | W2: RTO | X2: Cluster Name | Y2: City | AA2: RTO | AB2: RTO name | AC2: Cluster
A3: PY01 | B3: TN & PY REF | C3: PY01_LOWCD2 | D3: TN & PY REF | E3: TN & PY REF | F3: TN & PY REF | G3: TN & PY REF | H3: TN & PY REF | I3: TN & PY REF | J3: Declined for Tractors & MISCD open according to specific body types | L3: PY01 | M3: South_Ref | P3: PY01 | Q3: TN+KL_Bad | R3: Puducherry | T3: PY01 | U3: TN+KL_Bad | W3: PY01 | X3: TN | Y3: Puducherry | AA3: TN01 | AB3: CHENNAI (CENTRAL): AYANAVARAM | AC3: TN OPEN
A4: PY02 | B4: TN & PY REF | C4: TN & PY REF | D4: TN & PY REF | E4: TN & PY REF | F4: TN & PY REF | G4: TN & PY REF | H4: TN & PY REF | I4: TN & PY REF | J4: Declined for Tractors & MISCD open according to specific body types | L4: PY02 | M4: South_Ref | P4: PY02 | Q4: TN+KL+KA REF | R4: Karaikal | T4: PY02 | U4: TN+KL+KA REF | W4: PY02 | X4: TN | Y4: Karaikal | AA4: TN02 | AB4: CHENNAI (NORTH WEST): ANNA NAGAR | AC4: TN OPEN
A5: PY03 | B5: TN & PY REF | C5: TN & PY REF | D5: TN & PY REF | E5: TN & PY REF | F5: TN & PY REF | G5: TN & PY REF | H5: TN & PY REF | I5: TN & PY REF | J5: Declined for Tractors & MISCD open according to specific body types | L5: PY03 | M5: South_Ref | P5: PY03 | Q5: TN+KL_Bad | R5: Mahe | T5: PY03 | U5: TN+KL_Bad | W5: PY03 | X5: TN | Y5: Mahe | AA5: TN03 | AB5: CHENNAI (NORTH EAST): TONDIARPET | AC5: TN OPEN
A6: PY04 | B6: TN & PY REF | C6: TN & PY REF | D6: TN & PY REF | E6: TN & PY REF | F6: TN & PY REF | G6: TN & PY REF | H6: TN & PY REF | I6: TN & PY REF | J6: Declined for Tractors & MISCD open according to specific body types | L6: PY04 | M6: South_Ref | P6: PY04 | Q6: APTS_Good1 | R6: Yanam | T6: PY04 | U6: APTS_Good | W6: PY04 | X6: TN | Y6: Yanam | AA6: TN04 | AB6: CHENNAI (EAST): ROYAPURAM | AC6: TN OPEN
A7: PY05 | B7: TN & PY REF | C7: TN & PY REF | D7: TN & PY REF | E7: TN & PY REF | F7: TN & PY REF | G7: TN & PY REF | H7: TN & PY REF | I7: TN & PY REF | J7: Declined for Tractors & MISCD open according to specific body types | L7: PY05 | M7: South_Ref | P7: PY05 | Q7: TN+KL+KA REF | R7: Oulgaret | T7: PY05 | U7: TN+KL+KA REF | W7: PY05 | X7: TN | Y7: Oulgaret | AA7: TN05 | AB7: CHENNAI (NORTH): KOLATHUR | AC7: TN OPEN
A8: TN01 | B8: GOOD TN | C8: GOOD TN | D8: GOOD TN | E8: GOOD TN | F8: GOOD TN | G8: GOOD TN | H8: GOOD TN | I8: GOOD TN | L8: TN01 | M8: TN_Good | P8: TN01 | Q8: TN_Chennai | R8: Chennai (Central): Ayanavaram | T8: TN01 | U8: TN_Chennai | W8: TN01 | X8: Chennai_Coimbatore | Y8: Chennai (Central): Ayanavaram | AA8: TN06 | AB8: CHENNAI (SOUTH EAST): MANDAVELLI | AC8: TN OPEN
A9: TN02 | B9: GOOD TN | C9: GOOD TN | D9: GOOD TN | E9: GOOD TN | F9: GOOD TN | G9: GOOD TN | H9: GOOD TN | I9: GOOD TN | L9: TN02 | M9: TN_Good | P9: TN02 | Q9: TN_Chennai | R9: Chennai (North West): Anna Nagar | T9: TN02 | U9: TN_Chennai | W9: TN02 | X9: Chennai_Coimbatore | Y9: Chennai (North West): Anna Nagar | AA9: TN07 | AB9: CHENNAI (SOUTH): ADYAR | AC9: TN OPEN
A10: TN03 | B10: GOOD TN | C10: GOOD TN | D10: GOOD TN | E10: GOOD TN | F10: GOOD TN | G10: GOOD TN | H10: GOOD TN | I10: GOOD TN | L10: TN03 | M10: TN_Good | P10: TN03 | Q10: TN+KL Good | R10: Chennai (North East): Tondiarpet | T10: TN03 | U10: TN+KL Good | W10: TN03 | X10: Chennai_Coimbatore | Y10: Chennai (North East): Tondiarpet | AA10: TN09 | AB10: CHENNAI (WEST): K. K. NAGAR | AC10: TN OPEN
A11: TN04 | B11: GOOD TN | C11: GOOD TN | D11: GOOD TN | E11: GOOD TN | F11: GOOD TN | G11: GOOD TN | H11: GOOD TN | I11: GOOD TN | L11: TN04 | M11: TN_Good | P11: TN04 | Q11: TN_Chennai | R11: Chennai (East): Royapuram | T11: TN04 | U11: TN_Chennai | W11: TN04 | X11: Chennai_Coimbatore | Y11: Chennai (East): Royapuram | AA11: TN10 | AB11: CHENNAI (SOUTH WEST): VIRUGAMBAKKAM | AC11: TN OPEN
A12: TN05 | B12: GOOD TN | C12: GOOD TN | D12: GOOD TN | E12: GOOD TN | F12: GOOD TN | G12: GOOD TN | H12: GOOD TN | I12: GOOD TN | L12: TN05 | M12: TN_Good | P12: TN05 | Q12: TN_Chennai | R12: Chennai (North): Kolathur | T12: TN05 | U12: TN_Chennai | W12: TN05 | X12: Chennai_Coimbatore | Y12: Chennai (North): Kolathur | AA12: TN37 | AB12: COIMBATORE (SOUTH) | AC12: TN OPEN
A13: TN06 | B13: GOOD TN | C13: GOOD TN | D13: GOOD TN | E13: GOOD TN | F13: GOOD TN | G13: GOOD TN | H13: GOOD TN | I13: GOOD TN | L13: TN06 | M13: TN_Good | P13: TN06 | Q13: TN_Chennai | R13: Chennai (South East): Mandavelli | T13: TN06 | U13: TN_Chennai | W13: TN06 | X13: Chennai_Coimbatore | Y13: Chennai (South East): Mandavelli | AA13: TN38 | AB13: COIMBATORE (NORTH) | AC13: TN OPEN
A14: TN07 | B14: GOOD TN | C14: GOOD TN | D14: GOOD TN | E14: GOOD TN | F14: GOOD TN | G14: GOOD TN | H14: GOOD TN | I14: GOOD TN | L14: TN07 | M14: TN_Good | P14: TN07 | Q14: TN+KL Good | R14: Chennai (South): Adyar | T14: TN07 | U14: TN+KL Good | W14: TN07 | X14: Chennai_Coimbatore | Y14: Chennai (South): Adyar | AA14: TN66 | AB14: COIMBATORE (CENTRAL) | AC14: TN OPEN
A15: TN09 | B15: GOOD TN | C15: GOOD TN | D15: GOOD TN | E15: GOOD TN | F15: GOOD TN | G15: GOOD TN | H15: GOOD TN | I15: GOOD TN | L15: TN09 | M15: TN_Good | P15: TN09 | Q15: TN_Chennai | R15: Chennai (West): K. K. Nagar | T15: TN09 | U15: TN_Chennai | W15: TN09 | X15: Chennai_Coimbatore | Y15: Chennai (West): K. K. Nagar | AA15: TN99 | AB15: COIMBATORE(WEST) | AC15: TN OPEN
A16: TN10 | B16: GOOD TN | C16: GOOD TN | D16: GOOD TN | E16: GOOD TN | F16: GOOD TN | G16: GOOD TN | H16: GOOD TN | I16: GOOD TN | L16: TN10 | M16: TN_Good | P16: TN10 | Q16: TN_Chennai | R16: Chennai (South West: Virugambakkam | T16: TN10 | U16: TN_Chennai | W16: TN10 | X16: Chennai_Coimbatore | Y16: Chennai (South West: Virugambakkam | AA16: PY01 | AB16: PUDUCHERRY | AC16: TN OPEN
A17: TN11 | B17: GOOD TN | C17: GOOD TN | D17: GOOD TN | E17: GOOD TN | F17: GOOD TN | G17: GOOD TN | H17: GOOD TN | I17: GOOD TN | L17: TN11 | M17: TN_Good | P17: TN11 | Q17: TN+KL Good | R17: Tambaram | T17: TN11 | U17: TN+KL Good | W17: TN11 | X17: Chennai_Coimbatore | Y17: Tambaram | AA17: PY02 | AB17: KARAIKAL | AC17: TN OPEN
A18: TN12 | B18: GOOD TN | C18: GOOD TN | D18: GOOD TN | E18: GOOD TN | F18: GOOD TN | G18: GOOD TN | H18: GOOD TN | I18: GOOD TN | L18: TN12 | M18: TN_Good | P18: TN12 | Q18: TN+KL Good | R18: Poonamallee | T18: TN12 | U18: TN+KL Good | W18: TN12 | X18: Chennai_Coimbatore | Y18: Poonamallee | AA18: PY03 | AB18: MAHE | AC18: TN OPEN
A19: TN13 | B19: GOOD TN | C19: GOOD TN | D19: GOOD TN | E19: GOOD TN | F19: GOOD TN | G19: GOOD TN | H19: GOOD TN | I19: GOOD TN | L19: TN13 | M19: TN_Good | P19: TN13 | Q19: TN+KL Good | R19: Ambattur | T19: TN13 | U19: TN+KL Good | W19: TN13 | X19: Chennai_Coimbatore | Y19: Ambattur | AA19: PY04 | AB19: YANAM | AC19: TN OPEN
A20: TN14 | B20: GOOD TN | C20: GOOD TN | D20: GOOD TN | E20: GOOD TN | F20: GOOD TN | G20: GOOD TN | H20: GOOD TN | I20: GOOD TN | L20: TN14 | M20: TN_Good | P20: TN14 | Q20: TN+KL Good | R20: Sholinganallur | T20: TN14 | U20: TN+KL Good | W20: TN14 | X20: Chennai_Coimbatore | Y20: Sholinganallur | AA20: PY05 | AB20: OULGARET | AC20: TN OPEN
A21: TN15 | B21: TN & PY REF | C21: TN & PY REF | D21: TN & PY REF | E21: TN & PY REF | F21: BAD TN | G21: BAD TN | H21: BAD TN | I21: TN & PY REF | J21: Declined for Tractors & MISCD open according to specific body types | L21: TN15 | M21: South_Ref | P21: TN15 | Q21: TN+KL+KA REF | R21: Ulundurpet | T21: TN15 | U21: TN+KL+KA REF | W21: TN15 | X21: TN | Y21: Ulundurpet | AA21: TN11 | AB21: TAMBARAM | AC21: TN OPEN
A22: TN15Z | B22: TN & PY REF | C22: TN & PY REF | D22: TN & PY REF | E22: TN & PY REF | F22: BAD TN | G22: BAD TN | H22: BAD TN | I22: TN & PY REF | J22: Declined for Tractors & MISCD open according to specific body types | L22: TN15Z | M22: #N/A | P22: TN15Z | Q22: TN+KL+KA REF | R22: NA | T22: TN15Z | U22: TN+KL+KA REF | W22: TN15Z | X22: TN | Y22: NA | AA22: TN12 | AB22: POONAMALLEE | AC22: TN OPEN
A23: TN16 | B23: TN & PY REF | C23: TN & PY REF | D23: TN & PY REF | E23: TN & PY REF | F23: BAD TN | G23: BAD TN | H23: BAD TN | I23: TN & PY REF | J23: Declined for Tractors & MISCD open according to specific body types | L23: TN16 | M23: South_Ref | P23: TN16 | Q23: TN+KL+KA REF | R23: Tindivanam | T23: TN16 | U23: TN+KL+KA REF | W23: TN16 | X23: TN | Y23: Tindivanam | AA23: TN13 | AB23: AMBATTUR | AC23: TN OPEN
A24: TN16Z | B24: TN & PY REF | C24: TN & PY REF | D24: TN & PY REF | E24: TN & PY REF | F24: BAD TN | G24: BAD TN | H24: BAD TN | I24: TN & PY REF | J24: Declined for Tractors & MISCD open according to specific body types | L24: TN16Z | M24: #N/A | P24: TN16Z | Q24: TN+KL+KA REF | R24: NA | T24: TN16Z | U24: TN+KL+KA REF | W24: TN16Z | X24: TN | Y24: NA | AA24: TN14 | AB24: SHOLINGANALLUR | AC24: TN OPEN
A25: TN18 | B25: GOOD TN | C25: GOOD TN | D25: GOOD TN | E25: GOOD TN | F25: GOOD TN | G25: GOOD TN | H25: GOOD TN | I25: GOOD TN | L25: TN18 | M25: TN_Good | P25: TN18 | Q25: TN+KL Good | R25: Red Hills | T25: TN18 | U25: TN+KL Good | W25: TN18 | X25: Chennai_Coimbatore | Y25: Red Hills | AA25: TN15 | AB25: ULUNDURPET | AC25: TN OPEN
A26: TN18Y | B26: TN & PY REF | C26: TN & PY REF | D26: TN & PY REF | E26: TN & PY REF | F26: BAD TN | G26: BAD TN | H26: BAD TN | I26: TN & PY REF | J26: Declined for Tractors & MISCD open according to specific body types | L26: TN18Y | M26: #N/A | P26: TN18Y | Q26: TN+KL Good | R26: NA | T26: TN18Y | U26: TN+KL Good | W26: TN18Y | X26: Chennai_Coimbatore | Y26: NA | AA26: TN16 | AB26: TINDIVANAM | AC26: TN OPEN
A27: TN19 | B27: GOOD TN | C27: GOOD TN | D27: GOOD TN | E27: TN & PY REF | F27: TN & PY REF | G27: TN & PY REF | H27: TN & PY REF | I27: TN & PY REF | J27: Declined for Tractors & MISCD open according to specific body types | L27: TN19 | M27: South_Ref | P27: TN19 | Q27: TN+KL+KA REF | R27: Chengalpattu | T27: TN19 | U27: TN+KL+KA REF | W27: TN19 | X27: TN | Y27: Chengalpattu | AA27: TN18 | AB27: RED HILLS | AC27: TN OPEN
A28: TN20 | B28: GOOD TN | C28: GOOD TN | D28: GOOD TN | E28: GOOD TN | F28: BAD TN | G28: BAD TN | H28: BAD TN | I28: TN & PY REF | J28: Declined for Tractors & MISCD open according to specific body types | L28: TN20 | M28: South_Ref | P28: TN20 | Q28: TN+KL Good | R28: Tiruvallur | T28: TN20 | U28: TN+KL Good | W28: TN20 | X28: TN | Y28: Tiruvallur | AA28: TN19 | AB28: CHENGALPATTU | AC28: TN DECLINED
A29: TN20X | B29: TN & PY REF | C29: TN & PY REF | D29: TN & PY REF | E29: TN & PY REF | F29: BAD TN | G29: BAD TN | H29: BAD TN | I29: TN & PY REF | J29: Declined for Tractors & MISCD open according to specific body types | L29: TN20X | M29: #N/A | P29: TN20X | Q29: TN+KL Good | R29: NA | T29: TN20X | U29: TN+KL Good | W29: TN20X | X29: TN | Y29: NA | AA29: TN20 | AB29: TIRUVALLUR | AC29: TN DECLINED
A30: TN21 | B30: GOOD TN | C30: GOOD TN | D30: GOOD TN | E30: TN & PY REF | F30: TN & PY REF | G30: TN & PY REF | H30: TN & PY REF | I30: TN & PY REF | J30: Declined for Tractors & MISCD open according to specific body types | L30: TN21 | M30: South_Ref | P30: TN21 | Q30: TN+KL_Bad | R30: Kanchipuram | T30: TN21 | U30: TN+KL_Bad | W30: TN21 | X30: TN | Y30: Kanchipuram | AA30: TN22 | AB30: MEENAMBAKKAM | AC30: TN OPEN
A31: TN22 | B31: GOOD TN | C31: GOOD TN | D31: GOOD TN | E31: GOOD TN | F31: GOOD TN | G31: GOOD TN | H31: GOOD TN | I31: TN & PY REF | J31: Declined for Tractors & MISCD open according to specific body types | L31: TN22 | M31: TN_Good | P31: TN22 | Q31: TN_Chennai | R31: Meenambakkam | T31: TN22 | U31: TN_Chennai | W31: TN22 | X31: Chennai_Coimbatore | Y31: Meenambakkam | AA31: TN23 | AB31: VELLORE | AC31: TN OPEN
A32: TN23 | B32: TN & PY REF | C32: LOWCD2_10 | D32: TN & PY REF | E32: TN & PY REF | F32: TN & PY REF | G32: TN & PY REF | H32: TN & PY REF | I32: TN & PY REF | J32: Declined for Tractors & MISCD open according to specific body types. Please refer LOWCD2_10 as the cluster for uploading the grid on connect. | L32: TN23 | M32: South_Ref | P32: TN23 | Q32: TN+KL_Bad | R32: Vellore | T32: TN23 | U32: TN+KL_Bad | W32: TN23 | X32: TN | Y32: Vellore | AA32: TN27 | AB32: SALEM | AC32: TN OPEN
A33: TN23T | B33: TN & PY REF | C33: TN & PY REF | D33: TN & PY REF | E33: TN & PY REF | F33: BAD TN | G33: BAD TN | H33: BAD TN | I33: TN & PY REF | J33: Declined for Tractors & MISCD open according to specific body types | L33: TN23T | M33: #N/A | P33: TN23T | Q33: TN+KL_Bad | R33: NA | T33: TN23T | U33: TN+KL_Bad | W33: TN23T | X33: TN | Y33: NA | AA33: TN28 | AB33: NAMAKKAL (NORTH) | AC33: TN OPEN
A34: TN24 | B34: TN & PY REF | C34: LOWCD2_10 | D34: TN & PY REF | E34: TN & PY REF | F34: TN & PY REF | G34: TN & PY REF | H34: TN & PY REF | I34: TN & PY REF | J34: Declined for Tractors & MISCD open according to specific body types. Please refer LOWCD2_10 as the cluster for uploading the grid on connect. | L34: TN24 | M34: South_Ref | P34: TN24 | Q34: TN+KL+KA REF | R34: Krishnagiri | T34: TN24 | U34: TN+KL+KA REF | W34: TN24 | X34: TN | Y34: Krishnagiri | AA34: TN30 | AB34: SALEM (WEST) | AC34: TN OPEN
A35: TN25 | B35: TN & PY REF | C35: LOWCD2_10 | D35: TN & PY REF | E35: TN & PY REF | F35: TN & PY REF | G35: TN & PY REF | H35: TN & PY REF | I35: TN & PY REF | J35: Declined for Tractors & MISCD open according to specific body types. Please refer LOWCD2_10 as the cluster for uploading the grid on connect. | L35: TN25 | M35: South_Ref | P35: TN25 | Q35: TN+KL+KA REF | R35: Thiruvannamalai | T35: TN25 | U35: TN+KL+KA REF | W35: TN25 | X35: TN | Y35: Thiruvannamalai | AA35: TN31 | AB35: CUDDALORE | AC35: TN OPEN
A36: TN27 | B36: TN & PY REF | C36: LOWCD2_10 | D36: TN & PY REF | E36: TN & PY REF | F36: TN & PY REF | G36: TN & PY REF | H36: TN & PY REF | I36: TN & PY REF | J36: Declined for Tractors & MISCD open according to specific body types. Please refer LOWCD2_10 as the cluster for uploading the grid on connect. | L36: TN27 | M36: South_Ref | P36: TN27 | Q36: TN+KL_Bad | R36: Salem | T36: TN27 | U36: TN+KL_Bad | W36: TN27 | X36: TN | Y36: Salem | AA36: TN32 | AB36: VILLUPURAM | AC36: TN OPEN
A37: TN28 | B37: TN & PY REF | C37: TN28_LOWCD2 | D37: TN & PY REF | E37: TN & PY REF | F37: TN & PY REF | G37: TN & PY REF | H37: TN & PY REF | I37: TN & PY REF | J37: Declined for Tractors & MISCD open according to specific body types | L37: TN28 | M37: South_Ref | P37: TN28 | Q37: TN+KL+KA REF | R37: Namakkal (North) | T37: TN28 | U37: TN+KL+KA REF | W37: TN28 | X37: TN | Y37: Namakkal (North) | AA37: TN33 | AB37: ERODE (EAST) | AC37: TN OPEN
A38: TN29 | B38: TN & PY REF | C38: LOWCD2_10 | D38: TN & PY REF | E38: TN & PY REF | F38: TN & PY REF | G38: TN & PY REF | H38: TN & PY REF | I38: TN & PY REF | J38: Declined for Tractors & MISCD open according to specific body types. Please refer LOWCD2_10 as the cluster for uploading the grid on connect. | L38: TN29 | M38: South_Ref | P38: TN29 | Q38: TN+KL+KA REF | R38: Dharmapuri | T38: TN29 | U38: TN+KL+KA REF | W38: TN29 | X38: TN | Y38: Dharmapuri | AA38: TN34 | AB38: TIRUCHENGODE | AC38: TN OPEN
A39: TN30 | B39: BAD TN | C39: BAD TN_LOWCD2_10 | D39: BAD TN + PY | E39: BAD TN | F39: BAD TN | G39: BAD TN | H39: BAD TN | I39: TN & PY REF | J39: Declined for Tractors & MISCD open according to specific body types. Please refer BAD TN_LOWCD2_10 as the cluster for uploading grid on connect | L39: TN30 | M39: South_Ref | P39: TN30 | Q39: TN+KL_Bad | R39: Salem (West) | T39: TN30 | U39: TN+KL_Bad | W39: TN30 | X39: TN | Y39: Salem (West) | AA39: TN36 | AB39: GOBICHETTIPALAYAM | AC39: TN OPEN
A40: TN30W | B40: BAD TN | C40: BAD TN | D40: BAD TN | E40: BAD TN | F40: BAD TN | G40: BAD TN | H40: BAD TN | I40: TN & PY REF | J40: Declined for Tractors & MISCD open according to specific body types. Please refer BAD TN_LOWCD2_10 as the cluster for uploading grid on connect | L40: TN30W | M40: #N/A | P40: TN30W | Q40: TN+KL_Bad | R40: NA | T40: TN30W | U40: TN+KL_Bad | W40: TN30W | X40: TN | Y40: NA | AA40: TN39 | AB40: TIRUPUR (NORTH) | AC40: TN OPEN
...

Sheet Connect_RTO Mapping
C1: Connect Mapping - 2W | G1: Connect Mapping - 4W | J1: Connect Mapping - CV
A2: RTO Code | B2: State | C2: 2W_1+1 | D2: 2W_1+5 | E2: 2W_SATP | F2: 2W SAOD | G2: 4WTP | H2: 4WOD | I2: 4WSAOD | J2: CV_GCV3(EV/Non-EV) | K2: CV_LCV | L2: CV_MCV | M2: CV_HCV | N2: CV_PCV2W(All)_3W_Non-electric | O2: PCV_3W_Electric | P2: CV_PCV4(Upto 5 seating) | Q2: CV_PCV_6+Seating | R2: CV_MiscD
A3: PY01 | B3: PONDICHERRY | C3: TN+KL_Bad | D3: TN+KL_Bad | E3: TN+KL_Bad | F3: TN | G3: South_Ref | H3: TN | I3: TN | J3: TN & PY REF | K3: PY01_LOWCD2 | L3: TN & PY REF | M3: TN & PY REF | N3: TN & PY REF | O3: TN & PY REF | P3: TN & PY REF | Q3: TN OPEN | R3: TN & PY REF
A4: PY02 | B4: PONDICHERRY | C4: TN+KL+KA REF | D4: TN+KL+KA REF | E4: TN+KL+KA REF | F4: TN | G4: South_Ref | H4: TN | I4: TN | J4: TN & PY REF | K4: TN & PY REF | L4: TN & PY REF | M4: TN & PY REF | N4: TN & PY REF | O4: TN & PY REF | P4: TN & PY REF | Q4: TN OPEN | R4: TN & PY REF
A5: PY03 | B5: PONDICHERRY | C5: TN+KL_Bad | D5: TN+KL_Bad | E5: TN+KL_Bad | F5: TN | G5: South_Ref | H5: TN | I5: TN | J5: TN & PY REF | K5: TN & PY REF | L5: TN & PY REF | M5: TN & PY REF | N5: TN & PY REF | O5: TN & PY REF | P5: TN & PY REF | Q5: TN OPEN | R5: TN & PY REF
A6: PY04 | B6: PONDICHERRY | C6: APTS_Good1 | D6: APTS_Good | E6: APTS_Good1 | F6: TN | G6: South_Ref | H6: TN | I6: TN | J6: TN & PY REF | K6: TN & PY REF | L6: TN & PY REF | M6: TN & PY REF | N6: TN & PY REF | O6: TN & PY REF | P6: TN & PY REF | Q6: TN OPEN | R6: TN & PY REF
A7: PY05 | B7: PONDICHERRY | C7: TN+KL+KA REF | D7: TN+KL+KA REF | E7: TN+KL+KA REF | F7: TN | G7: South_Ref | H7: TN | I7: TN | J7: TN & PY REF | K7: TN & PY REF | L7: TN & PY REF | M7: TN & PY REF | N7: TN & PY REF | O7: TN & PY REF | P7: TN & PY REF | Q7: TN OPEN | R7: TN & PY REF
A8: TN19 | B8: TAMIL NADU | C8: TN+KL+KA REF | D8: TN+KL+KA REF | E8: TN+KL+KA REF | F8: TN | G8: South_Ref | H8: TN | I8: TN | J8: GOOD TN | K8: GOOD TN | L8: GOOD TN | M8: TN & PY REF | N8: TN & PY REF | O8: TN & PY REF | P8: TN & PY REF | Q8: TN DECLINED | R8: TN & PY REF
A9: TN21 | B9: TAMIL NADU | C9: TN+KL_Bad | D9: TN+KL_Bad | E9: TN+KL_Bad | F9: TN | G9: South_Ref | H9: TN | I9: TN | J9: GOOD TN | K9: GOOD TN | L9: GOOD TN | M9: TN & PY REF | N9: TN & PY REF | O9: TN & PY REF | P9: TN & PY REF | Q9: TN DECLINED | R9: TN & PY REF
A10: TN22 | B10: TAMIL NADU | C10: TN_Chennai | D10: TN_Chennai | E10: TN_Chennai | F10: Chennai_Coimbatore | G10: TN_Good | H10: TN | I10: TN | J10: GOOD TN | K10: GOOD TN | L10: GOOD TN | M10: GOOD TN | N10: GOOD TN | O10: GOOD TN | P10: GOOD TN | Q10: TN OPEN | R10: TN & PY REF
A11: TN23 | B11: TAMIL NADU | C11: TN+KL_Bad | D11: TN+KL_Bad | E11: TN+KL_Bad | F11: TN | G11: South_Ref | H11: TN | I11: TN | J11: TN & PY REF | K11: LOWCD2_10 | L11: TN & PY REF | M11: TN & PY REF | N11: TN & PY REF | O11: TN & PY REF | P11: TN & PY REF | Q11: TN OPEN | R11: TN & PY REF
A12: TN24 | B12: TAMIL NADU | C12: TN+KL+KA REF | D12: TN+KL+KA REF | E12: TN+KL+KA REF | F12: TN | G12: South_Ref | H12: TN | I12: TN | J12: TN & PY REF | K12: LOWCD2_10 | L12: TN & PY REF | M12: TN & PY REF | N12: TN & PY REF | O12: TN & PY REF | P12: TN & PY REF | Q12: TN DECLINED | R12: TN & PY REF
A13: TN25 | B13: TAMIL NADU | C13: TN+KL+KA REF | D13: TN+KL+KA REF | E13: TN+KL+KA REF | F13: TN | G13: South_Ref | H13: TN | I13: TN | J13: TN & PY REF | K13: LOWCD2_10 | L13: TN & PY REF | M13: TN & PY REF | N13: TN & PY REF | O13: TN & PY REF | P13: TN & PY REF | Q13: TN DECLINED | R13: TN & PY REF
... A95: TN99 | B95: TAMIL NADU | C95: TN+KL Good | D95: TN+KL Good | E95: TN+KL Good | F95: Chennai_Coimbatore | G95: TN_Good | H95: TN | I95: TN | J95: GOOD TN | K95: GOOD TN | L95: GOOD TN | M95: GOOD TN | N95: GOOD TN | O95: GOOD TN | P95: GOOD TN | Q95: TN OPEN | R95: GOOD TN
A96: TN2D | B96: TAMIL NADU | C96: TN_Chennai | D96: TN_Chennai | E96: TN_Chennai | F96: Chennai_Coimbatore | G96: #N/A | H96: TN | I96: TN | J96: GOOD TN | K96: GOOD TN | L96: #N/A | M96: GOOD TN | N96: GOOD TN | O96: GOOD TN | P96: GOOD TN | Q96: TN OPEN | R96: GOOD TN
A97: TN2A | B97: TAMIL NADU | C97: TN_Chennai | D97: TN_Chennai | E97: TN_Chennai | F97: Chennai_Coimbatore | G97: #N/A | H97: TN | I97: TN | J97: GOOD TN | K97: GOOD TN | L97: #N/A | M97: GOOD TN | N97: GOOD TN | O97: GOOD TN | P97: GOOD TN | Q97: TN OPEN | R97: GOOD TN
A98: TN15Z | B98: TAMIL NADU | C98: TN+KL+KA REF | D98: TN+KL+KA REF | E98: TN+KL+KA REF | F98: TN | G98: #N/A | H98: TN | I98: TN | J98: TN & PY REF | K98: TN & PY REF | L98: TN & PY REF | M98: TN & PY REF | N98: BAD TN | O98: BAD TN | P98: BAD TN | Q98: TN OPEN | R98: TN & PY REF
A99: TN16Z | B99: TAMIL NADU | C99: TN+KL+KA REF | D99: TN+KL+KA REF | E99: TN+KL+KA REF | F99: TN | G99: #N/A | H99: TN | I99: TN | J99: TN & PY REF | K99: TN & PY REF | L99: TN & PY REF | M99: TN & PY REF | N99: BAD TN | O99: BAD TN | P99: BAD TN | Q99: TN OPEN | R99: TN & PY REF
A100: TN18Y | B100: TAMIL NADU | C100: TN+KL Good | D100: TN+KL Good | E100: TN+KL Good | F100: Chennai_Coimbatore | G100: #N/A | H100: TN | I100: TN | J100: TN & PY REF | K100: TN & PY REF | L100: TN & PY REF | M100: TN & PY REF | N100: BAD TN | O100: BAD TN | P100: BAD TN | Q100: TN OPEN | R100: TN & PY REF
A101: TN20X | B101: TAMIL NADU | C101: TN+KL Good | D101: TN+KL Good | E101: TN+KL Good | F101: TN | G101: #N/A | H101: TN | I101: TN | J101: TN & PY REF | K101: TN & PY REF | L101: TN & PY REF | M101: TN & PY REF | N101: BAD TN | O101: BAD TN | P101: BAD TN | Q101: TN DECLINED | R101: TN & PY REF
A102: TN23T | B102: TAMIL NADU | C102: TN+KL_Bad | D102: TN+KL_Bad | E102: TN+KL_Bad | F102: TN | G102: #N/A | H102: TN | I102: TN | J102: TN & PY REF | K102: TN & PY REF | L102: TN & PY REF | M102: TN & PY REF | N102: BAD TN | O102: BAD TN | P102: BAD TN | Q102: TN OPEN | R102: TN & PY REF
A103: TN30W | B103: TAMIL NADU | C103: TN+KL_Bad | D103: TN+KL_Bad | E103: TN+KL_Bad | F103: TN | G103: #N/A | H103: TN | I103: TN | J103: BAD TN | K103: BAD TN | L103: BAD TN | M103: BAD TN | N103: BAD TN | O103: BAD TN | P103: BAD TN | Q103: TN OPEN | R103: TN & PY REF
A104: TN31Z | B104: TAMIL NADU | C104: TN+KL+KA REF | D104: TN+KL+KA REF | E104: TN+KL+KA REF | F104: TN | G104: #N/A | H104: TN | I104: TN | J104: TN & PY REF | K104: TN & PY REF | L104: TN & PY REF | M104: TN & PY REF | N104: BAD TN | O104: BAD TN | P104: BAD TN | Q104: TN OPEN | R104: TN & PY REF
A105: TN36W | B105: TAMIL NADU | C105: TN+KL+KA REF | D105: TN+KL+KA REF | E105: TN+KL+KA REF | F105: TN | G105: #N/A | H105: TN | I105: TN | J105: BAD TN | K105: BAD TN | L105: BAD TN | M105: BAD TN | N105: BAD TN | O105: BAD TN | P105: BAD TN | Q105: TN OPEN | R105: TN & PY REF
A106: TN36Z | B106: TAMIL NADU | C106: TN+KL+KA REF | D106: TN+KL+KA REF | E106: TN+KL+KA REF | F106: TN | G106: #N/A | H106: TN | I106: TN | J106: BAD TN | K106: BAD TN | L106: BAD TN | M106: BAD TN | N106: BAD TN | O106: BAD TN | P106: BAD TN | Q106: TN OPEN | R106: TN & PY REF
A107: TN37Z | B107: TAMIL NADU | C107: TN+KL Good | D107: TN+KL Good | E107: TN+KL Good | F107: Chennai_Coimbatore | G107: #N/A | H107: TN | I107: TN | J107: GOOD TN | K107: GOOD TN | L107: GOOD TN | M107: GOOD TN | N107: GOOD TN | O107: GOOD TN | P107: GOOD TN | Q107: TN OPEN | R107: GOOD TN
A108: TN39Z | B108: TAMIL NADU | C108: TN+KL_Bad | D108: TN+KL_Bad | E108: TN+KL_Bad | F108: Chennai_Coimbatore | G108: #N/A | H108: TN | I108: TN | J108: BAD TN | K108: BAD TN | L108: BAD TN | M108: BAD TN | N108: BAD TN | O108: BAD TN | P108: BAD TN | Q108: TN OPEN | R108: TN & PY REF
A109: TN41W | B109: TAMIL NADU | C109: TN+KL_Bad | D109: TN+KL_Bad | E109: TN+KL_Bad | F109: Chennai_Coimbatore | G109: #N/A | H109: TN | I109: TN | J109: TN & PY REF | K109: TN & PY REF | L109: TN & PY REF | M109: TN & PY REF | N109: BAD TN | O109: BAD TN | P109: BAD TN | Q109: TN OPEN | R109: TN & PY REF
... A124: TN91Z | B124: TAMIL NADU | C124: TN+KL+KA REF | D124: TN+KL+KA REF | E124: TN+KL+KA REF | F124: TN | G124: #N/A | H124: TN | I124: TN | J124: TN & PY REF | K124: TN & PY REF | L124: TN & PY REF | M124: TN & PY REF | N124: BAD TN | O124: BAD TN | P124: BAD TN | Q124: TN OPEN | R124: TN & PY REF

Sheet 4W Grid Changes
A1: Cluster | B1: Segment | C1: GWP FY'23 | D1: GWP 23'Q4 | E1: Current Max CD2 | F1: New Max CD2
A2: Chennai/Coimbatore | B2: Petrol > 1000cc | C2: 0 | D2: 0 | E2: 0.025 | F2: 0.05
A3: Chennai/Coimbatore | B3: Petrol < 1000 cc | F3: D
A4: Chennai/Coimbatore | B4: Diesel > 1500 cc | C4: 0 | D4: 0 | E4: 0.025 | F4: D
A5: Chennai/Coimbatore | B5: Diesel <1500 cc | C5: 0 | D5: 0 | E5: 0.025 | F5: D
A6: Chennai/Coimbatore | B6: CNG | C6: 0 | D6: 0 | E6: 0.025 | F6: D
A7: Rest of Tn REF | B7: Petrol | C7: 348320.5 | D7: 27038 | E7: 0.025 | F7: 0
A8: Rest of Tn REF | B8: Diesel > 1500 cc | C8: 202140 | D8: 7897 | E8: 0.025 | F8: 0
A9: Rest of Tn REF | B9: Diesel <1500 cc | C9: 60299 | D9: 0 | E9: 0.025 | F9: 0
A10: Rest of Tn REF | B10: CNG | C10: 11495 | D10: 0 | E10: 0.025 | F10: 0

Sheet 2W Grid Changes
C1: 2W SATP | I1: 2W Comp 1+1
A2: Cluster | B2: Segment | C2: FY22-23 GWP | D2: Q4 GWP | E2: Existing Max CD2 | F2: New max CD2 | G2: Remarks | I2: FY22-23 GWP | J2: Q4 GWP | K2: Existing Max CD1 | L2: New max CD1 | M2: Existing Max CD2 | N2: New max CD2 | O2: Remarks
A3: Chennai | B3: MC <=150 | C3: 113596 | D3: 23663 | E3: 0.034388215 | F3: D | G3: Decline | I3: 78940.14 | J3: 14441.06 | K3: 0 | L3: 0 | M3: 0.025 | N3: D | O3: decline
A4: Chennai | B4: MC <=150 Bajaj/Yamaha | C4: 49872 | D4: 714 | E4: 0 | F4: D | G4: Decline | I4: 19471.68 | J4: 5097.93 | K4: 0 | L4: 0 | M4: 0 | N4: D | O4: decline
A5: Chennai | B5: MC > 350 | C5: 0 | D5: 0 | E5: 0 | F5: D | G5: Decline | I5: 0 | J5: 0 | K5: 0 | L5: 0 | M5: 0 | N5: D | O5: decline
A6: Chennai | B6: MC 150-180 | C6: 10582 | D6: 1366 | E6: 0.0125 | F6: D | G6: Decline | I6: 4898.97 | J6: 0 | K6: 0 | L6: 0 | M6: 0.025 | N6: D | O6: decline
A7: Chennai | B7: MC 150-180 Bajaj/Yamaha | C7: 2386 | D7: 0 | E7: 0 | F7: D | G7: Decline | I7: 4770.11 | J7: 1839.6 | K7: 0 | L7: 0 | M7: 0 | N7: D | O7: decline
A8: Chennai | B8: MC 180-350 | C8: 1366 | D8: 0 | E8: 0.025 | F8: D | G8: Decline | I8: 0 | J8: 0 | K8: 0 | L8: 0 | M8: 0.025 | N8: D | O8: decline
A9: Chennai | B9: RE | C9: 31990 | D9: 4148 | E9: 0.032358329 | F9: D | G9: Decline | I9: 1712.39 | J9: 0 | K9: 0 | L9: 0 | M9: 0.025 | N9: D | O9: decline
A10: Chennai | B10: Scooter/Moped | C10: 1924431 | D10: 478097 | E10: 0.375 | F10: 0.275 | G10: 1+1 and SAOD is excl Aprilia and Piaggio and Suzuki | I10: 7877295.2 | J10: 1912950.4 | K10: 0.6 | L10: 0.6 | M10: 0.4 | N10: 0.3
A11: Coimbatore | B11: MC <=150 | C11: 0 | D11: 0 | E11: 0 | F11: D | G11: Decline | I11: 53695.65 | J11: 840.72 | K11: 0 | L11: 0 | M11: 0.025 | N11: D | O11: decline
A12: Coimbatore | B12: MC <=150 Bajaj/Yamaha | C12: 0 | D12: 0 | E12: 0 | F12: D | G12: Decline | I12: 13509.68 | J12: 0 | K12: 0 | L12: 0 | M12: 0 | N12: D | O12: decline
A13: Coimbatore | B13: MC > 350 | C13: 0 | D13: 0 | E13: 0 | F13: D | G13: Decline | I13: 0 | J13: 0 | K13: 0 | L13: 0 | M13: 0 | N13: D | O13: decline
A14: Coimbatore | B14: MC 150-180 | C14: 0 | D14: 0 | E14: 0 | F14: D | G14: Decline | I14: 0 | J14: 0 | K14: 0 | L14: 0 | M14: 0 | N14: D | O14: decline
A15: Coimbatore | B15: MC 150-180 Bajaj/Yamaha | C15: 0 | D15: 0 | E15: 0 | F15: D | G15: Decline | I15: 0 | J15: 0 | K15: 0 | L15: 0 | M15: 0 | N15: D | O15: decline
A16: Coimbatore | B16: MC 180-350 | C16: 0 | D16: 0 | E16: 0 | F16: D | G16: Decline | I16: 0 | J16: 0 | K16: 0 | L16: 0 | M16: 0 | N16: D | O16: decline
A17: Coimbatore | B17: RE | C17: 0 | D17: 0 | E17: 0 | F17: D | G17: Decline | I17: 0 | J17: 0 | K17: 0 | L17: 0 | M17: 0 | N17: D | O17: decline
A18: Coimbatore | B18: Scooter/Moped | C18: 2976958 | D18: 638262 | E18: 0.375 | F18: 0.375 | G18: 1+1 and SAOD is excl Aprilia and Piaggio and Suzuki | I18: 4032087.3 | J18: 1104583.6 | K18: 0.6 | L18: 0.6 | M18: 0.4 | N18: 0.4
A19: Rest of TN | B19: MC <=150 | C19: 0 | D19: 0 | E19: 0 | F19: D | G19: Decline | I19: 0 | J19: 0 | K19: 0 | L19: 0 | M19: 0 | N19: D | O19: decline
A20: Rest of TN | B20: MC <=150 Bajaj/Yamaha | C20: 0 | D20: 0 | E20: 0 | F20: D | G20: Decline | I20: 0 | J20: 0 | K20: 0 | L20: 0 | M20: 0 | N20: D | O20: decline
A21: Rest of TN | B21: MC 150-180 | C21: 0 | D21: 0 | E21: 0 | F21: D | G21: Decline | I21: 0 | J21: 0 | K21: 0 | L21: 0 | M21: 0 | N21: D | O21: decline
A22: Rest of TN | B22: MC 150-180 Bajaj/Yamaha | C22: 0 | D22: 0 | E22: 0 | F22: D | G22: Decline | I22: 0 | J22: 0 | K22: 0 | L22: 0 | M22: 0 | N22: D | O22: decline
A23: Rest of TN | B23: MC 180-350 | C23: 0 | D23: 0 | E23: 0 | F23: D | G23: Decline | I23: 0 | J23: 0 | K23: 0 | L23: 0 | M23: 0 | N23: D | O23: decline
A24: Rest of TN | B24: RE | C24: 0 | D24: 0 | E24: 0 | F24: D | G24: Decline | I24: 0 | J24: 0 | K24: 0 | L24: 0 | M24: 0 | N24: D | O24: decline
A25: Rest of TN | B25: Scooter/Moped | C25: 43781 | D25: 9544 | E25: 0 | F25: 0.25 | I25: 256311.68 | J25: 73680.42 | K25: 0 | L25: 0.6 | M25: 0 | N25: 0.325
A26: TN Bad | B26: MC <=150 | C26: 0 | D26: 0 | E26: 0 | F26: D | G26: Decline | I26: 24098.94 | J26: 882.43 | K26: 0 | L26: 0 | M26: 0 | N26: D | O26: decline
A27: TN Bad | B27: MC <=150 Bajaj/Yamaha | C27: 0 | D27: 0 | E27: 0 | F27: D | G27: Decline | I27: 0 | J27: 0 | K27: 0 | L27: 0 | M27: 0 | N27: D | O27: decline
A28: TN Bad | B28: MC > 350 | C28: 0 | D28: 0 | E28: 0 | F28: D | G28: Decline | I28: 0 | J28: 0 | K28: 0 | L28: 0 | M28: 0 | N28: D | O28: decline
A29: TN Bad | B29: MC 150-180 | C29: 0 | D29: 0 | E29: 0 | F29: D | G29: Decline | I29: 0 | J29: 0 | K29: 0 | L29: 0 | M29: 0 | N29: D | O29: decline
A30: TN Bad | B30: MC 150-180 Bajaj/Yamaha | C30: 0 | D30: 0 | E30: 0 | F30: D | G30: Decline | I30: 0 | J30: 0 | K30: 0 | L30: 0 | M30: 0 | N30: D | O30: decline
A31: TN Bad | B31: MC 180-350 | C31: 0 | D31: 0 | E31: 0 | F31: D | G31: Decline | I31: 0 | J31: 0 | K31: 0 | L31: 0 | M31: 0 | N31: D | O31: decline
A32: TN Bad | B32: RE | C32: 0 | D32: 0 | E32: 0 | F32: D | G32: Decline | I32: 0 | J32: 0 | K32: 0 | L32: 0 | M32: 0 | N32: D | O32: decline
A33: TN Bad | B33: Scooter/Moped | C33: 88675 | D33: 26894 | E33: 0 | F33: 0.25 | I33: 665367.98 | J33: 205020.66 | K33: 0 | L33: 0.6 | M33: 0 | N33: 0.2
A34: TN+KL Ref | B34: MC <=150 | C34: 14698 | D34: 4998 | E34: 0.025 | F34: D | G34: Decline | I34: 12218.42 | J34: 8500.68 | K34: 0 | L34: 0 | M34: 0.025 | N34: D | O34: decline
A35: TN+KL Ref | B35: MC <=150 Bajaj/Yamaha | C35: 4075 | D35: 1803 | E35: 0 | F35: D | G35: Decline | I35: 734.6 | J35: 0 | K35: 0 | L35: 0 | M35: 0 | N35: D | O35: decline
A36: TN+KL Ref | B36: MC > 350 | C36: 0 | D36: 0 | E36: 0 | F36: D | G36: Decline | I36: 0 | J36: 0 | K36: 0 | L36: 0 | M36: 0 | N36: D | O36: decline
A37: TN+KL Ref | B37: MC 150-180 | C37: 0 | D37: 0 | E37: 0 | F37: D | G37: Decline | I37: 0 | J37: 0 | K37: 0 | L37: 0 | M37: 0 | N37: D | O37: decline
A38: TN+KL Ref | B38: MC 150-180 Bajaj/Yamaha | C38: 0 | D38: 0 | E38: 0 | F38: D | G38: Decline | I38: 0 | J38: 0 | K38: 0 | L38: 0 | M38: 0 | N38: D | O38: decline
A39: TN+KL Ref | B39: MC 180-350 | C39: 0 | D39: 0 | E39: 0 | F39: D | G39: Decline | I39: 0 | J39: 0 | K39: 0 | L39: 0 | M39: 0 | N39: D | O39: decline
A40: TN+KL Ref | B40: RE | C40: 0 | D40: 0 | E40: 0 | F40: D | G40: Decline | I40: 0 | J40: 0 | K40: 0 | L40: 0 | M40: 0 | N40: D | O40: decline
...

Sheet Auto Rickshaw changes
A1: Cluster | B1: Age Band for Auto | C1: GWP FY22-23 | D1: Current Max CD1 | E1: Current Max CD2 @ Max CD1 | F1: New Max CD1 | G1: New Max CD2 @ Max CD1
A2: Good TN | B2: 0 | C2: 2.2132527 | D2: 0.7 | E2: 0.475 | F2: 0.7 | G2: 0.025
A3: Good TN | B3: 1 | C3: 4.1261276 | D3: 0.7 | E3: 0.475 | F3: 0.7 | G3: 0.025
A4: Good TN | B4: 2 | C4: 3.9686058 | D4: 0.7 | E4: 0.475 | F4: 0.7 | G4: 0.025
A5: Good TN | B5: 3-4 | C5: 29.588426 | D5: 0.7 | E5: 0.475 | F5: 0.7 | G5: 0.025
A6: Good TN | B6: 5 | C6: 8.975794 | D6: 0.7 | E6: 0.475 | F6: 0.7 | G6: 0.025
A7: Good TN | B7: 6+ | C7: 48.061903 | D7: 0.7 | E7: 0.475 | F7: 0.7 | G7: 0.025
A8: Bad TN | B8: 0 | C8: 0 | D8: 0.7 | E8: 0.275 | F8: 0.7 | G8: 0.025
A9: Bad TN | B9: 1 | C9: 0.0662507 | D9: 0.7 | E9: 0.275 | F9: 0.7 | G9: 0.025
A10: Bad TN | B10: 2 | C10: 0.1317593 | D10: 0.7 | E10: 0.275 | F10: 0.7 | G10: 0.025
A11: Bad TN | B11: 3-4 | C11: 0.9028636 | D11: 0.7 | E11: 0.275 | F11: 0.7 | G11: 0.025
A12: Bad TN | B12: 5 | C12: 0.070339 | D12: 0.7 | E12: 0.275 | F12: 0.7 | G12: 0.025
A13: Bad TN | B13: 6+ | C13: 1.3868733 | D13: 0.7 | E13: 0.275 | F13: 0.7 | G13: 0.025

Sheet E-Rickshaw Changes
A1: PLR Cluster | B1: GWP FY23 | C1: Current Max CD1 | D1: Current Max CD2 @ Max CD1 | E1: New Max CD1 | F1: New Max CD2 @ Max CD1
A2: Bad TN | B2: 0 | C2: 0.5 | D2: 0.25 | E2: 0.5 | F2: 0.205
A3: Good TN | B3: 0 | C3: 0.5 | D3: 0.25 | E3: 0.5 | F3: 0.205

Sheet HCV Changes
B1: GWP FY22_23 | H1: Current Max CD1 | L1: Current Max CD2 @ Max CD1 | R1: New Max CD1 | V1: New Max CD2 @ Max CD1
A2: Cluster | B2: 20-40T 2 to 5 COMP | C2: 20-40T 5+ COMP | D2: 20-40T 5+ SATP | E2: 12-20T 2 to 5 COMP | F2: 12 to 20T 5+ COMP | G2: 12 to 20T 5+ SATP | H2: 20-40T 2 to 5 COMP | I2: 20-40T 5+ COMP | J2: 12-20T 2 to 5 COMP | K2: 12 to 20T 5+ COMP | L2: 20-40T 2 to 5 COMP | M2: 20-40T 5+ COMP | N2: 20-40T 5+ SATP | O2: 12-20T 2 to 5 COMP | P2: 12 to 20T 5+ COMP | Q2: 12 to 20T 5+ SATP | R2: 20-40T 2 to 5 COMP | S2: 20-40T 5+ COMP | T2: 12-20T 2 to 5 COMP | U2: 12 to 20T 5+ COMP | V2: 20-40T 2 to 5 COMP | W2: 20-40T 5+ COMP | X2: 20-40T 5+ SATP | Y2: 12-20T 2 to 5 COMP | Z2: 12 to 20T 5+ COMP | AA2: 12 to 20T 5+ SATP
A3: Bad TN | B3: 0 | C3: 2.7652905 | D3: 0.4405 | E3: 0.4226173 | F3: 0 | G3: 0 | H3: D | I3: D | J3: D | K3: D | L3: D | M3: D | N3: D | O3: D | P3: D | Q3: D | R3: D | S3: D | T3: D | U3: D | V3: D | W3: D | X3: D | Y3: D | Z3: D | AA3: D
